Workbook

Sheet All DP
A1: Agent | B1: Kode DP | C1: nama dp | D1: status
A2: AGENT10 | B2: BLM14 | C2: WAY_TUBA | D2: Masih
A3: AGENT10 | B3: SKD15 | C3: PASIR_SAKTI | D3: Masih
A4: AGENT10 | B4: KOG20 | C4: PEKON_WONOSOBO | D4: Masih
A5: AGENT10 | B5: KOG15 | C5: PULAU_PANGGUNG | D5: Masih
A6: AGENT10 | B6: GTT07 | C6: WAY_LIMA | D6: Masih
A7: AGENT10 | B7: LWA02A | C7: KEMBAHANG | D7: Masih
A8: AGENT10 | B8: KBB14 | C8: BERNAH | D8: Masih
A9: AGENT10 | B9: KBB05 | C9: ABUNG_SEMULI | D9: Masih
A10: AGENT10 | B10: KBB21 | C10: NEGARA_RATU | D10: Masih
A11: AGENT10 | B11: BKH02C | C11: SIDOASRI | D11: Masih
A12: AGENT12 | B12: BAL01D | C12: GADING_KELAPA_DUA | D12: Tidak
... A3508: AGENT40 | B3508: JKT21U | C3508: DC_GANDARIA | D3508: Masih

Sheet raw Base
B1: Tanggal upload fin | C1: Kode Agent 代理区代码 | D1: Nama Drop Point 网点名称 | E1: Kode Drop Point 网点代码 | F1: Video Briefing 班前例会视频 | G1: Summary Briefing 会议要点总结 | H1: Kategori Materi | I1: Tanggal Upload 上传日期 | J1: Sprinter Ikut breifing hari ini | K1: Total Sprinter | L1: created by | M1: status | N1: Last Modified Date 2 | O1: feedback DP | P1: total DP
B2: =INT(I2) -> 46266 | C2: AGENT23 | D2: MASOHI | E2: MSI01 | F2: 2026-09-01 06.34.05_.mp4 | G2: POD VALID DAN MARKETING | H2: Marketing | I2: 46266.194 | J2: 8 | K2: 16 | L2: Amina Abd. Khair | N2: 46266.194 | O2: Masih | P2: 175
B3: =INT(I3) -> 46266 | C3: AGENT23 | D3: WAEAPO | E3: NAM02 | F3: 1ac716247d7932dbfa26a61de418409e.jpg | G3: BRIFING DP NAM02 1 AGUSTUS 2026 - RITASE - PAYCOOLS - E POD - POD RETUR VALID - ARBITRASE - LONG TAIL - TIKET PLATFROM - PARCEL CARE - DENDA HQ | H3: other | I3: 46266.196 | J3: 5 | K3: 10 | L3: Marselinus Tehe | N3: 46266.196 | O3: Masih | P3: 175
B4: =INT(I4) -> 46266 | C4: AGENT23 | D4: GEMBA | E4: PRU02 | F4: BREFING.jpeg | G4: BREAFING GEMBA TGL 01 September 2026 1. PUSH TTD KEJAR RITASE > 90% 2. PEMBAYARAN PAYCOOLS 3. EPOD HARUS VALID 92% 4. KODE KETIGA 5. RETUR DGN POD VALID 6. KEBERSIHAN DP 7. PENGGUNAAN KODE QR DP & SPRINTER 8. SOP MENGANTAR 9.PARCEL CARE | H4: Marketing | I4: 46266.213 | J4: 3 | K4: 3 | L4: Dewi Sriyanti Seipalla | N4: 46266.213 | O4: Masih | P4: 175
B5: =INT(I5) -> 46266 | C5: AGENT23 | D5: LABUHA | E5: LAH01 | F5: 2026-09-01 06.46.11__(Judul-Absensi).mp4 | G5: 1. Absensi sebelum jam 6:30 2. Delivery sebelum jam 12 3. Tidak boleh tahan paket diatas 3 hari Jaga kebersihan dp 4. Terapkan 3S | H5: other | I5: 46266.227 | J5: 21 | K5: 25 | L5: Rifaldi Sanaba | N5: 46266.227 | O5: Masih | P5: 175
B6: =INT(I6) -> 46266 | C6: AGENT23 | D6: GALALA | E6: AMQ07 | F6: 2026-09-01 07.20.44_Jalan Jenderal Sudirman_(Pemeriksa-DP AMQ07_GALALA).jpg | G6: BRIEFING PAGI AMQ07 GALALA 1 SEPTEMBER 2026 ABSEN 6.30 PUSH TTD JAM 12 LONGTAIL PARCEL CARE POD RETUR DAN PU VALID PUSH PAYCOOLS | H6: other | I6: 46266.229 | J6: 23 | K6: 24 | L6: Zulfikry Ramadhan Ismail | N6: 46266.229 | O6: Masih | P6: 175
B7: =INT(I7) -> 46266 | C7: AGENT23 | D7: BOBONG | E7: BOB01 | F7: 20260901_70848AMByGPSMapCamera.jpg | G7: *GROOMING & BRIEFING BOBONG* Pembahasan. ->Push TTD ->TTD REAL TIME ->Di perhatikan paket yg stuck. ->Jujur dalam berkerja. ->Disiplin dgn waktu. ->Penambahan SDM | H7: other | I7: 46266.234 | J7: 1 | K7: 1 | L7: Farisal Irawan | N7: 46266.234 | O7: Masih | P7: 175
B8: =INT(I8) -> 46266 | C8: AGENT23 | D8: PAGUYAMAN | E8: LBO02 | F8: 2026-09-01 06.32.23_.mp4 | G8: PUSH 6.30 PUSH QR SPRINTER PUSH TTD/RITASE | H8: Marketing | I8: 46266.234 | J8: 7 | K8: 8 | L8: Alvian Ahmad | N8: 46266.234 | O8: Masih | P8: 175
B9: =INT(I9) -> 46266 | C9: AGENT23 | D9: DONGGALA | E9: DON01 | F9: 2026-09-01 06.33.10_Jalan Pettalolo_(Judul-DP DON01).jpg | G9: ABSENSI PUSH TTD PAYCOOLS POD VALID LONGTAIL QR SPRINTER | H9: Marketing | I9: 46266.235 | J9: 10 | K9: 17 | L9: Zainuddin . | N9: 46266.236 | O9: Masih | P9: 175
B10: =INT(I10) -> 46266 | C10: AGENT23 | D10: KEBUN_CENGKEH | E10: AMQ02 | F10: 20260901-053848.jpg | G10: 1. QUIZ APP SPRINTER 2. PUSH ABSENSI 06.30 3. PICK-UP 4. SIMPANG GUDANG POD VALID 5. KELUAR 07.30 DAN TTD JAM 12.00 6. PAYCOOLS & GOPAY 7. LONGTAIL | H10: other | I10: 46266.239 | J10: 4 | K10: 20 | L10: Fahbi Safitri | N10: 46266.239 | O10: Masih | P10: 175
B11: =INT(I11) -> 46266 | C11: AGENT23 | D11: FALAJAWA2 | E11: TTE05 | F11: WhatsApp Video 2026-09-01 at 07.46.25.mp4 | G11: PUSH KPI | H11: other | I11: 46266.244 | J11: 2 | K11: 3 | L11: Fadila Samsudin | N11: 46266.244 | O11: Masih | P11: 175
B12: =INT(I12) -> 46266 | C12: AGENT23 | D12: SOJOL | E12: DON13 | F12: IMG-20260901-WA0003(1).jpg | G12: Awb HV,pod, simpan gudang, ujian sprinter | H12: Marketing | I12: 46266.244 | J12: 5 | K12: 5 | L12: Memet . | N12: 46266.244 | O12: Masih | P12: 175
B13: =INT(I13) -> 46266 | C13: AGENT21 | D13: KETEWEL | E13: GIA01B | F13: 20260901_64122AMByGPSMapCamera.mp4 | G13: brifing tentang TTD paksa T7 keatas | H13: other | I13: 46266.245 | J13: 19 | K13: 26 | L13: Rifqi Al'Afif Ramadhan | N13: 46266.245 | O13: Masih | P13: 176
... B17: =INT(I17) -> 46266 | C17: AGENT23 | D17: TUAL | E17: UAL01 | F17: 2026-09-01 07.14.34_Jalan Doktor Leimena_(Judul-Visit)_(Catatan-Kunjungan Harian).jpg | G17: Push TTD sebelum jam 12 Push paycools Push satu sprinter satu pickupan | H17: Marketing | I17: 46266.252 | J17: 6 | K17: 8 | L17: Kufra Ahmad Toha Rery | N17: 46266.252 | O17: Masih | P17: 175
B18: =INT(I18) -> 46266 | C18: AGENT22 | D18: PEKKABATA | E18: PRR02 | F18: VID-20260901-WA0051.mp4 | G18: Absensi Quis app Paket longtail | H18: other | I18: 46266.252 | J18: 11 | K18: 16 | L18: Rusli At | N18: 46266.253 | P18: 148
B19: =INT(I19) -> 46266 | C19: AGENT23 | D19: SOJOL | E19: DON13 | F19: 9b1b0ccd-8eab-4dce-b25b-ebcffcd2fc57.jpeg | G19: ABSENSI QUIS SPRINTER LONGTAIL POD VALID TTD SEBELUM JAM 12 | H19: other | I19: 46266.254 | J19: 5 | K19: 5 | L19: Pengguna Tamu 98700 | N19: 46266.254 | O19: Masih | P19: 175
B20: =INT(I20) -> 46266 | C20: AGENT23 | D20: BONE_PANTAI | E20: SUW02 | F20: 2026-09-01 06.46.43_.jpg | G20: ABESENSI 06.30, TTD SEBELUM JAM 12 | H20: other | I20: 46266.254 | J20: 5 | K20: 9 | L20: Arya Yoga Pangestu | N20: 46266.254 | O20: Masih | P20: 175
B21: =INT(I21) -> 46266 | C21: AGENT23 | D21: MABA | E21: MAB01 | F21: 2026-09-01 07.42.55_Maba Sangaji.JPEG | G21: QR SPRINTER (mkt) ptmp, stuck (NM) | H21: Marketing | I21: 46266.257 | J21: 10 | K21: 6 | L21: Hardi . | N21: 46266.257 | O21: Masih | P21: 175
B22: =INT(I22) -> 46266 | C22: AGENT23 | D22: AMPIBABO | E22: PII04 | F22: BRIFING PAGI.jpg | G22: PUSH PAKET LONGTAIL ABSENSI TIKTOK REVERSE | H22: other | I22: 46266.257 | J22: 4 | K22: 9 | L22: Nurhaliza . | N22: 46266.257 | O22: Masih | P22: 175
B23: =INT(I23) -> 46266 | C23: AGENT23 | D23: DIMEMBE | E23: AID02A | F23: 2026-09-01_06.51.38_Jalan_Sukur_-_Likupang_(Company-J&T_Express)[1].jpg | G23: END STATUS, POD | H23: other | I23: 46266.257 | J23: 4 | K23: 9 | L23: Febrika Falensia Effendie | N23: 46266.257 | P23: 175
B24: =INT(I24) -> 46266 | C24: AGENT22 | D24: BENU_BENUA | E24: KDI11 | F24: 2026-09-01 07.03.32_Jnt Benu Benua.jpeg | G24: memaksimalkan paket di dp mengedukasikan untuk datang lebih awal agar keluar delivery lebih awal juga hati2 saat berkendara mengedukasikan uktuk menggunakan pod valid pada saat meretur dan gagal pick up paket | H24: other | I24: 46266.257 | J24: 15 | K24: 19 | L24: Fitra Chalik | N24: 46266.257 | P24: 148
B25: =INT(I25) -> 46266 | C25: AGENT23 | D25: TENTENA | E25: PSJ02 | F25: IMG_4724.JPEG | G25: 1. PARCEL CARE 2. KEBERSIHAN DP 3. PUSH TTD SEBELUM JAM 12 4. POD VALID 5. POD RETUR 6. PELAYANAN DP 7. MAKSIMALKAN PAKET 8. PICKUP QR SPRINTER 9. ABSENSI 6.30 | H25: Marketing | I25: 46266.257 | J25: 11 | K25: 11 | L25: Stefi Landika | N25: 46266.258 | O25: Masih | P25: 175
B26: =INT(I26) -> 46266 | C26: AGENT28 | D26: MERAUKE | E26: MKQ01 | F26: TimePhoto_20260901_075908.jpg | G26: paket lontail dan paket priofitas | H26: other | I26: 46266.258 | J26: 19 | K26: 3 | L26: Pengguna Tamu 46219 | N26: 46266.258 | P26: 13
B27: =INT(I27) -> 46266 | C27: AGENT22 | D27: NGAPA | E27: LAS02 | F27: hasil_LAS02_1788217968721.mp4 | G27: pod, absensi, delivery jam 07.30 | H27: other | I27: 46266.261 | J27: 13 | K27: 15 | L27: Pengguna Tamu 90586 | N27: 46266.261 | P27: 148
B28: =INT(I28) -> 46266 | C28: AGENT23 | D28: MADIDIR | E28: BIT03 | F28: WhatsApp Image 2026-09-01 at 07.04.35.jpeg,WhatsApp Video 2026-09-01 at 07.06.30.mp4 | G28: LONG TAIL TTD JAM 12 ABSENSI KEBERSIHAN | H28: other | I28: 46266.261 | J28: 23 | K28: 23 | L28: Anglie Meihua Lim | N28: 46266.261 | O28: Masih | P28: 175
B29: =INT(I29) -> 46266 | C29: AGENT21 | D29: SEMINYAK_1 | E29: MGW04C | F29: b1ddf51b-73cb-4ea1-a651-99ab727fd3e8.mp4 | G29: Longtail | H29: other | I29: 46266.261 | J29: 40 | K29: 50 | L29: Diana Ursula Wati | N29: 46266.261 | O29: Masih | P29: 176
B30: =INT(I30) -> 46266 | C30: AGENT22 | D30: TINANGGEA | E30: WAG21 | F30: 2026-09-01 07.13.58_Jalan Poros Lapulu_(TINANGGEA).jpg | G30: pod Ttd absen | H30: other | I30: 46266.261 | J30: 18 | K30: 18 | L30: Sutarno . | N30: 46266.261 | P30: 148
B31: =INT(I31) -> 46266 | C31: AGENT23 | D31: KAKASKASEN | E31: TMH02 | F31: img_v3_02154_e328b5c8-c7cd-4eec-8fc6-d2f54ec1e2hu.jpg | G31: POD PARCELCARE QR SPRINTER/DP PAYCOOLS LONGTAIL KEBERSIHAN | H31: Marketing | I31: 46266.262 | J31: 13 | K31: 20 | L31: Anggreyni Marini Marentek | N31: 46266.262 | O31: Masih | P31: 175
B32: =INT(I32) -> 46266 | C32: AGENT23 | D32: SOFIFI | E32: TID02 | F32: VID-20260901-WA0006.mp4 | G32: PAKET 3 HARI STORAN | H32: other | I32: 46266.264 | J32: 12 | K32: 20 | L32: Karmila Gorotomole | N32: 46266.264 | O32: Masih | P32: 175
B33: =INT(I33) -> 46266 | C33: AGENT22 | D33: BALANIPA | E33: PWX03 | F33: IMG-20260901-WA0021.jpg | G33: Target pick up dan pod retur | H33: other | I33: 46266.264 | J33: 18 | K33: 28 | L33: Wahyu . | N33: 46266.264 | P33: 148
B34: =INT(I34) -> 46266 | C34: AGENT18 | D34: NGAGLIK | E34: SLM03 | F34: aa0c843b-4be0-42dd-9224-5dafa88ce718.JPEG | G34: ttd jam 12 | H34: other | I34: 46266.266 | J34: 7 | K34: 23 | L34: Soeko Wicaksono Novianto | N34: 46266.266 | O34: Masih | P34: 129
B35: =INT(I35) -> 46266 | C35: AGENT21 | D35: NEGARA_1 | E35: NRG01A | F35: 20260901_71748AMByGPSMapCamera.mp4 | G35: mengenai paket yang sudah 3 hari dan simpan gudang atau paket bermasalah | H35: other | I35: 46266.266 | J35: 30 | K35: 45 | L35: Pengguna Tamu 95133 | N35: 46266.266 | O35: Masih | P35: 176
B36: =INT(I36) -> 46266 | C36: AGENT27 | D36: SAMARINDA | E36: SRI01 | F36: 2026-09-01 07.23.24_Citraland City.jpeg | G36: ttd sblm jm12 | H36: other | I36: 46266.267 | J36: 4 | K36: 21 | L36: Pengguna Tamu 68821 | N36: 46266.267 | P36: 165
B37: =INT(I37) -> 46266 | C37: AGENT22 | D37: MAKASSAR | E37: UPG01 | F37: 2026-09-01 7.12.33 AM_Jalan Veteran Selatan No. 64.mp4 | G37: POD Scan Bermasalah | H37: other | I37: 46266.268 | J37: 7 | K37: 31 | L37: Guest User 21841 | N37: 46266.268 | P37: 148
B38: =INT(I38) -> 46266 | C38: AGENT23 | D38: TOMPASO_BARU | E38: AMR16 | F38: 2026-09-01 07.09.58_.jpg | G38: ABSENSI SLA TTD SSEBELUM JAM 12 PEYCOLS | H38: other | I38: 46266.269 | J38: 5 | K38: 11 | L38: Cinta Celsi Tarumingkeng | N38: 46266.269 | O38: Masih | P38: 175
B39: =INT(I39) -> 46266 | C39: AGENT21 | D39: JEMBRANA | E39: NRG03A | F39: WhatsApp Video 2026-09-01 at 06.25.40.mp4 | G39: SHARING SPRINTER BINTANG 5 PENILAIAN CUSTOMER DI APP CUSTOMER | H39: Marketing | I39: 46266.269 | J39: 18 | K39: 19 | L39: Eni Maryana | N39: 46266.269 | O39: Masih | P39: 176
B40: =INT(I40) -> 46266 | C40: AGENT22 | D40: WUNDULAKO | E40: KOL05 | F40: 2026-09-01 07.16.56_.mp4 | G40: memaksimalkanp | H40: other | I40: 46266.271 | J40: 8 | K40: 9 | L40: Irpandi . | N40: 46266.271 | P40: 148
B41: =INT(I41) -> 46266 | C41: AGENT22 | D41: KADIA | E41: KDI02 | F41: WhatsApp Image 2026-09-01 at 06.29.32.jpeg | G41: 1awb perhari | H41: Marketing | I41: 46266.272 | J41: 23 | K41: 26 | L41: Andi Fachri Ramadhan | N41: 46266.273 | P41: 148
B42: =INT(I42) -> 46266 | C42: AGENT19 | D42: DC_PORONG | E42: SDA24 | F42: 2026-09-01 06.29.42_No.447, Jalan Bhayangkari.jpg,2026-09-01 06.29.45_No.447, Jalan Bhayangkari.mp4 | G42: SDA JAM 12 TARGET LEGULER KEDATANGAN | H42: other | I42: 46266.273 | J42: 50 | K42: 56 | L42: fandi rakhmad_SDA24 | N42: 46266.273 | O42: Masih | P42: 365
B43: =INT(I43) -> 46266 | C43: AGENT21 | D43: NUSA_PENIDA | E43: KKL03 | F43: 1 September.mp4 | G43: Briefing pagi : Menyampaikan materi briefing sesuai ketentuan HQ yang dibagi menjadi 3 section. | H43: other | I43: 46266.275 | J43: 26 | K43: 27 | L43: I Dewa Made Dwipayana | N43: 46266.275 | O43: Masih | P43: 176
...

Sheet Raw JMS
A1: Tanggal upload fin | B1: Kode Agent 代理区代码 | C1: Nama Drop Point 网点名称 | D1: Kode Drop Point 网点代码 | E1: Video Briefing 班前例会视频 | F1: Summary Briefing 会议要点总结 | G1: Kategori Materi | H1: Tanggal Upload 上传日期 | I1: Sprinter Ikut breifing hari ini | J1: Total Sprinter | K1: created by | L1: status | M1: Last Modified Date 2 | N1: feedback DP | O1: total DP | P1: paste here
A2: =INT(H2) -> 46266 | B2: =RIGHT(Q2,7) -> AGENT19 | C2: =L2 -> SUMBERBARU_1 | D2: =K2 -> JBR30 | H2: =P2 -> 2026-09-01 18:05:03 | K2: {=_xlfn.TEXTSPLIT(R2," ")} -> JBR30 | L2: SUMBERBARU_1 | P2: 2026-09-01 18:05:03 | Q2: 6660019 AGENT19 | R2: JBR30 SUMBERBARU_1 | S2: JBR30000001 | T2: Rahman JM0330010 | U2: obaforever/idnztapp/meeting/20260901/upload_1788260691243951140af7ca34de8ab0bf55b61c8d99c.mp4
A3: =INT(H3) -> 46266 | B3: =RIGHT(Q3,7) -> AGENT19 | C3: =L3 -> MULYOREJO_1 | D3: =K3 -> SUB39A | H3: =P3 -> 2026-09-01 18:02:20 | K3: {=_xlfn.TEXTSPLIT(R3," ")} -> SUB39A | L3: MULYOREJO_1 | P3: 2026-09-01 18:02:20 | Q3: 6660019 AGENT19 | R3: SUB39A MULYOREJO_1 | S3: SUB39A0030 | T3: Bayu Jm0010007 | U3: obaforever/idnztapp/meeting/20260901/upload_178826048773355737032f80d451fa3d75ffc7fc23eef.mp4 | V3: serah terima oaketbreguler klien dengan prosesing double cek minimalisir double penerima, salah temoel alamat dari pengirim
A4: =INT(H4) -> 46266 | B4: =RIGHT(Q4,7) -> AGENT04 | C4: =L4 -> BANGKINANG_01 | D4: =K4 -> BNG01A | H4: =P4 -> 2026-09-01 17:57:32 | K4: {=_xlfn.TEXTSPLIT(R4," ")} -> BNG01A | L4: BANGKINANG_01 | P4: 2026-09-01 17:57:32 | Q4: 6660004 AGENT04 | R4: BNG01A BANGKINANG_01 | S4: LS0000272317 | T4: Sahrul Wadi | U4: obaforever/idnztapp/meeting/20260901/VID_2026-09-01 05-56-1516444229928efe833075194017b20be3f1518f375f.mp4
A5: =INT(H5) -> 46266 | B5: =RIGHT(Q5,7) -> AGENT16 | C5: =L5 -> DC_CINAMBO | D5: =K5 -> BDO05A | H5: =P5 -> 2026-09-01 17:56:56 | K5: {=_xlfn.TEXTSPLIT(R5," ")} -> BDO05A | L5: DC_CINAMBO | P5: 2026-09-01 17:56:56 | Q5: 6660016 AGENT16 | R5: BDO05A DC_CINAMBO | S5: LS0000415301 | T5: Nezar Hikmatiar | U5: obaforever/idnztapp/meeting/20260901/VID_2026-09-01 05-56-24-115250108660c243aefff14f25beef84aeb3cfb38c.mp4
A6: =INT(H6) -> 46266 | B6: =RIGHT(Q6,7) -> AGENT19 | C6: =L6 -> SUKODONO_1 | D6: =K6 -> SDA38 | H6: =P6 -> 2026-09-01 17:54:52 | K6: {=_xlfn.TEXTSPLIT(R6," ")} -> SDA38 | L6: SUKODONO_1 | P6: 2026-09-01 17:54:52 | Q6: 6660019 AGENT19 | R6: SDA38 SUKODONO_1 | S6: SDA380115 | T6: Fery J07192286 | U6: obaforever/idnztapp/meeting/20260901/upload_178825999901436681E65-06C4-4AAB-B7DD-393CE941D2C5ef569a64f91c486db10eab519a9dedf1.mp4 | V6: grooming & capain reg
A7: =INT(H7) -> 46266 | B7: =RIGHT(Q7,7) -> AGENT19 | C7: =L7 -> MANTUP_1 | D7: =K7 -> LMG11A | H7: =P7 -> 2026-09-01 17:48:43 | K7: {=_xlfn.TEXTSPLIT(R7," ")} -> LMG11A | L7: MANTUP_1 | P7: 2026-09-01 17:48:43 | Q7: 6660019 AGENT19 | R7: LMG11A MANTUP_1 | S7: LS0000191119 | T7: Andy J07181603 | U7: obaforever/idnztapp/meeting/20260901/upload_178825970792429ef259307524b2f9063d092014eea8f.MOV | V7: QR SPRINTER
A8: =INT(H8) -> 46266 | B8: =RIGHT(Q8,7) -> AGENT19 | C8: =L8 -> TIKUNG_2 | D8: =K8 -> LMG16A | H8: =P8 -> 2026-09-01 17:47:26 | K8: {=_xlfn.TEXTSPLIT(R8," ")} -> LMG16A | L8: TIKUNG_2 | P8: 2026-09-01 17:47:26 | Q8: 6660019 AGENT19 | R8: LMG16A TIKUNG_2 | S8: LS0000191120 | T8: Andy J07181603 | U8: obaforever/idnztapp/meeting/20260901/upload_17882596387188c5fd341c1f740458587409c40a8208b.MOV | V8: QR SPRINTER
A9: =INT(H9) -> 46266 | B9: =RIGHT(Q9,7) -> AGENT19 | C9: =L9 -> LAMONGAN_2 | D9: =K9 -> LMG01A | H9: =P9 -> 2026-09-01 17:46:36 | K9: {=_xlfn.TEXTSPLIT(R9," ")} -> LMG01A | L9: LAMONGAN_2 | P9: 2026-09-01 17:46:36 | Q9: 6660019 AGENT19 | R9: LMG01A LAMONGAN_2 | S9: 00552807 | T9: Ahmad Andy Fajar Wijaya | U9: obaforever/idnztapp/meeting/20260901/upload_1788259585707038868c22f8242ee8568de9349e01880.MOV | V9: QR SPRINTER
A10: =INT(H10) -> 46266 | B10: =RIGHT(Q10,7) -> AGENT04 | C10: =L10 -> UJUNG_TANJUNG_01 | D10: =K10 -> BAS02A | H10: =P10 -> 2026-09-01 17:45:31 | K10: {=_xlfn.TEXTSPLIT(R10," ")} -> BAS02A | L10: UJUNG_TANJUNG_01 | P10: 2026-09-01 17:45:31 | Q10: 6660004 AGENT04 | R10: BAS02A UJUNG_TANJUNG_01 | S10: 01685590 | T10: Febrianto . | U10: obaforever/idnztapp/meeting/20260901/upload_178825952006868c2272616514b6ab93e4a3b500f44ad.mp4
A11: =INT(H11) -> 46266 | B11: =RIGHT(Q11,7) -> AGENT19 | C11: =L11 -> MAYJEND_BARAT | D11: =K11 -> SUB90 | H11: =P11 -> 2026-09-01 17:16:47 | K11: {=_xlfn.TEXTSPLIT(R11," ")} -> SUB90 | L11: MAYJEND_BARAT | P11: 2026-09-01 17:16:47 | Q11: 6660019 AGENT19 | R11: SUB90 MAYJEND_BARAT | S11: SUB90000025 | T11: Ragil JM0060007 | U11: obaforever/idnztapp/meeting/20260901/upload_1788257796437c8f526b55e6a4c089c0dfbd7f48f2960.mp4 | V11: bulan baru target baru
A12: =INT(H12) -> 46266 | B12: =RIGHT(Q12,7) -> AGENT03 | C12: =L12 -> NEGERI_BARU_02 | D12: =K12 -> RPT02B | H12: =P12 -> 2026-09-01 17:14:23 | K12: {=_xlfn.TEXTSPLIT(R12," ")} -> RPT02B | L12: NEGERI_BARU_02 | P12: 2026-09-01 17:14:23 | Q12: 6660003 AGENT03 | R12: RPT02B NEGERI_BARU_02 | S12: LS0000221064 | T12: SITI NURHAZIZAH RPT02B | U12: obaforever/idnztapp/meeting/20260901/upload_1788257657324a5ac9f4360494dfaaa450b4e92064464.mp4
A13: =INT(H13) -> 46266 | B13: =RIGHT(Q13,7) -> AGENT19 | C13: =L13 -> BWI_GENTENG | D13: =K13 -> BWI10B | H13: =P13 -> 2026-09-01 17:14:13 | K13: {=_xlfn.TEXTSPLIT(R13," ")} -> BWI10B | L13: BWI_GENTENG | P13: 2026-09-01 17:14:13 | Q13: 6660019 AGENT19 | R13: BWI10B BWI_GENTENG | S13: LS0000371669 | T13: Prakoso J07230496 | U13: obaforever/idnztapp/meeting/20260901/VID_2026-09-01 05-12-351555569492aa3f98537874449fac259c490d57eece.mp4 | V13: Indikator rating Sprinter dan penilaian di setiap poin, penilaian customer dan fokus input paket reguler
A14: =INT(H14) -> 46266 | B14: =RIGHT(Q14,7) -> AGENT19 | C14: =L14 -> GLENMORE_1 | D14: =K14 -> BWI09A | H14: =P14 -> 2026-09-01 17:14:01 | K14: {=_xlfn.TEXTSPLIT(R14," ")} -> BWI09A | L14: GLENMORE_1 | P14: 2026-09-01 17:14:01 | Q14: 6660019 AGENT19 | R14: BWI09A GLENMORE_1 | S14: 01378927 | T14: Nor Dwi Prakoso | U14: obaforever/idnztapp/meeting/20260901/VID_2026-09-01 05-12-3057356577733569bd43f78433880dbd496f5ed36fb.mp4 | V14: Indikator rating Sprinter dan penilaian di setiap poin, penilaian customer dan fokus input paket reguler
A15: =INT(H15) -> 46266 | B15: =RIGHT(Q15,7) -> AGENT16 | C15: =L15 -> KALIANGSANA_2 | D15: =K15 -> SBG30 | H15: =P15 -> 2026-09-01 17:09:33 | K15: {=_xlfn.TEXTSPLIT(R15," ")} -> SBG30 | L15: KALIANGSANA_2 | P15: 2026-09-01 17:09:33 | Q15: 6660016 AGENT16 | R15: SBG30 KALIANGSANA_2 | S15: 01206511 | T15: Dede Rino Mailudin | U15: obaforever/idnztapp/meeting/20260901/upload_1788257347947f1f932143bcf4c5bbeade353ac055f10.MOV | V15: QUIZ APP SPRINTER
A16: =INT(H16) -> 46266 | B16: =RIGHT(Q16,7) -> AGENT23 | C16: =L16 -> WINANGUN_01 | D16: =K16 -> MDC09C | H16: =P16 -> 2026-09-01 17:08:34 | K16: {=_xlfn.TEXTSPLIT(R16," ")} -> MDC09C | L16: WINANGUN_01 | P16: 2026-09-01 17:08:34 | Q16: 6660023 AGENT23 | R16: MDC09C WINANGUN_01 | S16: MDC09C000001 | T16: Hizkia Owen Gosal | U16: obaforever/idnztapp/meeting/20260901/upload_17882573086253463309ebc284c3490bea4cf44e1e561.mp4
A17: =INT(H17) -> 46266 | B17: =RIGHT(Q17,7) -> AGENT19 | C17: =L17 -> GENTENG_BWI_1 | D17: =K17 -> BWI10A | H17: =P17 -> 2026-09-01 17:08:30 | K17: {=_xlfn.TEXTSPLIT(R17," ")} -> BWI10A | L17: GENTENG_BWI_1 | P17: 2026-09-01 17:08:30 | Q17: 6660019 AGENT19 | R17: BWI10A GENTENG_BWI_1 | S17: LS0000371717 | T17: Dwi J07230496 | U17: obaforever/idnztapp/meeting/20260901/VID_2026-09-01 05-07-111923041408d20a449e10284235ba0210bab66fc2ee.mp4 | V17: Indikator rating Sprinter dan penilaian di setiap poin, penilaian customer dan fokus input paket reguler
A18: =INT(H18) -> 46266 | B18: =RIGHT(Q18,7) -> AGENT25 | C18: =L18 -> TEWAH | D18: =K18 -> KUK02 | H18: =P18 -> 2026-09-01 17:06:00 | K18: {=_xlfn.TEXTSPLIT(R18," ")} -> KUK02 | L18: TEWAH | P18: 2026-09-01 17:06:00 | Q18: 6660025 AGENT25 | R18: KUK02 TEWAH | S18: 01254245 | T18: Predi Sinambela | U18: obaforever/idnztapp/meeting/20260901/upload_17882571566209e68082fbf4942a9814d4f03c9bbdf09.mp4
A19: =INT(H19) -> 46266 | B19: =RIGHT(Q19,7) -> AGENT16 | C19: =L19 -> SUM08D | D19: =K19 -> SUM08D | H19: =P19 -> 2026-09-01 17:04:52 | K19: {=_xlfn.TEXTSPLIT(R19," ")} -> SUM08D | L19: SUM08D | P19: 2026-09-01 17:04:52 | Q19: 6660016 AGENT16 | R19: SUM08D SUM08D | S19: LS0000415171 | T19: Indra Nuryanto | U19: obaforever/idnztapp/meeting/20260901/upload_17882570703524b61934086e6445e8e807cc274ea968f.MOV | V19: keluar gudang ttd jam 12 ttd aktual paycools gopay absensi karyawan
A20: =INT(H20) -> 46266 | B20: =RIGHT(Q20,7) -> AGENT19 | C20: =L20 -> SAMBENG | D20: =K20 -> LMG10 | H20: =P20 -> 2026-09-01 17:02:57 | K20: {=_xlfn.TEXTSPLIT(R20," ")} -> LMG10 | L20: SAMBENG | P20: 2026-09-01 17:02:57 | Q20: 6660019 AGENT19 | R20: LMG10 SAMBENG | S20: LMG100078 | T20: Said Jm0280021 | U20: obaforever/idnztapp/meeting/20260901/upload_1788256968542aa2e42b6c46141edbf895181d6efe7f5.mp4
A21: =INT(H21) -> 46266 | B21: =RIGHT(Q21,7) -> AGENT19 | C21: =L21 -> KEDUNGPRING_2 | D21: =K21 -> LMG24 | H21: =P21 -> 2026-09-01 17:02:00 | K21: {=_xlfn.TEXTSPLIT(R21," ")} -> LMG24 | L21: KEDUNGPRING_2 | P21: 2026-09-01 17:02:00 | Q21: 6660019 AGENT19 | R21: LMG24 KEDUNGPRING_2 | S21: LS0000208253 | T21: Said_01 JM0280021 | U21: obaforever/idnztapp/meeting/20260901/upload_1788256908761560ab8b7f44b487eba0d645e66b2c347.mp4
A22: =INT(H22) -> 46266 | B22: =RIGHT(Q22,7) -> AGENT16 | C22: =L22 -> KRW17A | D22: =K22 -> KRW17A | H22: =P22 -> 2026-09-01 16:56:44 | K22: {=_xlfn.TEXTSPLIT(R22," ")} -> KRW17A | L22: KRW17A | P22: 2026-09-01 16:56:44 | Q22: 6660016 AGENT16 | R22: KRW17A KRW17A | S22: LS0000415130 | T22: Reza Zaqiyuddin | U22: obaforever/idnztapp/meeting/20260901/upload_17882566002024c9df87eb2b843159b7d8e875f0af5e5.mp4
A23: =INT(H23) -> 46266 | B23: =RIGHT(Q23,7) -> AGENT16 | C23: =L23 -> BATUJAYA | D23: =K23 -> KRW16 | H23: =P23 -> 2026-09-01 16:56:15 | K23: {=_xlfn.TEXTSPLIT(R23," ")} -> KRW16 | L23: BATUJAYA | P23: 2026-09-01 16:56:15 | Q23: 6660016 AGENT16 | R23: KRW16 BATUJAYA | S23: LS0000415129 | T23: Reza Zaqiyuddin | U23: obaforever/idnztapp/meeting/20260901/upload_1788256570324c834262d2fb5498eb12410c7ede5bc7c.mp4
A24: =INT(H24) -> 46266 | B24: =RIGHT(Q24,7) -> AGENT16 | C24: =L24 -> CRN03E | D24: =K24 -> CRN03E | H24: =P24 -> 2026-09-01 16:55:35 | K24: {=_xlfn.TEXTSPLIT(R24," ")} -> CRN03E | L24: CRN03E | P24: 2026-09-01 16:55:35 | Q24: 6660016 AGENT16 | R24: CRN03E CRN03E | S24: LS0000415305 | T24: Dany Kurniawan | U24: obaforever/idnztapp/meeting/20260901/upload_178825637681328d3a36bc3a04dc4856316eecb5cd36d.mp4 | V24: peran sprinter
A25: =INT(H25) -> 46266 | B25: =RIGHT(Q25,7) -> AGENT26 | C25: =L25 -> UPAS_MAJU | D25: =K25 -> TTT02A | H25: =P25 -> 2026-09-01 16:41:51 | K25: {=_xlfn.TEXTSPLIT(R25," ")} -> TTT02A | L25: UPAS_MAJU | P25: 2026-09-01 16:41:51 | Q25: 6660026 AGENT26 | R25: TTT02A UPAS_MAJU | S25: LS0000430535 | T25: Darwis Mas Kartiwa_FL | U25: obaforever/idnztapp/meeting/20260901/upload_1788255659752e599d14c67624dfc954eec7e8517c987.mp4 | V25: brifing penggunaan yoyi dan stuk yoyi
A26: =INT(H26) -> 46266 | B26: =RIGHT(Q26,7) -> AGENT26 | C26: =L26 -> SAJINGAN_BESAR_01 | D26: =K26 -> SAS07A | H26: =P26 -> 2026-09-01 16:33:44 | K26: {=_xlfn.TEXTSPLIT(R26," ")} -> SAS07A | L26: SAJINGAN_BESAR_01 | P26: 2026-09-01 16:33:44 | Q26: 6660026 AGENT26 | R26: SAS07A SAJINGAN_BESAR_01 | S26: SAS07A000009 | T26: Nuari Sukriawan | U26: obaforever/idnztapp/meeting/20260901/VID_2026-09-01 04-31-59177932406372fc7844ed04406782542e2663442151.mp4
A27: =INT(H27) -> 46266 | B27: =RIGHT(Q27,7) -> AGENT19 | C27: =L27 -> NGANJUK_3 | D27: =K27 -> NGK01A | H27: =P27 -> 2026-09-01 16:31:48 | K27: {=_xlfn.TEXTSPLIT(R27," ")} -> NGK01A | L27: NGANJUK_3 | P27: 2026-09-01 16:31:48 | Q27: 6660019 AGENT19 | R27: NGK01A NGANJUK_3 | S27: NGK01A000004 | T27: Didit JM0430005 | U27: obaforever/idnztapp/meeting/20260901/upload_178825509644168ebca472f9e46c1b52b815c90c8aaf2.mp4 | V27: push pencapaian SLA & Reminder paket High Value
A28: =INT(H28) -> 46266 | B28: =RIGHT(Q28,7) -> AGENT19 | C28: =L28 -> LOCERET | D28: =K28 -> NGK03 | H28: =P28 -> 2026-09-01 16:28:16 | K28: {=_xlfn.TEXTSPLIT(R28," ")} -> NGK03 | L28: LOCERET | P28: 2026-09-01 16:28:16 | Q28: 6660019 AGENT19 | R28: NGK03 LOCERET | S28: NGK03000002 | T28: Didit JM0430005 | U28: obaforever/idnztapp/meeting/20260901/upload_1788254808252dbe77be24d2a49eeb294630c9c8a8142.mp4 | V28: push pencapaian SLA & Reminder paket High Value
A29: =INT(H29) -> 46266 | B29: =RIGHT(Q29,7) -> AGENT16 | C29: =L29 -> DC_MARGAASIH | D29: =K29 -> SOG30 | H29: =P29 -> 2026-09-01 16:21:29 | K29: {=_xlfn.TEXTSPLIT(R29," ")} -> SOG30 | L29: DC_MARGAASIH | P29: 2026-09-01 16:21:29 | Q29: 6660016 AGENT16 | R29: SOG30 DC_MARGAASIH | S29: LS0000415111 | T29: Soni | U29: obaforever/idnztapp/meeting/20260901/upload_1788254380566eb1bf1b57a53415db052d5a542a5fe13.mp4 | V29: 1.Ttd jam 12 2.Rating sprinter 3.Sop 6s
A30: =INT(H30) -> 46266 | B30: =RIGHT(Q30,7) -> AGENT19 | C30: =L30 -> DC_TUGU_PENDEKAR | D30: =K30 -> MDN09 | H30: =P30 -> 2026-09-01 16:19:56 | K30: {=_xlfn.TEXTSPLIT(R30," ")} -> MDN09 | L30: DC_TUGU_PENDEKAR | P30: 2026-09-01 16:19:56 | Q30: 6660019 AGENT19 | R30: MDN09 DC_TUGU_PENDEKAR | S30: MDN09000012 | T30: Boma JM0420001 | U30: obaforever/idnztapp/meeting/20260901/upload_1788254384048052b4cf852434b8d98aa9df572067cbb.mp4 | V30: parcel care
A31: =INT(H31) -> 46266 | B31: =RIGHT(Q31,7) -> AGENT19 | C31: =L31 -> SRENGAT | D31: =K31 -> BLT03 | H31: =P31 -> 2026-09-01 16:18:52 | K31: {=_xlfn.TEXTSPLIT(R31," ")} -> BLT03 | L31: SRENGAT | P31: 2026-09-01 16:18:52 | Q31: 6660019 AGENT19 | R31: BLT03 SRENGAT | S31: BLT030131 | T31: Andrean Jm0390005 | U31: obaforever/idnztapp/meeting/20260901/upload_17882543094310b508f2d0cee4a2c87a2ab84273444e0.MOV
A32: =INT(H32) -> 46266 | B32: =RIGHT(Q32,7) -> AGENT16 | C32: =L32 -> IDM07E | D32: =K32 -> IDM07E | H32: =P32 -> 2026-09-01 16:17:34 | K32: {=_xlfn.TEXTSPLIT(R32," ")} -> IDM07E | L32: IDM07E | P32: 2026-09-01 16:17:34 | Q32: 6660016 AGENT16 | R32: IDM07E IDM07E | S32: LS0000415239 | T32: Muhamad Ali Assegap | U32: obaforever/idnztapp/meeting/20260901/VID_2026-09-01 04-16-35225829087450caa870ab641d5847caaed19100090.mp4
A33: =INT(H33) -> 46266 | B33: =RIGHT(Q33,7) -> AGENT19 | C33: =L33 -> GUBENG_2 | D33: =K33 -> SUB12B | H33: =P33 -> 2026-09-01 16:16:04 | K33: {=_xlfn.TEXTSPLIT(R33," ")} -> SUB12B | L33: GUBENG_2 | P33: 2026-09-01 16:16:04 | Q33: 6660019 AGENT19 | R33: SUB12B GUBENG_2 | S33: SUB12B000001 | T33: Ainun JM0580007 | U33: obaforever/idnztapp/meeting/20260901/VID_2026-09-01 04-15-2516618453116f0832f4404a46738f2ca92212653654.mp4 | V33: UPM Sprinter Persiapan kunjungan dari Malaysia dan Thailand
A34: =INT(H34) -> 46266 | B34: =RIGHT(Q34,7) -> AGENT16 | C34: =L34 -> KARAWANG_WETAN | D34: =K34 -> KRW23B | H34: =P34 -> 2026-09-01 16:15:12 | K34: {=_xlfn.TEXTSPLIT(R34," ")} -> KRW23B | L34: KARAWANG_WETAN | P34: 2026-09-01 16:15:12 | Q34: 6660016 AGENT16 | R34: KRW23B KARAWANG_WETAN | S34: LS0000415118 | T34: Asep | U34: obaforever/idnztapp/meeting/20260901/upload_17882540951225fa117b625074ddfa4b62a0004d566f5.mp4 | V34: briefing
A35: =INT(H35) -> 46266 | B35: =RIGHT(Q35,7) -> AGENT16 | C35: =L35 -> GRT32A | D35: =K35 -> GRT32A | H35: =P35 -> 2026-09-01 16:14:59 | K35: {=_xlfn.TEXTSPLIT(R35," ")} -> GRT32A | L35: GRT32A | P35: 2026-09-01 16:14:59 | Q35: 6660016 AGENT16 | R35: GRT32A GRT32A | S35: LS0000415094 | T35: Undang Ramdani | U35: obaforever/idnztapp/meeting/20260901/upload_178825409201689a9e37c840d4c938e6daa3ecaa459ed.mp4
A36: =INT(H36) -> 46266 | B36: =RIGHT(Q36,7) -> AGENT19 | C36: =L36 -> TEGALSARI_4 | D36: =K36 -> SUB30B | H36: =P36 -> 2026-09-01 16:07:12 | K36: {=_xlfn.TEXTSPLIT(R36," ")} -> SUB30B | L36: TEGALSARI_4 | P36: 2026-09-01 16:07:12 | Q36: 6660019 AGENT19 | R36: SUB30B TEGALSARI_4 | S36: SUB30B000001 | T36: Taufiq JM0580048 | U36: obaforever/idnztapp/meeting/20260901/VID_2026-09-01 04-04-57-537609488601a7c0ffd4b3bb995cc985e155b6e.mp4 | V36: Nama DP : TEGALSARI_4 Kode DP : SUB30B Total Brifing : 33 orang Materi Brifing : 1.Kebersihan DP 2.Grooming kayawan 3.Evaluasi kinerja di bulan Agustus dan plan September 4.persiapan kunjungan
A37: =INT(H37) -> 46266 | B37: =RIGHT(Q37,7) -> AGENT16 | C37: =L37 -> CIBUAYA | D37: =K37 -> KRW21 | H37: =P37 -> 2026-09-01 16:05:48 | K37: {=_xlfn.TEXTSPLIT(R37," ")} -> KRW21 | L37: CIBUAYA | P37: 2026-09-01 16:05:48 | Q37: 6660016 AGENT16 | R37: KRW21 CIBUAYA | S37: LS0000415119 | T37: Dede Asikin | U37: obaforever/idnztapp/meeting/20260901/VID_2026-09-01 04-04-4213733761782df34881868438a83a0d71025eaeafc.mp4 | V37: marketing dan penanganan paket retur outgoing
A38: =INT(H38) -> 46266 | B38: =RIGHT(Q38,7) -> AGENT19 | C38: =L38 -> WONOREJO_PSR | D38: =K38 -> PSR05 | H38: =P38 -> 2026-09-01 16:04:56 | K38: {=_xlfn.TEXTSPLIT(R38," ")} -> PSR05 | L38: WONOREJO_PSR | P38: 2026-09-01 16:04:56 | Q38: 6660019 AGENT19 | R38: PSR05 WONOREJO_PSR | S38: 01820826 | T38: Ilham Ramadhan | U38: obaforever/idnztapp/meeting/20260901/VID_2026-09-01 04-04-44-20843276924cf895e4434e427dbb5f233901b9facc.mp4
A39: =INT(H39) -> 46266 | B39: =RIGHT(Q39,7) -> AGENT18 | C39: =L39 -> PEDAN | D39: =K39 -> KLT06 | H39: =P39 -> 2026-09-01 16:01:27 | K39: {=_xlfn.TEXTSPLIT(R39," ")} -> KLT06 | L39: PEDAN | P39: 2026-09-01 16:01:27 | Q39: 6660018 AGENT18 | R39: KLT06 PEDAN | S39: 00571208 | T39: Eko Febri ,Laksono | U39: obaforever/idnztapp/meeting/20260901/upload_1788253231718cfd356afd49f4494bdf431e7e9666f3d.mp4 | V39: absen sebelum jam 6.00 kwis app sprinter ttd jam 12.00
A40: =INT(H40) -> 46266 | B40: =RIGHT(Q40,7) -> AGENT19 | C40: =L40 -> BWI_TEGALSARI_2 | D40: =K40 -> BWI13A | H40: =P40 -> 2026-09-01 15:57:17 | K40: {=_xlfn.TEXTSPLIT(R40," ")} -> BWI13A | L40: BWI_TEGALSARI_2 | P40: 2026-09-01 15:57:17 | Q40: 6660019 AGENT19 | R40: BWI13A BWI_TEGALSARI_2 | S40: LS0000029908 | T40: Riva J07210989 | U40: obaforever/idnztapp/meeting/20260901/VID_2026-09-01 03-56-15-1917005546dc010f6569dd46a9be98640991f16bbb.mp4 | V40: brefing pagi bersama kurir pembahasan terkait cara identifikasi calon customer dengan volume tinggi dan lebih fokus terhadap seller UMKM dan toko rumahan serta memperhatikan area kompetitor
...

Sheet Raw data yang sudah upload
A1: Tanggal upload fin | B1: Kode Agent 代理区代码 | C1: Nama Drop Point 网点名称 | D1: Kode Drop Point 网点代码 | E1: Video Briefing 班前例会视频 | F1: Summary Briefing 会议要点总结 | G1: Kategori Materi | H1: Tanggal Upload 上传日期 | I1: Sprinter Ikut breifing hari ini | J1: Total Sprinter | K1: created by | L1: status | M1: Last Modified Date 2 | N1: feedback DP | O1: total DP | W1: Status DP | X1: Sebelum 15:00
A2: 46266 | B2: AGENT23 | C2: MASOHI | D2: MSI01 | E2: 2026-09-01 06.34.05_.mp4 | F2: POD VALID DAN MARKETING | G2: Marketing | H2: 46266.194 | I2: 8 | J2: 16 | K2: Amina Abd. Khair | M2: 46266.194 | N2: Masih | O2: 175 | W2: =_xlfn.XLOOKUP(D2,'All DP'!B:B,'All DP'!D:D,"Tidak") -> Masih | X2: =IFERROR(IF(MOD(H2,1)<=TIME(15,0,0),"YA","TIDAK"),0) -> YA
A3: 46266 | B3: AGENT23 | C3: WAEAPO | D3: NAM02 | E3: 1ac716247d7932dbfa26a61de418409e.jpg | F3: BRIFING DP NAM02 1 AGUSTUS 2026 - RITASE - PAYCOOLS - E POD - POD RETUR VALID - ARBITRASE - LONG TAIL - TIKET PLATFROM - PARCEL CARE - DENDA HQ | G3: other | H3: 46266.196 | I3: 5 | J3: 10 | K3: Marselinus Tehe | M3: 46266.196 | N3: Masih | O3: 175 | W3: =_xlfn.XLOOKUP(D3,'All DP'!B:B,'All DP'!D:D,"Tidak") -> Masih | X3: =IFERROR(IF(MOD(H3,1)<=TIME(15,0,0),"YA","TIDAK"),0) -> YA
A4: 46266 | B4: AGENT23 | C4: GEMBA | D4: PRU02 | E4: BREFING.jpeg | F4: BREAFING GEMBA TGL 01 September 2026 1. PUSH TTD KEJAR RITASE > 90% 2. PEMBAYARAN PAYCOOLS 3. EPOD HARUS VALID 92% 4. KODE KETIGA 5. RETUR DGN POD VALID 6. KEBERSIHAN DP 7. PENGGUNAAN KODE QR DP & SPRINTER 8. SOP MENGANTAR 9.PARCEL CARE | G4: Marketing | H4: 46266.213 | I4: 3 | J4: 3 | K4: Dewi Sriyanti Seipalla | M4: 46266.213 | N4: Masih | O4: 175 | W4: =_xlfn.XLOOKUP(D4,'All DP'!B:B,'All DP'!D:D,"Tidak") -> Masih | X4: =IFERROR(IF(MOD(H4,1)<=TIME(15,0,0),"YA","TIDAK"),0) -> YA
A5: 46266 | B5: AGENT23 | C5: LABUHA | D5: LAH01 | E5: 2026-09-01 06.46.11__(Judul-Absensi).mp4 | F5: 1. Absensi sebelum jam 6:30 2. Delivery sebelum jam 12 3. Tidak boleh tahan paket diatas 3 hari Jaga kebersihan dp 4. Terapkan 3S | G5: other | H5: 46266.227 | I5: 21 | J5: 25 | K5: Rifaldi Sanaba | M5: 46266.227 | N5: Masih | O5: 175 | W5: =_xlfn.XLOOKUP(D5,'All DP'!B:B,'All DP'!D:D,"Tidak") -> Masih | X5: =IFERROR(IF(MOD(H5,1)<=TIME(15,0,0),"YA","TIDAK"),0) -> YA
A6: 46266 | B6: AGENT23 | C6: GALALA | D6: AMQ07 | E6: 2026-09-01 07.20.44_Jalan Jenderal Sudirman_(Pemeriksa-DP AMQ07_GALALA).jpg | F6: BRIEFING PAGI AMQ07 GALALA 1 SEPTEMBER 2026 ABSEN 6.30 PUSH TTD JAM 12 LONGTAIL PARCEL CARE POD RETUR DAN PU VALID PUSH PAYCOOLS | G6: other | H6: 46266.229 | I6: 23 | J6: 24 | K6: Zulfikry Ramadhan Ismail | M6: 46266.229 | N6: Masih | O6: 175 | W6: =_xlfn.XLOOKUP(D6,'All DP'!B:B,'All DP'!D:D,"Tidak") -> Masih | X6: =IFERROR(IF(MOD(H6,1)<=TIME(15,0,0),"YA","TIDAK"),0) -> YA
A7: 46266 | B7: AGENT23 | C7: BOBONG | D7: BOB01 | E7: 20260901_70848AMByGPSMapCamera.jpg | F7: *GROOMING & BRIEFING BOBONG* Pembahasan. ->Push TTD ->TTD REAL TIME ->Di perhatikan paket yg stuck. ->Jujur dalam berkerja. ->Disiplin dgn waktu. ->Penambahan SDM | G7: other | H7: 46266.234 | I7: 1 | J7: 1 | K7: Farisal Irawan | M7: 46266.234 | N7: Masih | O7: 175 | W7: =_xlfn.XLOOKUP(D7,'All DP'!B:B,'All DP'!D:D,"Tidak") -> Masih | X7: =IFERROR(IF(MOD(H7,1)<=TIME(15,0,0),"YA","TIDAK"),0) -> YA
A8: 46266 | B8: AGENT23 | C8: PAGUYAMAN | D8: LBO02 | E8: 2026-09-01 06.32.23_.mp4 | F8: PUSH 6.30 PUSH QR SPRINTER PUSH TTD/RITASE | G8: Marketing | H8: 46266.234 | I8: 7 | J8: 8 | K8: Alvian Ahmad | M8: 46266.234 | N8: Masih | O8: 175 | W8: =_xlfn.XLOOKUP(D8,'All DP'!B:B,'All DP'!D:D,"Tidak") -> Masih | X8: =IFERROR(IF(MOD(H8,1)<=TIME(15,0,0),"YA","TIDAK"),0) -> YA
A9: 46266 | B9: AGENT23 | C9: DONGGALA | D9: DON01 | E9: 2026-09-01 06.33.10_Jalan Pettalolo_(Judul-DP DON01).jpg | F9: ABSENSI PUSH TTD PAYCOOLS POD VALID LONGTAIL QR SPRINTER | G9: Marketing | H9: 46266.235 | I9: 10 | J9: 17 | K9: Zainuddin . | M9: 46266.236 | N9: Masih | O9: 175 | W9: =_xlfn.XLOOKUP(D9,'All DP'!B:B,'All DP'!D:D,"Tidak") -> Masih | X9: =IFERROR(IF(MOD(H9,1)<=TIME(15,0,0),"YA","TIDAK"),0) -> YA
A10: 46266 | B10: AGENT23 | C10: KEBUN_CENGKEH | D10: AMQ02 | E10: 20260901-053848.jpg | F10: 1. QUIZ APP SPRINTER 2. PUSH ABSENSI 06.30 3. PICK-UP 4. SIMPANG GUDANG POD VALID 5. KELUAR 07.30 DAN TTD JAM 12.00 6. PAYCOOLS & GOPAY 7. LONGTAIL | G10: other | H10: 46266.239 | I10: 4 | J10: 20 | K10: Fahbi Safitri | M10: 46266.239 | N10: Masih | O10: 175 | W10: =_xlfn.XLOOKUP(D10,'All DP'!B:B,'All DP'!D:D,"Tidak") -> Masih | X10: =IFERROR(IF(MOD(H10,1)<=TIME(15,0,0),"YA","TIDAK"),0) -> YA
A11: 46266 | B11: AGENT23 | C11: FALAJAWA2 | D11: TTE05 | E11: WhatsApp Video 2026-09-01 at 07.46.25.mp4 | F11: PUSH KPI | G11: other | H11: 46266.244 | I11: 2 | J11: 3 | K11: Fadila Samsudin | M11: 46266.244 | N11: Masih | O11: 175 | W11: =_xlfn.XLOOKUP(D11,'All DP'!B:B,'All DP'!D:D,"Tidak") -> Masih | X11: =IFERROR(IF(MOD(H11,1)<=TIME(15,0,0),"YA","TIDAK"),0) -> YA
A12: 46266 | B12: AGENT23 | C12: SOJOL | D12: DON13 | E12: IMG-20260901-WA0003(1).jpg | F12: Awb HV,pod, simpan gudang, ujian sprinter | G12: Marketing | H12: 46266.244 | I12: 5 | J12: 5 | K12: Memet . | M12: 46266.244 | N12: Masih | O12: 175 | W12: =_xlfn.XLOOKUP(D12,'All DP'!B:B,'All DP'!D:D,"Tidak") -> Masih | X12: =IFERROR(IF(MOD(H12,1)<=TIME(15,0,0),"YA","TIDAK"),0) -> YA
A13: 46266 | B13: AGENT21 | C13: KETEWEL | D13: GIA01B | E13: 20260901_64122AMByGPSMapCamera.mp4 | F13: brifing tentang TTD paksa T7 keatas | G13: other | H13: 46266.245 | I13: 19 | J13: 26 | K13: Rifqi Al'Afif Ramadhan | M13: 46266.245 | N13: Masih | O13: 176 | W13: =_xlfn.XLOOKUP(D13,'All DP'!B:B,'All DP'!D:D,"Tidak") -> Masih | X13: =IFERROR(IF(MOD(H13,1)<=TIME(15,0,0),"YA","TIDAK"),0) -> YA
... A17: 46266 | B17: AGENT23 | C17: TUAL | D17: UAL01 | E17: 2026-09-01 07.14.34_Jalan Doktor Leimena_(Judul-Visit)_(Catatan-Kunjungan Harian).jpg | F17: Push TTD sebelum jam 12 Push paycools Push satu sprinter satu pickupan | G17: Marketing | H17: 46266.252 | I17: 6 | J17: 8 | K17: Kufra Ahmad Toha Rery | M17: 46266.252 | N17: Masih | O17: 175 | W17: =_xlfn.XLOOKUP(D17,'All DP'!B:B,'All DP'!D:D,"Tidak") -> Masih | X17: =IFERROR(IF(MOD(H17,1)<=TIME(15,0,0),"YA","TIDAK"),0) -> YA
A18: 46266 | B18: AGENT22 | C18: PEKKABATA | D18: PRR02 | E18: VID-20260901-WA0051.mp4 | F18: Absensi Quis app Paket longtail | G18: other | H18: 46266.252 | I18: 11 | J18: 16 | K18: Rusli At | M18: 46266.253 | O18: 148 | W18: =_xlfn.XLOOKUP(D18,'All DP'!B:B,'All DP'!D:D,"Tidak") -> Masih | X18: =IFERROR(IF(MOD(H18,1)<=TIME(15,0,0),"YA","TIDAK"),0) -> YA
A19: 46266 | B19: AGENT23 | C19: BONE_PANTAI | D19: SUW02 | E19: 2026-09-01 06.46.43_.jpg | F19: ABESENSI 06.30, TTD SEBELUM JAM 12 | G19: other | H19: 46266.254 | I19: 5 | J19: 9 | K19: Arya Yoga Pangestu | M19: 46266.254 | N19: Masih | O19: 175 | W19: =_xlfn.XLOOKUP(D19,'All DP'!B:B,'All DP'!D:D,"Tidak") -> Masih | X19: =IFERROR(IF(MOD(H19,1)<=TIME(15,0,0),"YA","TIDAK"),0) -> YA
A20: 46266 | B20: AGENT23 | C20: MABA | D20: MAB01 | E20: 2026-09-01 07.42.55_Maba Sangaji.JPEG | F20: QR SPRINTER (mkt) ptmp, stuck (NM) | G20: Marketing | H20: 46266.257 | I20: 10 | J20: 6 | K20: Hardi . | M20: 46266.257 | N20: Masih | O20: 175 | W20: =_xlfn.XLOOKUP(D20,'All DP'!B:B,'All DP'!D:D,"Tidak") -> Masih | X20: =IFERROR(IF(MOD(H20,1)<=TIME(15,0,0),"YA","TIDAK"),0) -> YA
A21: 46266 | B21: AGENT23 | C21: AMPIBABO | D21: PII04 | E21: BRIFING PAGI.jpg | F21: PUSH PAKET LONGTAIL ABSENSI TIKTOK REVERSE | G21: other | H21: 46266.257 | I21: 4 | J21: 9 | K21: Nurhaliza . | M21: 46266.257 | N21: Masih | O21: 175 | W21: =_xlfn.XLOOKUP(D21,'All DP'!B:B,'All DP'!D:D,"Tidak") -> Masih | X21: =IFERROR(IF(MOD(H21,1)<=TIME(15,0,0),"YA","TIDAK"),0) -> YA
A22: 46266 | B22: AGENT23 | C22: DIMEMBE | D22: AID02A | E22: 2026-09-01_06.51.38_Jalan_Sukur_-_Likupang_(Company-J&T_Express)[1].jpg | F22: END STATUS, POD | G22: other | H22: 46266.257 | I22: 4 | J22: 9 | K22: Febrika Falensia Effendie | M22: 46266.257 | O22: 175 | W22: =_xlfn.XLOOKUP(D22,'All DP'!B:B,'All DP'!D:D,"Tidak") -> Masih | X22: =IFERROR(IF(MOD(H22,1)<=TIME(15,0,0),"YA","TIDAK"),0) -> YA
A23: 46266 | B23: AGENT22 | C23: BENU_BENUA | D23: KDI11 | E23: 2026-09-01 07.03.32_Jnt Benu Benua.jpeg | F23: memaksimalkan paket di dp mengedukasikan untuk datang lebih awal agar keluar delivery lebih awal juga hati2 saat berkendara mengedukasikan uktuk menggunakan pod valid pada saat meretur dan gagal pick up paket | G23: other | H23: 46266.257 | I23: 15 | J23: 19 | K23: Fitra Chalik | M23: 46266.257 | O23: 148 | W23: =_xlfn.XLOOKUP(D23,'All DP'!B:B,'All DP'!D:D,"Tidak") -> Masih | X23: =IFERROR(IF(MOD(H23,1)<=TIME(15,0,0),"YA","TIDAK"),0) -> YA
A24: 46266 | B24: AGENT23 | C24: TENTENA | D24: PSJ02 | E24: IMG_4724.JPEG | F24: 1. PARCEL CARE 2. KEBERSIHAN DP 3. PUSH TTD SEBELUM JAM 12 4. POD VALID 5. POD RETUR 6. PELAYANAN DP 7. MAKSIMALKAN PAKET 8. PICKUP QR SPRINTER 9. ABSENSI 6.30 | G24: Marketing | H24: 46266.257 | I24: 11 | J24: 11 | K24: Stefi Landika | M24: 46266.258 | N24: Masih | O24: 175 | W24: =_xlfn.XLOOKUP(D24,'All DP'!B:B,'All DP'!D:D,"Tidak") -> Masih | X24: =IFERROR(IF(MOD(H24,1)<=TIME(15,0,0),"YA","TIDAK"),0) -> YA
A25: 46266 | B25: AGENT28 | C25: MERAUKE | D25: MKQ01 | E25: TimePhoto_20260901_075908.jpg | F25: paket lontail dan paket priofitas | G25: other | H25: 46266.258 | I25: 19 | J25: 3 | K25: Pengguna Tamu 46219 | M25: 46266.258 | O25: 13 | W25: =_xlfn.XLOOKUP(D25,'All DP'!B:B,'All DP'!D:D,"Tidak") -> Masih | X25: =IFERROR(IF(MOD(H25,1)<=TIME(15,0,0),"YA","TIDAK"),0) -> YA
A26: 46266 | B26: AGENT22 | C26: NGAPA | D26: LAS02 | E26: hasil_LAS02_1788217968721.mp4 | F26: pod, absensi, delivery jam 07.30 | G26: other | H26: 46266.261 | I26: 13 | J26: 15 | K26: Pengguna Tamu 90586 | M26: 46266.261 | O26: 148 | W26: =_xlfn.XLOOKUP(D26,'All DP'!B:B,'All DP'!D:D,"Tidak") -> Masih | X26: =IFERROR(IF(MOD(H26,1)<=TIME(15,0,0),"YA","TIDAK"),0) -> YA
A27: 46266 | B27: AGENT23 | C27: MADIDIR | D27: BIT03 | E27: WhatsApp Image 2026-09-01 at 07.04.35.jpeg,WhatsApp Video 2026-09-01 at 07.06.30.mp4 | F27: LONG TAIL TTD JAM 12 ABSENSI KEBERSIHAN | G27: other | H27: 46266.261 | I27: 23 | J27: 23 | K27: Anglie Meihua Lim | M27: 46266.261 | N27: Masih | O27: 175 | W27: =_xlfn.XLOOKUP(D27,'All DP'!B:B,'All DP'!D:D,"Tidak") -> Masih | X27: =IFERROR(IF(MOD(H27,1)<=TIME(15,0,0),"YA","TIDAK"),0) -> YA
A28: 46266 | B28: AGENT21 | C28: SEMINYAK_1 | D28: MGW04C | E28: b1ddf51b-73cb-4ea1-a651-99ab727fd3e8.mp4 | F28: Longtail | G28: other | H28: 46266.261 | I28: 40 | J28: 50 | K28: Diana Ursula Wati | M28: 46266.261 | N28: Masih | O28: 176 | W28: =_xlfn.XLOOKUP(D28,'All DP'!B:B,'All DP'!D:D,"Tidak") -> Masih | X28: =IFERROR(IF(MOD(H28,1)<=TIME(15,0,0),"YA","TIDAK"),0) -> YA
A29: 46266 | B29: AGENT22 | C29: TINANGGEA | D29: WAG21 | E29: 2026-09-01 07.13.58_Jalan Poros Lapulu_(TINANGGEA).jpg | F29: pod Ttd absen | G29: other | H29: 46266.261 | I29: 18 | J29: 18 | K29: Sutarno . | M29: 46266.261 | O29: 148 | W29: =_xlfn.XLOOKUP(D29,'All DP'!B:B,'All DP'!D:D,"Tidak") -> Masih | X29: =IFERROR(IF(MOD(H29,1)<=TIME(15,0,0),"YA","TIDAK"),0) -> YA
A30: 46266 | B30: AGENT23 | C30: KAKASKASEN | D30: TMH02 | E30: img_v3_02154_e328b5c8-c7cd-4eec-8fc6-d2f54ec1e2hu.jpg | F30: POD PARCELCARE QR SPRINTER/DP PAYCOOLS LONGTAIL KEBERSIHAN | G30: Marketing | H30: 46266.262 | I30: 13 | J30: 20 | K30: Anggreyni Marini Marentek | M30: 46266.262 | N30: Masih | O30: 175 | W30: =_xlfn.XLOOKUP(D30,'All DP'!B:B,'All DP'!D:D,"Tidak") -> Masih | X30: =IFERROR(IF(MOD(H30,1)<=TIME(15,0,0),"YA","TIDAK"),0) -> YA
A31: 46266 | B31: AGENT23 | C31: SOFIFI | D31: TID02 | E31: VID-20260901-WA0006.mp4 | F31: PAKET 3 HARI STORAN | G31: other | H31: 46266.264 | I31: 12 | J31: 20 | K31: Karmila Gorotomole | M31: 46266.264 | N31: Masih | O31: 175 | W31: =_xlfn.XLOOKUP(D31,'All DP'!B:B,'All DP'!D:D,"Tidak") -> Masih | X31: =IFERROR(IF(MOD(H31,1)<=TIME(15,0,0),"YA","TIDAK"),0) -> YA
A32: 46266 | B32: AGENT22 | C32: BALANIPA | D32: PWX03 | E32: IMG-20260901-WA0021.jpg | F32: Target pick up dan pod retur | G32: other | H32: 46266.264 | I32: 18 | J32: 28 | K32: Wahyu . | M32: 46266.264 | O32: 148 | W32: =_xlfn.XLOOKUP(D32,'All DP'!B:B,'All DP'!D:D,"Tidak") -> Masih | X32: =IFERROR(IF(MOD(H32,1)<=TIME(15,0,0),"YA","TIDAK"),0) -> YA
A33: 46266 | B33: AGENT18 | C33: NGAGLIK | D33: SLM03 | E33: aa0c843b-4be0-42dd-9224-5dafa88ce718.JPEG | F33: ttd jam 12 | G33: other | H33: 46266.266 | I33: 7 | J33: 23 | K33: Soeko Wicaksono Novianto | M33: 46266.266 | N33: Masih | O33: 129 | W33: =_xlfn.XLOOKUP(D33,'All DP'!B:B,'All DP'!D:D,"Tidak") -> Masih | X33: =IFERROR(IF(MOD(H33,1)<=TIME(15,0,0),"YA","TIDAK"),0) -> YA
A34: 46266 | B34: AGENT21 | C34: NEGARA_1 | D34: NRG01A | E34: 20260901_71748AMByGPSMapCamera.mp4 | F34: mengenai paket yang sudah 3 hari dan simpan gudang atau paket bermasalah | G34: other | H34: 46266.266 | I34: 30 | J34: 45 | K34: Pengguna Tamu 95133 | M34: 46266.266 | N34: Masih | O34: 176 | W34: =_xlfn.XLOOKUP(D34,'All DP'!B:B,'All DP'!D:D,"Tidak") -> Masih | X34: =IFERROR(IF(MOD(H34,1)<=TIME(15,0,0),"YA","TIDAK"),0) -> YA
A35: 46266 | B35: AGENT27 | C35: SAMARINDA | D35: SRI01 | E35: 2026-09-01 07.23.24_Citraland City.jpeg | F35: ttd sblm jm12 | G35: other | H35: 46266.267 | I35: 4 | J35: 21 | K35: Pengguna Tamu 68821 | M35: 46266.267 | O35: 165 | W35: =_xlfn.XLOOKUP(D35,'All DP'!B:B,'All DP'!D:D,"Tidak") -> Masih | X35: =IFERROR(IF(MOD(H35,1)<=TIME(15,0,0),"YA","TIDAK"),0) -> YA
A36: 46266 | B36: AGENT22 | C36: MAKASSAR | D36: UPG01 | E36: 2026-09-01 7.12.33 AM_Jalan Veteran Selatan No. 64.mp4 | F36: POD Scan Bermasalah | G36: other | H36: 46266.268 | I36: 7 | J36: 31 | K36: Guest User 21841 | M36: 46266.268 | O36: 148 | W36: =_xlfn.XLOOKUP(D36,'All DP'!B:B,'All DP'!D:D,"Tidak") -> Masih | X36: =IFERROR(IF(MOD(H36,1)<=TIME(15,0,0),"YA","TIDAK"),0) -> YA
A37: 46266 | B37: AGENT23 | C37: TOMPASO_BARU | D37: AMR16 | E37: 2026-09-01 07.09.58_.jpg | F37: ABSENSI SLA TTD SSEBELUM JAM 12 PEYCOLS | G37: other | H37: 46266.269 | I37: 5 | J37: 11 | K37: Cinta Celsi Tarumingkeng | M37: 46266.269 | N37: Masih | O37: 175 | W37: =_xlfn.XLOOKUP(D37,'All DP'!B:B,'All DP'!D:D,"Tidak") -> Masih | X37: =IFERROR(IF(MOD(H37,1)<=TIME(15,0,0),"YA","TIDAK"),0) -> YA
A38: 46266 | B38: AGENT21 | C38: JEMBRANA | D38: NRG03A | E38: WhatsApp Video 2026-09-01 at 06.25.40.mp4 | F38: SHARING SPRINTER BINTANG 5 PENILAIAN CUSTOMER DI APP CUSTOMER | G38: Marketing | H38: 46266.269 | I38: 18 | J38: 19 | K38: Eni Maryana | M38: 46266.269 | N38: Masih | O38: 176 | W38: =_xlfn.XLOOKUP(D38,'All DP'!B:B,'All DP'!D:D,"Tidak") -> Masih | X38: =IFERROR(IF(MOD(H38,1)<=TIME(15,0,0),"YA","TIDAK"),0) -> YA
A39: 46266 | B39: AGENT22 | C39: WUNDULAKO | D39: KOL05 | E39: 2026-09-01 07.16.56_.mp4 | F39: memaksimalkanp | G39: other | H39: 46266.271 | I39: 8 | J39: 9 | K39: Irpandi . | M39: 46266.271 | O39: 148 | W39: =_xlfn.XLOOKUP(D39,'All DP'!B:B,'All DP'!D:D,"Tidak") -> Masih | X39: =IFERROR(IF(MOD(H39,1)<=TIME(15,0,0),"YA","TIDAK"),0) -> YA
A40: 46266 | B40: AGENT22 | C40: KADIA | D40: KDI02 | E40: WhatsApp Image 2026-09-01 at 06.29.32.jpeg | F40: 1awb perhari | G40: Marketing | H40: 46266.272 | I40: 23 | J40: 26 | K40: Andi Fachri Ramadhan | M40: 46266.273 | O40: 148 | W40: =_xlfn.XLOOKUP(D40,'All DP'!B:B,'All DP'!D:D,"Tidak") -> Masih | X40: =IFERROR(IF(MOD(H40,1)<=TIME(15,0,0),"YA","TIDAK"),0) -> YA
A41: 46266 | B41: AGENT19 | C41: DC_PORONG | D41: SDA24 | E41: 2026-09-01 06.29.42_No.447, Jalan Bhayangkari.jpg,2026-09-01 06.29.45_No.447, Jalan Bhayangkari.mp4 | F41: SDA JAM 12 TARGET LEGULER KEDATANGAN | G41: other | H41: 46266.273 | I41: 50 | J41: 56 | K41: fandi rakhmad_SDA24 | M41: 46266.273 | N41: Masih | O41: 365 | W41: =_xlfn.XLOOKUP(D41,'All DP'!B:B,'All DP'!D:D,"Tidak") -> Masih | X41: =IFERROR(IF(MOD(H41,1)<=TIME(15,0,0),"YA","TIDAK"),0) -> YA
A42: 46266 | B42: AGENT21 | C42: NUSA_PENIDA | D42: KKL03 | E42: 1 September.mp4 | F42: Briefing pagi : Menyampaikan materi briefing sesuai ketentuan HQ yang dibagi menjadi 3 section. | G42: other | H42: 46266.275 | I42: 26 | J42: 27 | K42: I Dewa Made Dwipayana | M42: 46266.275 | N42: Masih | O42: 176 | W42: =_xlfn.XLOOKUP(D42,'All DP'!B:B,'All DP'!D:D,"Tidak") -> Masih | X42: =IFERROR(IF(MOD(H42,1)<=TIME(15,0,0),"YA","TIDAK"),0) -> YA
A43: 46266 | B43: AGENT40 | C43: CP_PULO_GADUNG | D43: JKT57G | E43: image.png | F43: brifing pagi cp pulo gadung absen 6.30 keluar gudang 7.30 ttd jam 12.00 dan all ritase longtail, paket stuck penanganan paket DG qr sprinter kejar dari awal bulan dan juga prospek pelanggan vip evaluasi pencapaian agustus | G43: Marketing | H43: 46266.276 | I43: 147 | J43: 155 | K43: Arman Suryadi | M43: 46266.276 | O43: 73 | W43: =_xlfn.XLOOKUP(D43,'All DP'!B:B,'All DP'!D:D,"Tidak") -> Masih | X43: =IFERROR(IF(MOD(H43,1)<=TIME(15,0,0),"YA","TIDAK"),0) -> YA
...

Sheet Display
D2: c
F4: ="网管 - 各代理早会上传状态 "&TEXT(AJ7,"yyyy-mm-dd")&" NM - Status Upload Briefing Pagi Agent "&TEXT(AJ7,"yyyy-mm-dd") -> 网管 - 各代理早会上传状态 2026-09-03 NM - Status Upload Briefing Pagi Agent 2026-09-03
F5: Sumber Data : 1. JMS > Monitoring Briefing > Karyawan 2. Feishu Base > Feedback Briefing Kerja Penarikan data = Tanggal 1 bulan berjalan - H-1 Penjelasan : 1. Total DP = Jumlah DP yang harus upload briefing pagi 2. Yang Sudah Upload Tepat Waktu = DP yang sudah upload dan submit form briefing pagi pada tanggal berjalan, dengan waktu upload 00:00–15:00. 3. Upload setelah pukul 15:00 = Tidak dihitung sebagai upload tepat waktu. 4. Persentase Upload Tepat Waktu = Jumlah DP yang upload tepat waktu ÷ Total DP. | Q5: 数据来源： 1. JMS > 班前例会监控报表 > 按员工统计 2. Feishu Base > 工作早会反馈 数据提取范围：当月1日至前一天（H-1） 说明： 1. 网点总数 = 需要上传早会的网点数量。 2. 及时上传 = 网点在当天完成早会上传及提交表单，上传时间为 00:00–15:00。 3. 15:00之后上传 = 不计入及时上传。 4. 及时上传率 = 及时上传网点数 ÷ 网点总数。
F6: 区域 Area | G6: 代理区 Agent | J6: 排名 Rank | K6: 目标 Target | L6: ="日度达成 "&TEXT(AJ7,"YYYY-MM-DD")&" Pencapaian Harian " -> 日度达成 2026-09-03 Pencapaian Harian | O6: 周度达成 Pencapaian Mingguan | AC6: 月度达成 Pencapaian Bulanan
O7: 网点总数 Total DP | P7: ="W1"&CHAR(10)&TEXT(AJ8,"DD MMM")&" - "&TEXT(AK8,"DD MMM") -> W1 01 Sep - 07 Sep | R7: ="W2"&CHAR(10)&TEXT(AK8+1,"DD MMM")&" - "&TEXT(AL8,"DD MMM") -> W2 08 Sep - 14 Sep | T7: ="W3"&CHAR(10)&TEXT(AL8+1,"DD MMM")&" - "&TEXT(AM8,"DD MMM") -> W3 15 Sep - 21 Sep | V7: ="W4"&CHAR(10)&TEXT(AM8+1,"DD MMM")&" - "&TEXT(AN8,"DD MMM") -> W4 22 Sep - 28 Sep | X7: w1 | Y7: w2 | Z7: w3 | AA7: w4 | AB7: 周度趋势线 Trendline Mingguan | AI7: update V | AJ7: =DATE(2026,9,AI8) -> 46268
L8: 网点总数 Total DP | M8: 已及时上传 Upload Tepat Waktu | N8: 上传及时率 Persentase Upload Tepat Waktu | P8: 已及时上传 Upload Tepat Waktu | Q8: 上传及时率 Persentase Upload Tepat Waktu | R8: 已及时上传 Upload Tepat Waktu | S8: 上传及时率 Persentase Upload Tepat Waktu | T8: 已及时上传 Upload Tepat Waktu | U8: 上传及时率 Persentase Upload Tepat Waktu | V8: 已上传 Yang Sudah Upload | W8: 上传及时率 Persentase Upload Tepat Waktu | AC8: 网点总数 Total DP | AD8: 已及时上传 Upload Tepat Waktu | AE8: 上传及时率 Persentase Upload Tepat Waktu | AH8: =AI8 -> 3 | AI8: 3 | AJ8: =EOMONTH(AJ7,-1)+1 -> 46266 | AK8: =AJ8+6 -> 46272 | AL8: =AK8+7 -> 46279 | AM8: =AL8+7 -> 46286 | AN8: =AM8+7 -> 46293 | AP8: =MIN(7,MAX(0,$AH$8)) -> 3 | AQ8: =MIN(7,MAX(0,$AH$8-7)) -> 0 | AR8: =MIN(7,MAX(0,$AH$8-14)) -> 0 | AS8: =MAX(0,$AH$8-21) -> 0
F9: 合计 Total | J9: - | K9: 0.9 | L9: =SUM(L10:L35) -> 2687 | M9: =SUM(M10:M35) -> 2508 | N9: =M9/L9 -> 0.93338295 | O9: =SUM(O10:O35) -> 18809 | P9: =SUM(P10:P35) -> 7437 | Q9: =IFERROR(P9/($L9*$AP$8),0) -> 0.92259025 | R9: =SUM(R10:R35) -> 0 | S9: =IFERROR(T9/($L9*$AR$8),0) -> 0 | T9: =SUM(T10:T35) -> 0 | U9: =IFERROR(T9/($L9*$AR$8),0) -> 0 | V9: =SUM(V10:V35) -> 0 | W9: =IFERROR(V9/($L9*$AS$8),0) -> 0 | X9: =Q9 -> 0.92259025 | AC9: =SUM(AC10:AC35) -> 8061 | AD9: =SUM(AD10:AD35) -> 7437 | AE9: =AD9/AC9 -> 0.92259025 | AK9: =AK8+1 -> 46273 | AL9: =AL8+1 -> 46280 | AM9: =AM8+1 -> 46287 | AN9: =AN8+1 -> 46294 | AP9: W1 | AQ9: W2 | AR9: W3 | AS9: W4
F10: =_xlfn.XLOOKUP(I10,[1]Lembar1!$A:$A,[1]Lembar1!$C:$C,0) -> Sumatra 苏门答腊岛 | G10: JAMBI占碑 | H10: a | I10: AGENT07 | J10: =_xlfn.RANK.AVG(AE10,$AE$10:$AE$19) -> 1 | K10: 0.9 | L10: =COUNTIFS('All DP'!A:A,I10,'All DP'!D:D,"<>"&"Tidak") -> 64 | M10: =COUNTIFS('Raw data yang sudah upload'!B:B,I10,'Raw data yang sudah upload'!A:A,$AJ$7,'Raw data yang sudah upload'!W:W,"Masih",'Raw data yang sudah upload'!X:X,"YA") -> 63 | N10: =M10/L10 -> 0.984375 | O10: =$L10*7 -> 448 | P10: =COUNTIFS('Raw data yang sudah upload'!$B:$B,$I10,'Raw data yang sudah upload'!$A:$A,">="&$AJ$8,'Raw data yang sudah upload'!$A:$A,"<="&$AK$8,'Raw data yang sudah upload'!W:W,"Masih",'Raw data yang sudah upload'!X:X,"YA") -> 191 | Q10: =IFERROR(P10/($L10*$AP$8),0) -> 0.99479167 | R10: =COUNTIFS('Raw data yang sudah upload'!$B:$B,$I10,'Raw data yang sudah upload'!$A:$A,">="&$AK$9,'Raw data yang sudah upload'!$A:$A,"<="&$AL$8,'Raw data yang sudah upload'!W:W,"Masih",'Raw data yang sudah upload'!X:X,"YA") -> 0 | S10: =IFERROR(R10/($L10*$AQ$8),0) -> 0 | T10: =COUNTIFS('Raw data yang sudah upload'!$B:$B,$I10,'Raw data yang sudah upload'!$A:$A,">="&$AL$9,'Raw data yang sudah upload'!$A:$A,"<="&$AM$8,'Raw data yang sudah upload'!W:W,"Masih",'Raw data yang sudah upload'!X:X,"YA") -> 0 | U10: =IFERROR(T10/($L10*$AR$8),0) -> 0 | V10: =COUNTIFS('Raw data yang sudah upload'!$B:$B,$I10,'Raw data yang sudah upload'!$A:$A,">="&$AM$9,'Raw data yang sudah upload'!$A:$A,"<="&$AN$8,'Raw data yang sudah upload'!W:W,"Masih",'Raw data yang sudah upload'!X:X,"YA") -> 0 | W10: =IFERROR(V10/($L10*$AS$8),0) -> 0 | X10: =Q10 -> 0.99479167 | AC10: =L10*$AH$8 -> 192 | AD10: =COUNTIFS('Raw data yang sudah upload'!B:B,I10,'Raw data yang sudah upload'!A:A,">="&$AJ$8,'Raw data yang sudah upload'!A:A,"<="&$AJ$7,'Raw data yang sudah upload'!W:W,"Masih",'Raw data yang sudah upload'!X:X,"YA") -> 191 | AE10: =AD10/AC10 -> 0.99479167
B11: 01-08 - 07-08 (W2) | G11: BENGKULU明古鲁 | H11: a | I11: AGENT09 | J11: =_xlfn.RANK.AVG(AE11,$AE$10:$AE$19) -> 2 | K11: 0.9 | L11: =COUNTIFS('All DP'!A:A,I11,'All DP'!D:D,"<>"&"Tidak") -> 41 | M11: =COUNTIFS('Raw data yang sudah upload'!B:B,I11,'Raw data yang sudah upload'!A:A,$AJ$7,'Raw data yang sudah upload'!W:W,"Masih",'Raw data yang sudah upload'!X:X,"YA") -> 40 | N11: =M11/L11 -> 0.97560976 | O11: =$L11*7 -> 287 | P11: =COUNTIFS('Raw data yang sudah upload'!$B:$B,$I11,'Raw data yang sudah upload'!$A:$A,">="&$AJ$8,'Raw data yang sudah upload'!$A:$A,"<="&$AK$8,'Raw data yang sudah upload'!W:W,"Masih",'Raw data yang sudah upload'!X:X,"YA") -> 120 | Q11: =IFERROR(P11/($L11*$AP$8),0) -> 0.97560976 | R11: =COUNTIFS('Raw data yang sudah upload'!$B:$B,$I11,'Raw data yang sudah upload'!$A:$A,">="&$AK$9,'Raw data yang sudah upload'!$A:$A,"<="&$AL$8,'Raw data yang sudah upload'!W:W,"Masih",'Raw data yang sudah upload'!X:X,"YA") -> 0 | S11: =IFERROR(R11/($L11*$AQ$8),0) -> 0 | T11: =COUNTIFS('Raw data yang sudah upload'!$B:$B,$I11,'Raw data yang sudah upload'!$A:$A,">="&$AL$9,'Raw data yang sudah upload'!$A:$A,"<="&$AM$8,'Raw data yang sudah upload'!W:W,"Masih",'Raw data yang sudah upload'!X:X,"YA") -> 0 | U11: =IFERROR(T11/($L11*$AR$8),0) -> 0 | V11: =COUNTIFS('Raw data yang sudah upload'!$B:$B,$I11,'Raw data yang sudah upload'!$A:$A,">="&$AM$9,'Raw data yang sudah upload'!$A:$A,"<="&$AN$8,'Raw data yang sudah upload'!W:W,"Masih",'Raw data yang sudah upload'!X:X,"YA") -> 0 | W11: =IFERROR(V11/($L11*$AS$8),0) -> 0 | X11: =Q11 -> 0.97560976 | AC11: =L11*$AH$8 -> 123 | AD11: =COUNTIFS('Raw data yang sudah upload'!B:B,I11,'Raw data yang sudah upload'!A:A,">="&$AJ$8,'Raw data yang sudah upload'!A:A,"<="&$AJ$7,'Raw data yang sudah upload'!W:W,"Masih",'Raw data yang sudah upload'!X:X,"YA") -> 120 | AE11: =AD11/AC11 -> 0.97560976
G12: PADANG巴东 | H12: a | I12: AGENT06 | J12: =_xlfn.RANK.AVG(AE12,$AE$10:$AE$19) -> 7 | K12: 0.9 | L12: =COUNTIFS('All DP'!A:A,I12,'All DP'!D:D,"<>"&"Tidak") -> 56 | M12: =COUNTIFS('Raw data yang sudah upload'!B:B,I12,'Raw data yang sudah upload'!A:A,$AJ$7,'Raw data yang sudah upload'!W:W,"Masih",'Raw data yang sudah upload'!X:X,"YA") -> 54 | N12: =M12/L12 -> 0.96428571 | O12: =$L12*7 -> 392 | P12: =COUNTIFS('Raw data yang sudah upload'!$B:$B,$I12,'Raw data yang sudah upload'!$A:$A,">="&$AJ$8,'Raw data yang sudah upload'!$A:$A,"<="&$AK$8,'Raw data yang sudah upload'!W:W,"Masih",'Raw data yang sudah upload'!X:X,"YA") -> 155 | Q12: =IFERROR(P12/($L12*$AP$8),0) -> 0.92261905 | R12: =COUNTIFS('Raw data yang sudah upload'!$B:$B,$I12,'Raw data yang sudah upload'!$A:$A,">="&$AK$9,'Raw data yang sudah upload'!$A:$A,"<="&$AL$8,'Raw data yang sudah upload'!W:W,"Masih",'Raw data yang sudah upload'!X:X,"YA") -> 0 | S12: =IFERROR(R12/($L12*$AQ$8),0) -> 0 | T12: =COUNTIFS('Raw data yang sudah upload'!$B:$B,$I12,'Raw data yang sudah upload'!$A:$A,">="&$AL$9,'Raw data yang sudah upload'!$A:$A,"<="&$AM$8,'Raw data yang sudah upload'!W:W,"Masih",'Raw data yang sudah upload'!X:X,"YA") -> 0 | U12: =IFERROR(T12/($L12*$AR$8),0) -> 0 | V12: =COUNTIFS('Raw data yang sudah upload'!$B:$B,$I12,'Raw data yang sudah upload'!$A:$A,">="&$AM$9,'Raw data yang sudah upload'!$A:$A,"<="&$AN$8,'Raw data yang sudah upload'!W:W,"Masih",'Raw data yang sudah upload'!X:X,"YA") -> 0 | W12: =IFERROR(V12/($L12*$AS$8),0) -> 0 | X12: =Q12 -> 0.92261905 | AC12: =L12*$AH$8 -> 168 | AD12: =COUNTIFS('Raw data yang sudah upload'!B:B,I12,'Raw data yang sudah upload'!A:A,">="&$AJ$8,'Raw data yang sudah upload'!A:A,"<="&$AJ$7,'Raw data yang sudah upload'!W:W,"Masih",'Raw data yang sudah upload'!X:X,"YA") -> 155 | AE12: =AD12/AC12 -> 0.92261905
G13: PEKANBARU北干巴鲁 | H13: a | I13: AGENT04 | J13: =_xlfn.RANK.AVG(AE13,$AE$10:$AE$19) -> 8 | K13: 0.9 | L13: =COUNTIFS('All DP'!A:A,I13,'All DP'!D:D,"<>"&"Tidak") -> 72 | M13: =COUNTIFS('Raw data yang sudah upload'!B:B,I13,'Raw data yang sudah upload'!A:A,$AJ$7,'Raw data yang sudah upload'!W:W,"Masih",'Raw data yang sudah upload'!X:X,"YA") -> 69 | N13: =M13/L13 -> 0.95833333 | O13: =$L13*7 -> 504 | P13: =COUNTIFS('Raw data yang sudah upload'!$B:$B,$I13,'Raw data yang sudah upload'!$A:$A,">="&$AJ$8,'Raw data yang sudah upload'!$A:$A,"<="&$AK$8,'Raw data yang sudah upload'!W:W,"Masih",'Raw data yang sudah upload'!X:X,"YA") -> 193 | Q13: =IFERROR(P13/($L13*$AP$8),0) -> 0.89351852 | R13: =COUNTIFS('Raw data yang sudah upload'!$B:$B,$I13,'Raw data yang sudah upload'!$A:$A,">="&$AK$9,'Raw data yang sudah upload'!$A:$A,"<="&$AL$8,'Raw data yang sudah upload'!W:W,"Masih",'Raw data yang sudah upload'!X:X,"YA") -> 0 | S13: =IFERROR(R13/($L13*$AQ$8),0) -> 0 | T13: =COUNTIFS('Raw data yang sudah upload'!$B:$B,$I13,'Raw data yang sudah upload'!$A:$A,">="&$AL$9,'Raw data yang sudah upload'!$A:$A,"<="&$AM$8,'Raw data yang sudah upload'!W:W,"Masih",'Raw data yang sudah upload'!X:X,"YA") -> 0 | U13: =IFERROR(T13/($L13*$AR$8),0) -> 0 | V13: =COUNTIFS('Raw data yang sudah upload'!$B:$B,$I13,'Raw data yang sudah upload'!$A:$A,">="&$AM$9,'Raw data yang sudah upload'!$A:$A,"<="&$AN$8,'Raw data yang sudah upload'!W:W,"Masih",'Raw data yang sudah upload'!X:X,"YA") -> 0 | W13: =IFERROR(V13/($L13*$AS$8),0) -> 0 | X13: =Q13 -> 0.89351852 | AC13: =L13*$AH$8 -> 216 | AD13: =COUNTIFS('Raw data yang sudah upload'!B:B,I13,'Raw data yang sudah upload'!A:A,">="&$AJ$8,'Raw data yang sudah upload'!A:A,"<="&$AJ$7,'Raw data yang sudah upload'!W:W,"Masih",'Raw data yang sudah upload'!X:X,"YA") -> 193 | AE13: =AD13/AC13 -> 0.89351852
G14: LAMPUNG班达楠榜 | H14: a | I14: AGENT10 | J14: =_xlfn.RANK.AVG(AE14,$AE$10:$AE$19) -> 3 | K14: 0.9 | L14: =COUNTIFS('All DP'!A:A,I14,'All DP'!D:D,"<>"&"Tidak") -> 68 | M14: =COUNTIFS('Raw data yang sudah upload'!B:B,I14,'Raw data yang sudah upload'!A:A,$AJ$7,'Raw data yang sudah upload'!W:W,"Masih",'Raw data yang sudah upload'!X:X,"YA") -> 65 | N14: =M14/L14 -> 0.95588235 | O14: =$L14*7 -> 476 | P14: =COUNTIFS('Raw data yang sudah upload'!$B:$B,$I14,'Raw data yang sudah upload'!$A:$A,">="&$AJ$8,'Raw data yang sudah upload'!$A:$A,"<="&$AK$8,'Raw data yang sudah upload'!W:W,"Masih",'Raw data yang sudah upload'!X:X,"YA") -> 196 | Q14: =IFERROR(P14/($L14*$AP$8),0) -> 0.96078431 | R14: =COUNTIFS('Raw data yang sudah upload'!$B:$B,$I14,'Raw data yang sudah upload'!$A:$A,">="&$AK$9,'Raw data yang sudah upload'!$A:$A,"<="&$AL$8,'Raw data yang sudah upload'!W:W,"Masih",'Raw data yang sudah upload'!X:X,"YA") -> 0 | S14: =IFERROR(R14/($L14*$AQ$8),0) -> 0 | T14: =COUNTIFS('Raw data yang sudah upload'!$B:$B,$I14,'Raw data yang sudah upload'!$A:$A,">="&$AL$9,'Raw data yang sudah upload'!$A:$A,"<="&$AM$8,'Raw data yang sudah upload'!W:W,"Masih",'Raw data yang sudah upload'!X:X,"YA") -> 0 | U14: =IFERROR(T14/($L14*$AR$8),0) -> 0 | V14: =COUNTIFS('Raw data yang sudah upload'!$B:$B,$I14,'Raw data yang sudah upload'!$A:$A,">="&$AM$9,'Raw data yang sudah upload'!$A:$A,"<="&$AN$8,'Raw data yang sudah upload'!W:W,"Masih",'Raw data yang sudah upload'!X:X,"YA") -> 0 | W14: =IFERROR(V14/($L14*$AS$8),0) -> 0 | X14: =Q14 -> 0.96078431 | AC14: =L14*$AH$8 -> 204 | AD14: =COUNTIFS('Raw data yang sudah upload'!B:B,I14,'Raw data yang sudah upload'!A:A,">="&$AJ$8,'Raw data yang sudah upload'!A:A,"<="&$AJ$7,'Raw data yang sudah upload'!W:W,"Masih",'Raw data yang sudah upload'!X:X,"YA") -> 196 | AE14: =AD14/AC14 -> 0.96078431 | AJ14: =MIN(7,MAX(0,$AH$8)) -> 3
