Workbook

Sheet ALL DP DATA
B1: ="网管-雅加达网点质量达成 "&TEXT(BA2,"YYYY-MM-DD")&" "&"NM - Pencapaian Kualitas DropPoint Jakarta "&TEXT(BA2,"YYYY-MM-DD") -> 网管-雅加达网点质量达成 2026-09-23 NM - Pencapaian Kualitas DropPoint Jakarta 2026-09-23 | BA1: Date
BA2: ='06.30, 07.30, & 12.00'!F4 -> 46288 | BB2: =EOMONTH(BA2,-1)+1 -> 46266 | BC2: report kualitas agent | BF2: =COUNTIFS('[10]Raw Abnsensi'!P:P,I:I,'[10]Raw Abnsensi'!Q:Q,1,'[10]Raw Abnsensi'!O:O,"<="&#REF!) -> 0 | BG2: =COUNTIFS('[10]Raw Abnsensi'!P:P,I:I,'[10]Raw Abnsensi'!Q:Q,1) -> 0 | BH2: =BF2/BG2 -> #DIV/0!
BA3: =BA2-2 -> 46286 | BB3: =EOMONTH(BA3,-1)+1 -> 46266 | BC3: report ramadan
C4: 定义: 一派质量考核项 1. 快递员出勤准点率 = 当天当地时间06:30前打卡且当日有签收的快递员人数/ 当天已打卡且有签收的快递员人数 2. 0730出仓率 = 0730前出仓量/ 一班应签收量 3. 1200签收率 = 1200前签收量/ 一班应签收量 4. 一班：散货数量,按照散货班次第一班 目标：90% 质量达成 1. 交件准点率: 准点交件票数 / 应交件票数*100% 目标: 93% 2. 全天签收率 = 按规划时效网点当天签收票数/应签收票数 目标：A92%，B90%，C90% 非平台质量 1. 非平台揽收及时率 = (实际揽收及时量 + 揽收失败及时量)/ 订单量 目标：98% 2. 非平台COD退件率 = (退件登记票数 - 退件作废票数) / 派件量 | U4: Penjelasan: Penilaian Kualitas Delivery Ritase Pertama 1. Tingkat Ketepatan Waktu Kehadiran Spirnter = Jumlah sprinter yang melakukan absen sebelum 06.30 waktu setempat dan melakukan TTD/ jumlah sprinter yang melakukan absen dan melakukan TTD 2. Persentase Deliv 7.30 = Total delivery sebelum jam 7.30/ Total Seharusnya TTD Rit 1 3. Persentase TTD 12.00 = Total TTD sebelum jam 1200/ Total seharusnya TTD Rit 1 4. Ritase Pertama: Jumlah penyebaran paket massal kargo Rit 1 Target : 90% Pencapaian Kualitas 1. TPTW = Total kirim tepat waktu / Total seharusnya kirim Target: 93% 2. Persentase TTD = Jumlah TTD Hari H/Jumlah Seharusnya TTD Target: A92%, B90%, C90% Kualitas Non Platform 1. % Pickup Non-ecommerce = (On Time Pick Up + On Time Gagal Pick Up) / Total Order Target : 98% 2. % Retur COD Non-Ecommerce = (Jumlah regis retur - jumlah batal retur)/ jumlah delivery
C6: 代理区 Agent | D6: Fungsi DP | E6: 代理区编码 Kode Agent | F6: 网点 Nama Drop point | G6: Nama agent | I6: 代理区编码 Kode Agent | J6: 一派质量达成 Penilaian Kualitas Delivery Ritase Pertama | Y6: 二派质量达成 Penilaian Kualitas Delivery Ritase Kedua | AD6: 全天收派质量达成 Pencapaian Kualitas Operasional Harian
J7: 快递员出勤准点率 Tingkat Ketepatan Waktu Kehadiran Spirnter | O7: 0730出仓率 Persenase Keluar Gudang 0730 | T7: 1200签收率 Persentase TTD 1200 | Y7: 二派签收率 Persentase TTD Delivery Kedua | AD7: 交件准点率 TPTW | AI7: 全天签收率 Persentase TTD | AN7: 非平台揽收及时率 % Pickup Non- Ecommerce | AS7: 非平台COD退件率 % Retur COD Non-Ecommerce | BA7: =BA2-1 -> 46287
J8: Target | K8: 46288 | L8: =BA7 -> 46287 | M8: =BA3 -> 46286 | N8: 月度达成 Pencapaian Bulanan | O8: Target | P8: =$BA$2 -> 46288 | Q8: =BA7 -> 46287 | R8: =BA3 -> 46286 | S8: 月度达成 Pencapaian Bulanan | T8: Target | U8: =$BA$2 -> 46288 | V8: =BA7 -> 46287 | W8: =BA3 -> 46286 | X8: 月度达成 Pencapaian Bulanan | Y8: Target | Z8: =$BA$2 -> 46288 | AA8: =BA7 -> 46287 | AB8: =BA3 -> 46286 | AC8: 月度达成 Pencapaian Bulanan | AD8: Target | AE8: =$BA$2 -> 46288 | AF8: =BA7 -> 46287 | AG8: =BA3 -> 46286 | AH8: 月度达成 Pencapaian Bulanan | AI8: Target | AJ8: =$BA$2 -> 46288 | AK8: =BA7 -> 46287 | AL8: =BA3 -> 46286 | AM8: 月度达成 Pencapaian Bulanan | AN8: Target | AO8: =$BA$2 -> 46288 | AP8: =BA7 -> 46287 | AQ8: =BA3 -> 46286 | AR8: 月度达成 Pencapaian Bulanan | AS8: 目标 Target | AT8: =$BA$2 -> 46288 | AU8: =BA7 -> 46287 | AV8: =BA3 -> 46286 | AW8: 月度达成 Pencapaian Bulanan
C9: JAKARTA雅加达 | D9: Pickup Delivery | E9: AGENT40 | F9: CP_PLUIT_PERMAI | G9: CP_PLUIT_PERMAI | H9: CP_PLUIT_PERMAI | I9: CP_PLUIT_PERMAI | J9: 0.9 | K9: 0.92424242 | L9: 0.83076923 | M9: 0.98113208 | N9: 0.90545455 | O9: 0.9 | P9: 0.93410752 | Q9: 0.95202602 | R9: 0.99277485 | S9: 0.94921213 | T9: 0.9 | U9: 0.78131524 | V9: 0.8165063 | W9: 0.84475688 | X9: 0.73188334 | Y9: 0.92 | Z9: 0.94675249 | AA9: 0.93269977 | AB9: 0.95739242 | AC9: 0.92021914 | AD9: 0.92 | AE9: 0.99590829 | AF9: 0.98400657 | AG9: 0.94816026 | AH9: 0.96078385 | AI9: 0.92 | AJ9: 0.95661012 | AK9: 0.95102887 | AL9: 0.96319593 | AM9: 0.93854595 | AN9: 0.99 | AO9: 1 | AP9: 1 | AQ9: 1 | AR9: 1 | AS9: 0.08721821 | AT9: 0.033333333 | AU9: 0.068181818 | AV9: 0.096774194 | AW9: 0.052564103
C10: JAKARTA雅加达 | D10: Pickup Delivery | E10: AGENT40 | F10: CP_DANAUSUNTER_UTARA | G10: CP_DANAUSUNTER_UTARA | H10: CP_DANAUSUNTER_UTARA | I10: CP_DANAUSUNTER_UTARA | J10: 0.9 | K10: 0.92622951 | L10: 0.93442623 | M10: 0.84848485 | N10: 0.87910842 | O10: 0.9 | P10: 0.96811316 | Q10: 0.98247044 | R10: 0.96653472 | S10: 0.98540779 | T10: 0.9 | U10: 0.81982738 | V10: 0.88952303 | W10: 0.82367758 | X10: 0.80042759 | Y10: 0.92 | Z10: 0.94382583 | AA10: 0.96983464 | AB10: 0.96629213 | AC10: 0.96142044 | AD10: 0.92 | AE10: 0.99829932 | AF10: 0.98959049 | AG10: 0.99553877 | AH10: 0.99297429 | AI10: 0.92 | AJ10: 0.95041783 | AK10: 0.97465599 | AL10: 0.97027348 | AM10: 0.96996905 | AN10: 0.99 | AO10: 1 | AP10: 1 | AQ10: 1 | AR10: 1 | AS10: 0.08721821 | AT10: 0.082191781 | AU10: 0.033707865 | AV10: 0.069444444 | AW10: 0.058858152
C11: JAKARTA雅加达 | D11: Pickup Delivery | E11: AGENT40 | F11: KAMAL_MUARA | G11: KAMAL_MUARA | H11: KAMAL_MUARA | I11: KAMAL_MUARA | J11: 0.9 | K11: 0.93333333 | L11: 1 | M11: 0.92592593 | N11: 0.93161094 | O11: 0.9 | P11: 0.99531773 | Q11: 0.99472097 | R11: 0.98459043 | S11: 0.93744423 | T11: 0.9 | U11: 0.86555184 | V11: 0.87631976 | W11: 0.83049473 | X11: 0.88741236 | Y11: 0.92 | Z11: 0.94259259 | AA11: 0.94259116 | AB11: 0.9391771 | AC11: 0.95048448 | AD11: 0.92 | AE11: 0.99039201 | AF11: 0.99487904 | AG11: 0.92824727 | AH11: 0.94384375 | AI11: 0.92 | AJ11: 0.94759317 | AK11: 0.95487572 | AL11: 0.95535714 | AM11: 0.96456061 | AN11: 0.99 | AO11: 1 | AP11: 1 | AQ11: 1 | AR11: 1 | AS11: 0.08721821 | AT11: 0 | AU11: 0 | AV11: 0 | AW11: 0.027888446
C12: JAKARTA雅加达 | D12: Pickup Delivery | E12: AGENT40 | F12: TELUK_GONG | G12: TELUK_GONG | H12: TELUK_GONG | I12: TELUK_GONG | J12: 0.9 | K12: 0.90909091 | L12: 0.94782609 | M12: 0.96907216 | N12: 0.92098197 | O12: 0.9 | P12: 0.88403909 | Q12: 0.95120928 | R12: 0.84336678 | S12: 0.91364197 | T12: 0.9 | U12: 0.82084691 | V12: 0.86607018 | W12: 0.83036046 | X12: 0.82505947 | Y12: 0.92 | Z12: 0.93807881 | AA12: 0.98320925 | AB12: 0.93460009 | AC12: 0.97310476 | AD12: 0.92 | AE12: 0.95677656 | AF12: 0.98510882 | AG12: 0.8552556 | AH12: 0.9292313 | AI12: 0.92 | AJ12: 0.942028 | AK12: 0.984925 | AL12: 0.95788097 | AM12: 0.97807776 | AN12: 0.99 | AO12: 1 | AP12: 1 | AQ12: 1 | AR12: 1 | AS12: 0.08721821 | AT12: 0.050847458 | AU12: 0.13207547 | AV12: 0.14893617 | AW12: 0.073170732
C13: JAKARTA雅加达 | D13: Pickup Delivery | E13: AGENT40 | F13: CP_TELUK_GONG_RAYA | G13: CP_TELUK_GONG_RAYA | H13: CP_TELUK_GONG_RAYA | I13: CP_TELUK_GONG_RAYA | J13: 0.9 | K13: 0.94230769 | L13: 0.94117647 | M13: 0.95555556 | N13: 0.88833333 | O13: 0.9 | P13: 0.97674419 | Q13: 0.98520436 | R13: 0.88888889 | S13: 0.96187703 | T13: 0.9 | U13: 0.9253167 | V13: 0.9410024 | W13: 0.92852371 | X13: 0.93818404 | Y13: 0.92 | Z13: 0.95964487 | AA13: 0.97040537 | AB13: 0.95680864 | AC13: 0.95904655 | AD13: 0.92 | AE13: 0.98178849 | AF13: 0.97372919 | AG13: 0.97650757 | AH13: 0.9683292 | AI13: 0.92 | AJ13: 0.96968688 | AK13: 0.97857673 | AL13: 0.97288081 | AM13: 0.97433506 | AN13: 0.99 | AO13: 1 | AP13: 1 | AQ13: 1 | AR13: 1 | AS13: 0.08721821 | AT13: 0.074074074 | AU13: 0.03030303 | AV13: 0 | AW13: 0.0464
C14: JAKARTA雅加达 | D14: Pickup Delivery | E14: AGENT40 | F14: CP_PADEMANGAN_4 | G14: CP_PADEMANGAN_4 | H14: CP_PADEMANGAN_4 | I14: CP_PADEMANGAN_4 | J14: 0.9 | K14: - | L14: - | M14: - | N14: - | O14: 0.9 | P14: - | Q14: - | R14: - | S14: 0.125 | T14: 0.9 | U14: - | V14: - | W14: - | X14: 0.96428571 | Y14: 0.92 | Z14: - | AA14: - | AB14: - | AC14: 1 | AD14: 0.92 | AE14: - | AF14: - | AG14: - | AH14: 0.99639617 | AI14: 0.92 | AJ14: - | AK14: - | AL14: 1 | AM14: 0.97222222 | AN14: 0.99 | AO14: - | AP14: - | AQ14: - | AR14: 1 | AS14: 0.08721821 | AT14: - | AU14: - | AV14: - | AW14: -
C15: JAKARTA雅加达 | D15: Pickup Delivery | E15: AGENT40 | F15: CP_ANCOL_SELATAN_1 | G15: CP_ANCOL_SELATAN_1 | H15: CP_ANCOL_SELATAN_1 | I15: CP_ANCOL_SELATAN_1 | J15: 0.9 | K15: 0.97674419 | L15: 1 | M15: 0.98230088 | N15: 0.98857143 | O15: 0.9 | P15: 0.9900879 | Q15: 0.99287024 | R15: 0.99223164 | S15: 0.9820134 | T15: 0.9 | U15: 0.91228726 | V15: 0.91882257 | W15: 0.92683616 | X15: 0.91994037 | Y15: 0.92 | Z15: 0.95785861 | AA15: 0.95816161 | AB15: 0.96641131 | AC15: 0.96758705 | AD15: 0.92 | AE15: 0.99876874 | AF15: 0.99689574 | AG15: 0.99286673 | AH15: 0.99341032 | AI15: 0.92 | AJ15: 0.96829987 | AK15: 0.97122827 | AL15: 0.97794749 | AM15: 0.97846079 | AN15: 0.99 | AO15: 1 | AP15: 1 | AQ15: 1 | AR15: 1 | AS15: 0.08721821 | AT15: 0.02955665 | AU15: 0.027210884 | AV15: 0.03875969 | AW15: 0.031204854
C16: JAKARTA雅加达 | D16: Pickup Delivery | E16: AGENT40 | F16: KEPULAUAN_SERIBU | G16: KEPULAUAN_SERIBU | H16: KEPULAUAN_SERIBU | I16: KEPULAUAN_SERIBU | J16: 0.9 | K16: 0.96774194 | L16: 1 | M16: 1 | N16: 0.96091205 | O16: 0.9 | P16: 0.99951503 | Q16: 0.99929972 | R16: 0.99927405 | S16: 0.95204887 | T16: 0.9 | U16: 0.98884578 | V16: 0.99054622 | W16: 0.98983666 | X16: 0.95135434 | Y16: 0.92 | Z16: - | AA16: - | AB16: - | AC16: 0 | AD16: 0.92 | AE16: 0.77777778 | AF16: 0.75 | AG16: 0 | AH16: 0.52791878 | AI16: 0.92 | AJ16: 0.99224054 | AK16: 0.99684874 | AL16: 0.99600726 | AM16: 0.9942172 | AN16: 0.99 | AO16: 1 | AP16: 1 | AQ16: 1 | AR16: 1 | AS16: 0.08721821 | AT16: 0 | AU16: 0.16666667 | AV16: 0.066666667 | AW16: 0.06504065
C17: JAKARTA雅加达 | D17: Pickup Delivery | E17: AGENT40 | F17: TANAH_ABANG | G17: TANAH_ABANG | H17: TANAH_ABANG | I17: TANAH_ABANG | J17: 0.9 | K17: 0.93939394 | L17: 0.95049505 | M17: 0.89411765 | N17: 0.88490214 | O17: 0.9 | P17: 0.99354257 | Q17: 0.99566929 | R17: 0.99654079 | S17: 0.99423061 | T17: 0.9 | U17: 0.74290434 | V17: 0.7726378 | W17: 0.72643413 | X17: 0.72306913 | Y17: 0.92 | Z17: 0.8966651 | AA17: 0.88411753 | AB17: 0.89467238 | AC17: 0.87895285 | AD17: 0.92 | AE17: 0.99334357 | AF17: 0.99740035 | AG17: 0.99665459 | AH17: 0.98431476 | AI17: 0.92 | AJ17: 0.90928251 | AK17: 0.91112898 | AL17: 0.92375539 | AM17: 0.90242405 | AN17: 0.99 | AO17: 1 | AP17: 1 | AQ17: 1 | AR17: 1 | AS17: 0.08721821 | AT17: 0.026666667 | AU17: 0.051282051 | AV17: 0.029850746 | AW17: 0.047067901
C18: JAKARTA雅加达 | D18: Pickup Delivery | E18: AGENT40 | F18: SENEN | G18: SENEN | H18: SENEN | I18: SENEN | J18: 0.9 | K18: 0.96694215 | L18: 0.99186992 | M18: 0.99090909 | N18: 0.98224195 | O18: 0.9 | P18: 0.99232883 | Q18: 0.98442979 | R18: 0.9965358 | S18: 0.9923751 | T18: 0.9 | U18: 0.87634532 | V18: 0.90110815 | W18: 0.87690531 | X18: 0.8873132 | Y18: 0.92 | Z18: 0.92819919 | AA18: 0.94320798 | AB18: 0.92096386 | AC18: 0.93562211 | AD18: 0.92 | AE18: 0.98431373 | AF18: 0.99263894 | AG18: 0.98 | AH18: 0.97885164 | AI18: 0.92 | AJ18: 0.94895758 | AK18: 0.95727686 | AL18: 0.94832162 | AM18: 0.95378303 | AN18: 0.99 | AO18: 1 | AP18: 1 | AQ18: 1 | AR18: 1 | AS18: 0.08721821 | AT18: 0.024390244 | AU18: 0.088888889 | AV18: 0.08974359 | AW18: 0.062371134
C19: JAKARTA雅加达 | D19: Pickup Delivery | E19: AGENT40 | F19: CP_PINANGSIA_RAYA | G19: CP_PINANGSIA_RAYA | H19: CP_PINANGSIA_RAYA | I19: CP_PINANGSIA_RAYA | J19: 0.9 | K19: 0.82352941 | L19: 0.77777778 | M19: 0.94117647 | N19: 0.8062954 | O19: 0.9 | P19: 0.98984772 | Q19: 0.98318318 | R19: 0.97513812 | S19: 0.88711148 | T19: 0.9 | U19: 0.68758653 | V19: 0.83243243 | W19: 0.63259669 | X19: 0.64048212 | Y19: 0.92 | Z19: 0.80130293 | AA19: 0.8717765 | AB19: 0.88649706 | AC19: 0.8111236 | AD19: 0.92 | AE19: 0.99786849 | AF19: 0.99606054 | AG19: 0.99359085 | AH19: 0.99423485 | AI19: 0.92 | AJ19: 0.87485277 | AK19: 0.91865403 | AL19: 0.9298685 | AM19: 0.85770933 | AN19: 0.99 | AO19: 1 | AP19: 1 | AQ19: 1 | AR19: 1 | AS19: 0.08721821 | AT19: 0 | AU19: 0 | AV19: 0 | AW19: 0.064705882
C20: JAKARTA雅加达 | D20: Pickup Delivery | E20: AGENT40 | F20: JOHAR_BARU_01 | G20: JOHAR_BARU_01 | H20: JOHAR_BARU_01 | I20: JOHAR_BARU_01 | J20: 0.9 | K20: 0.90909091 | L20: 0.94214876 | M20: 0.96581197 | N20: 0.93839031 | O20: 0.9 | P20: 0.99536889 | Q20: 0.9933916 | R20: 0.99740035 | S20: 0.99357817 | T20: 0.9 | U20: 0.86649633 | V20: 0.87507994 | W20: 0.86424032 | X20: 0.8733851 | Y20: 0.92 | Z20: 0.93645251 | AA20: 0.9354699 | AB20: 0.96459166 | AC20: 0.94715225 | AD20: 0.92 | AE20: 0.9897541 | AF20: 0.93696145 | AG20: 0.93188854 | AH20: 0.97890625 | AI20: 0.92 | AJ20: 0.95140205 | AK20: 0.95037061 | AL20: 0.96623825 | AM20: 0.96321995 | AN20: 0.99 | AO20: 1 | AP20: 1 | AQ20: 1 | AR20: 1 | AS20: 0.08721821 | AT20: 0.04 | AU20: 0.083333333 | AV20: 0.11111111 | AW20: 0.067936508
C21: JAKARTA雅加达 | D21: Pickup Delivery | E21: AGENT40 | F21: CP_ZAINUL_ARIFIN | G21: CP_ZAINUL_ARIFIN | H21: CP_ZAINUL_ARIFIN | I21: CP_ZAINUL_ARIFIN | J21: 0.9 | K21: 0.94117647 | L21: 0.9375 | M21: 0.86666667 | N21: 0.92368421 | O21: 0.9 | P21: 0.98912481 | Q21: 0.98351893 | R21: 0.98442368 | S21: 0.97867512 | T21: 0.9 | U21: 0.89124806 | V21: 0.91135857 | W21: 0.87601246 | X21: 0.8578615 | Y21: 0.92 | Z21: 0.95732839 | AA21: 0.9143898 | AB21: 0.97163121 | AC21: 0.9171443 | AD21: 0.92 | AE21: 0.99270219 | AF21: 0.98702787 | AG21: 0.9548751 | AH21: 0.98779018 | AI21: 0.92 | AJ21: 0.97406915 | AK21: 0.95692492 | AL21: 0.98202765 | AM21: 0.95361222 | AN21: 0.99 | AO21: 1 | AP21: 1 | AQ21: 1 | AR21: 1 | AS21: 0.08721821 | AT21: 0.28571429 | AU21: 0.11111111 | AV21: 0.33333333 | AW21: 0.10714286
C22: JAKARTA雅加达 | D22: Pickup Delivery | E22: AGENT40 | F22: CP_MANGGA_BESAR_2 | G22: CP_MANGGA_BESAR_2 | H22: CP_MANGGA_BESAR_2 | I22: CP_MANGGA_BESAR_2 | J22: 0.9 | K22: 0.91111111 | L22: 0.88888889 | M22: 0.93023256 | N22: 0.90576923 | O22: 0.9 | P22: 0.98052081 | Q22: 0.87150259 | R22: 0.84868249 | S22: 0.91466735 | T22: 0.9 | U22: 0.90670494 | V22: 0.9253886 | W22: 0.92016697 | X22: 0.89318072 | Y22: 0.92 | Z22: 0.94169096 | AA22: 0.96193497 | AB22: 0.97201018 | AC22: 0.961468 | AD22: 0.92 | AE22: 0.99571198 | AF22: 0.98270002 | AG22: 0.97805451 | AH22: 0.98849734 | AI22: 0.92 | AJ22: 0.956909 | AK22: 0.97432621 | AL22: 0.98427673 | AM22: 0.97553506 | AN22: 0.99 | AO22: 1 | AP22: 1 | AQ22: 1 | AR22: 1 | AS22: 0.08721821 | AT22: 0.090909091 | AU22: 0.038461538 | AV22: 0.2173913 | AW22: 0.11036036
C23: JAKARTA雅加达 | D23: Pickup Delivery | E23: AGENT40 | F23: CP_CEGER | G23: CP_CEGER | H23: CP_CEGER | I23: CP_CEGER | J23: 0.9 | K23: 0.91025641 | L23: 0.89171975 | M23: 0.83760684 | N23: 0.88892252 | O23: 0.9 | P23: 0.79209142 | Q23: 0.87173218 | R23: 0.69431997 | S23: 0.83118624 | T23: 0.9 | U23: 0.69952318 | V23: 0.76631559 | W23: 0.55334867 | X23: 0.66682709 | Y23: 0.92 | Z23: 0.93426847 | AA23: 0.97147016 | AB23: 0.97141081 | AC23: 0.95459178 | AD23: 0.92 | AE23: 0.99073814 | AF23: 0.88910615 | AG23: 0.60989011 | AH23: 0.76035508 | AI23: 0.92 | AJ23: 0.94528859 | AK23: 0.97360603 | AL23: 0.97537495 | AM23: 0.9654318 | AN23: 0.99 | AO23: 1 | AP23: 1 | AQ23: 1 | AR23: 1 | AS23: 0.08721821 | AT23: 0.083333333 | AU23: 0.11009174 | AV23: 0.092105263 | AW23: 0.060373216
C24: JAKARTA雅加达 | D24: Pickup Delivery | E24: AGENT40 | F24: KAMPUNG_TENGAH | G24: KAMPUNG_TENGAH | H24: KAMPUNG_TENGAH | I24: KAMPUNG_TENGAH | J24: 0.9 | K24: 0.89655172 | L24: 0.91034483 | M24: 0.89830508 | N24: 0.88980464 | O24: 0.9 | P24: 0.97742284 | Q24: 0.98377384 | R24: 0.96802885 | S24: 0.97194203 | T24: 0.9 | U24: 0.6890837 | V24: 0.743727 | W24: 0.69831731 | X24: 0.69395992 | Y24: 0.92 | Z24: 0.84397304 | AA24: 0.88049991 | AB24: 0.86593297 | AC24: 0.8918048 | AD24: 0.92 | AE24: 0.90990991 | AF24: 0.99885649 | AG24: 0.96875 | AH24: 0.93989665 | AI24: 0.92 | AJ24: 0.88326354 | AK24: 0.91219017 | AL24: 0.90339341 | AM24: 0.92282311 | AN24: 0.99 | AO24: 1 | AP24: 1 | AQ24: 1 | AR24: 1 | AS24: 0.08721821 | AT24: 0.096153846 | AU24: 0.14942529 | AV24: 0.11320755 | AW24: 0.06984127
C25: JAKARTA雅加达 | D25: Pickup Delivery | E25: AGENT40 | F25: CP_CIJANTUNG | G25: CP_CIJANTUNG | H25: CP_CIJANTUNG | I25: CP_CIJANTUNG | J25: 0.9 | K25: 0.95535714 | L25: 0.95327103 | M25: 0.93975904 | N25: 0.94112516 | O25: 0.9 | P25: 0.99169727 | Q25: 0.9860831 | R25: 0.99196095 | S25: 0.98270384 | T25: 0.9 | U25: 0.82692001 | V25: 0.85780557 | W25: 0.8630491 | X25: 0.81370802 | Y25: 0.92 | Z25: 0.92160706 | AA25: 0.91079713 | AB25: 0.90606061 | AC25: 0.92198472 | AD25: 0.92 | AE25: 0.99934182 | AF25: 0.99493002 | AG25: 0.99818367 | AH25: 0.98947127 | AI25: 0.92 | AJ25: 0.93433269 | AK25: 0.92938144 | AL25: 0.93726865 | AM25: 0.94481608 | AN25: 0.99 | AO25: 1 | AP25: 1 | AQ25: 1 | AR25: 1 | AS25: 0.08721821 | AT25: 0.0625 | AU25: 0.047169811 | AV25: 0.040540541 | AW25: 0.048004315
C26: JAKARTA雅加达 | D26: Pickup Delivery | E26: AGENT40 | F26: DC_MAKASAR | G26: DC_MAKASAR | H26: DC_MAKASAR | I26: DC_MAKASAR | J26: 0.9 | K26: 0.92792793 | L26: 0.93396226 | M26: 0.94444444 | N26: 0.93178947 | O26: 0.9 | P26: 0.99297495 | Q26: 0.99423148 | R26: 0.92830995 | S26: 0.88306956 | T26: 0.9 | U26: 0.7159438 | V26: 0.73855601 | W26: 0.71690055 | X26: 0.70475258 | Y26: 0.92 | Z26: 0.922505 | AA26: 0.90595675 | AB26: 0.87412141 | AC26: 0.91519778 | AD26: 0.92 | AE26: 0.99831579 | AF26: 0.99858824 | AG26: 0.99757804 | AH26: 0.99728191 | AI26: 0.92 | AJ26: 0.92872444 | AK26: 0.92759829 | AL26: 0.92217176 | AM26: 0.93883172 | AN26: 0.99 | AO26: 1 | AP26: 1 | AQ26: 1 | AR26: 1 | AS26: 0.08721821 | AT26: 0.054054054 | AU26: 0.050505051 | AV26: 0.066666667 | AW26: 0.040465632
C27: JAKARTA雅加达 | D27: Pickup Delivery | E27: AGENT40 | F27: DC_CIRACAS | G27: DC_CIRACAS | H27: DC_CIRACAS | I27: DC_CIRACAS | J27: 0.9 | K27: 0.96116505 | L27: 0.91262136 | M27: 0.95 | N27: 0.9503834 | O27: 0.9 | P27: 0.97050531 | Q27: 0.97083333 | R27: 0.96315171 | S27: 0.94288315 | T27: 0.9 | U27: 0.88418998 | V27: 0.88805556 | W27: 0.85339083 | X27: 0.88498906 | Y27: 0.92 | Z27: 0.93360223 | AA27: 0.94250132 | AB27: 0.92282697 | AC27: 0.94698223 | AD27: 0.92 | AE27: 0.63636364 | AF27: 0.71428571 | AG27: 0.81818182 | AH27: 0.8 | AI27: 0.92 | AJ27: 0.9557059 | AK27: 0.95729393 | AL27: 0.95480973 | AM27: 0.9661947 | AN27: 0.99 | AO27: 1 | AP27: 1 | AQ27: 1 | AR27: 1 | AS27: 0.08721821 | AT27: 0.18181818 | AU27: 0.15625 | AV27: 0.078431373 | AW27: 0.068507157
C28: JAKARTA雅加达 | D28: Pickup Delivery | E28: AGENT40 | F28: CP_RAYA_KELAPA | G28: CP_RAYA_KELAPA | H28: CP_RAYA_KELAPA | I28: CP_RAYA_KELAPA | J28: 0.9 | K28: 0.98214286 | L28: 0.92727273 | M28: 1 | N28: 0.98148148 | O28: 0.9 | P28: 0.98346056 | Q28: 0.79710145 | R28: 0.9885664 | S28: 0.94959789 | T28: 0.9 | U28: 0.88517812 | V28: 0.91181005 | W28: 0.87598945 | X28: 0.89827069 | Y28: 0.92 | Z28: 0.94021485 | AA28: 0.95805566 | AB28: 0.95130238 | AC28: 0.96102302 | AD28: 0.92 | AE28: 0.99825 | AF28: 0.99796866 | AG28: 0.95523371 | AH28: 0.99351018 | AI28: 0.92 | AJ28: 0.95666982 | AK28: 0.96842105 | AL28: 0.95891089 | AM28: 0.97267958 | AN28: 0.99 | AO28: 1 | AP28: 1 | AQ28: 1 | AR28: 1 | AS28: 0.08721821 | AT28: 0.041666667 | AU28: 0.15217391 | AV28: 0.17241379 | AW28: 0.071261682
C29: JAKARTA雅加达 | D29: Pickup Delivery | E29: AGENT40 | F29: CP_PONDOK_BAMBU | G29: CP_PONDOK_BAMBU | H29: CP_PONDOK_BAMBU | I29: CP_PONDOK_BAMBU | J29: 0.9 | K29: 0.84615385 | L29: 0.90909091 | M29: 0.90740741 | N29: 0.92008197 | O29: 0.9 | P29: 0.97858805 | Q29: 0.9675507 | R29: 0.96270018 | S29: 0.96329022 | T29: 0.9 | U29: 0.89371606 | V29: 0.94399376 | W29: 0.9333063 | X29: 0.9062252 | Y29: 0.92 | Z29: 0.96634001 | AA29: 0.97586957 | AB29: 0.98104485 | AC29: 0.97626637 | AD29: 0.92 | AE29: 0.99733575 | AF29: 0.92455275 | AG29: 0.93585986 | AH29: 0.96329382 | AI29: 0.92 | AJ29: 0.97289535 | AK29: 0.98546908 | AL29: 0.9873168 | AM29: 0.98300886 | AN29: 0.99 | AO29: 1 | AP29: 1 | AQ29: 1 | AR29: 1 | AS29: 0.08721821 | AT29: 0.060150376 | AU29: 0.058823529 | AV29: 0.033783784 | AW29: 0.020739165
C30: JAKARTA雅加达 | D30: Pickup Delivery | E30: AGENT40 | F30: DC_JATINEGARA | G30: DC_JATINEGARA | H30: DC_JATINEGARA | I30: DC_JATINEGARA | J30: 0.9 | K30: 0.92647059 | L30: 0.890625 | M30: 0.8852459 | N30: 0.90682415 | O30: 0.9 | P30: 0.93793295 | Q30: 0.93209238 | R30: 0.96934461 | S30: 0.96499888 | T30: 0.9 | U30: 0.81019673 | V30: 0.84453637 | W30: 0.82980973 | X30: 0.83010175 | Y30: 0.92 | Z30: 0.92131148 | AA30: 0.94173 | AB30: 0.92005242 | AC30: 0.93631883 | AD30: 0.92 | AE30: - | AF30: 1 | AG30: 0.5 | AH30: 0.53333333 | AI30: 0.92 | AJ30: 0.94169857 | AK30: 0.95110327 | AL30: 0.95065913 | AM30: 0.95465175 | AN30: 0.99 | AO30: - | AP30: 1 | AQ30: 1 | AR30: 1 | AS30: 0.08721821 | AT30: 0.12820513 | AU30: 0.16071429 | AV30: 0.13888889 | AW30: 0.061978546
C31: JAKARTA雅加达 | D31: Pickup Delivery | E31: AGENT40 | F31: SETIABUDI | G31: SETIABUDI | H31: SETIABUDI | I31: SETIABUDI | J31: 0.9 | K31: 0.98913043 | L31: 0.96703297 | M31: 0.9375 | N31: 0.97087379 | O31: 0.9 | P31: 0.99169149 | Q31: 0.98930966 | R31: 0.99681326 | S31: 0.98244798 | T31: 0.9 | U31: 0.91863929 | V31: 0.90269976 | W31: 0.86456342 | X31: 0.83869249 | Y31: 0.92 | Z31: 0.937583 | AA31: 0.9432967 | AB31: 0.92666667 | AC31: 0.9079418 | AD31: 0.92 | AE31: 0.9976834 | AF31: 0.99229216 | AG31: 0.99325726 | AH31: 0.99489227 | AI31: 0.92 | AJ31: 0.95652603 | AK31: 0.96305492 | AL31: 0.96098297 | AM31: 0.92899189 | AN31: 0.99 | AO31: 1 | AP31: 1 | AQ31: 1 | AR31: 1 | AS31: 0.08721821 | AT31: 0.14 | AU31: 0.12698413 | AV31: 0.21153846 | AW31: 0.073355818
C32: JAKARTA雅加达 | D32: Pickup Delivery | E32: AGENT40 | F32: KLENDER | G32: KLENDER | H32: KLENDER | I32: KLENDER | J32: 0.9 | K32: 0.94594595 | L32: 0.97260274 | M32: 0.9516129 | N32: 0.94416562 | O32: 0.9 | P32: 0.98818067 | Q32: 0.98712584 | R32: 0.98542805 | S32: 0.98490012 | T32: 0.9 | U32: 0.89067117 | V32: 0.88960412 | W32: 0.88797814 | X32: 0.89051041 | Y32: 0.92 | Z32: 0.94549366 | AA32: 0.9460719 | AB32: 0.93478261 | AC32: 0.95524671 | AD32: 0.92 | AE32: 0.99789079 | AF32: 0.98734686 | AG32: 0.99197056 | AH32: 0.99037748 | AI32: 0.92 | AJ32: 0.94948107 | AK32: 0.95664976 | AL32: 0.95604748 | AM32: 0.9664403 | AN32: 0.99 | AO32: 1 | AP32: 1 | AQ32: 1 | AR32: 1 | AS32: 0.08721821 | AT32: 0.085106383 | AU32: 0.027027027 | AV32: 0.028571429 | AW32: 0.047268908
C33: JAKARTA雅加达 | D33: Pickup Delivery | E33: AGENT40 | F33: CP_JATINEGARA_BARAT | G33: CP_JATINEGARA_BARAT | H33: CP_JATINEGARA_BARAT | I33: CP_JATINEGARA_BARAT | J33: 0.9 | K33: 0.9375 | L33: 0.98461538 | M33: 0.94642857 | N33: 0.93021767 | O33: 0.9 | P33: 0.91350312 | Q33: 0.86079916 | R33: 0.6400626 | S33: 0.87846099 | T33: 0.9 | U33: 0.80057665 | V33: 0.83102638 | W33: 0.78967136 | X33: 0.79399896 | Y33: 0.92 | Z33: 0.94335169 | AA33: 0.9249917 | AB33: 0.97194389 | AC33: 0.94565631 | AD33: 0.92 | AE33: 0.9960849 | AF33: 0.98428886 | AG33: 0.82363436 | AH33: 0.9521112 | AI33: 0.92 | AJ33: 0.94705444 | AK33: 0.94901388 | AL33: 0.9613826 | AM33: 0.95868955 | AN33: 0.99 | AO33: 1 | AP33: 1 | AQ33: 1 | AR33: 1 | AS33: 0.08721821 | AT33: 0.076923077 | AU33: 0.093023256 | AV33: 0.071428571 | AW33: 0.079507279
C34: JAKARTA雅加达 | D34: Pickup Delivery | E34: AGENT40 | F34: TEBET | G34: TEBET | H34: TEBET | I34: TEBET | J34: 0.9 | K34: 1 | L34: 0.94214876 | M34: 0.9787234 | N34: 0.97857948 | O34: 0.9 | P34: 0.99454793 | Q34: 0.99380514 | R34: 0.99741602 | S34: 0.99383266 | T34: 0.9 | U34: 0.87990307 | V34: 0.91026844 | W34: 0.88178295 | X34: 0.87932444 | Y34: 0.92 | Z34: 0.92678525 | AA34: 0.94316986 | AB34: 0.92427316 | AC34: 0.93593054 | AD34: 0.92 | AE34: 0.99811676 | AF34: 0.99355532 | AG34: 0.94248609 | AH34: 0.9870317 | AI34: 0.92 | AJ34: 0.95095888 | AK34: 0.96030959 | AL34: 0.95693989 | AM34: 0.95804874 | AN34: 0.99 | AO34: 1 | AP34: 1 | AQ34: 1 | AR34: 1 | AS34: 0.08721821 | AT34: 0.065789474 | AU34: 0.065420561 | AV34: 0.056603774 | AW34: 0.072345391
C35: JAKARTA雅加达 | D35: Pickup Delivery | E35: AGENT40 | F35: CP_HAJI_NAMAN_1 | G35: CP_HAJI_NAMAN_1 | H35: CP_HAJI_NAMAN_1 | I35: CP_HAJI_NAMAN_1 | J35: 0.9 | K35: 0.90425532 | L35: 0.87777778 | M35: 0.90789474 | N35: 0.91602687 | O35: 0.9 | P35: 0.92339648 | Q35: 0.91406092 | R35: 0.90252802 | S35: 0.8948958 | T35: 0.9 | U35: 0.8664008 | V35: 0.88279201 | W35: 0.85665885 | X35: 0.84454874 | Y35: 0.92 | Z35: 0.95844576 | AA35: 0.97519646 | AB35: 0.96854942 | AC35: 0.94622228 | AD35: 0.92 | AE35: 0.99768534 | AF35: 0.9715814 | AG35: 0.95444105 | AH35: 0.96903572 | AI35: 0.92 | AJ35: 0.96094954 | AK35: 0.97896368 | AL35: 0.97794254 | AM35: 0.96177619 | AN35: 0.99 | AO35: 1 | AP35: 1 | AQ35: 0.99526066 | AR35: 0.99936441 | AS35: 0.08721821 | AT35: 0.093023256 | AU35: 0.14925373 | AV35: 0.17241379 | AW35: 0.080645161
C36: JAKARTA雅加达 | D36: Pickup Delivery | E36: AGENT40 | F36: PULOGEBANG_01 | G36: PULOGEBANG_01 | H36: PULOGEBANG_01 | I36: PULOGEBANG_01 | J36: 0.9 | K36: 0.96875 | L36: 0.96753247 | M36: 0.94814815 | N36: 0.94707207 | O36: 0.9 | P36: 0.97380217 | Q36: 0.96713985 | R36: 0.9625498 | S36: 0.96630921 | T36: 0.9 | U36: 0.80266959 | V36: 0.82426393 | W36: 0.82111554 | X36: 0.81964629 | Y36: 0.92 | Z36: 0.91673879 | AA36: 0.93802817 | AB36: 0.93874891 | AC36: 0.93764253 | AD36: 0.92 | AE36: 0.98271889 | AF36: 0.98484848 | AG36: 0.94074074 | AH36: 0.95822102 | AI36: 0.92 | AJ36: 0.93562666 | AK36: 0.95125433 | AL36: 0.95697897 | AM36: 0.95621896 | AN36: 0.99 | AO36: 1 | AP36: 1 | AQ36: 1 | AR36: 1 | AS36: 0.08721821 | AT36: 0.18421053 | AU36: 0.063829787 | AV36: 0.076923077 | AW36: 0.062655087
C37: JAKARTA雅加达 | D37: Pickup Delivery | E37: AGENT40 | F37: DC_PULO_GADUNG | G37: DC_PULO_GADUNG | H37: DC_PULO_GADUNG | I37: DC_PULO_GADUNG | J37: 0.9 | K37: - | L37: - | M37: - | N37: - | O37: 0.9 | P37: - | Q37: - | R37: - | S37: - | T37: 0.9 | U37: - | V37: - | W37: - | X37: - | Y37: 0.92 | Z37: - | AA37: - | AB37: - | AC37: - | AD37: 0.92 | AE37: - | AF37: - | AG37: - | AH37: - | AI37: 0.92 | AJ37: - | AK37: - | AL37: - | AM37: - | AN37: 0.99 | AO37: - | AP37: - | AQ37: - | AR37: - | AS37: 0.08721821 | AT37: - | AU37: - | AV37: - | AW37: -
C38: JAKARTA雅加达 | D38: Pickup Delivery | E38: AGENT40 | F38: ROROTAN | G38: ROROTAN | H38: ROROTAN | I38: ROROTAN | J38: 0.9 | K38: 1 | L38: 1 | M38: 0.984375 | N38: 0.97639919 | O38: 0.9 | P38: 0.9792523 | Q38: 0.99150425 | R38: 0.9946198 | S38: 0.98473548 | T38: 0.9 | U38: 0.86318262 | V38: 0.85007496 | W38: 0.86477762 | X38: 0.85322966 | Y38: 0.92 | Z38: 0.93067703 | AA38: 0.92529054 | AB38: 0.92508143 | AC38: 0.93513963 | AD38: 0.92 | AE38: 0.99391062 | AF38: 0.99695622 | AG38: 0.99462414 | AH38: 0.99529069 | AI38: 0.92 | AJ38: 0.94706026 | AK38: 0.94344574 | AL38: 0.95593727 | AM38: 0.95589914 | AN38: 0.99 | AO38: 1 | AP38: 1 | AQ38: 1 | AR38: 1 | AS38: 0.08721821 | AT38: 0.12 | AU38: 0.090909091 | AV38: 0.23076923 | AW38: 0.069381599
C39: JAKARTA雅加达 | D39: Pickup Delivery | E39: AGENT40 | F39: DC_UJUNG_MENTENG | G39: DC_UJUNG_MENTENG | H39: DC_UJUNG_MENTENG | I39: DC_UJUNG_MENTENG | J39: 0.9 | K39: 0.93333333 | L39: 0.70689655 | M39: 0.86538462 | N39: 0.93042191 | O39: 0.9 | P39: 0.99504229 | Q39: 0.9959968 | R39: 0.98465037 | S39: 0.99770425 | T39: 0.9 | U39: 0.87459901 | V39: 0.89311449 | W39: 0.89596362 | X39: 0.88774852 | Y39: 0.92 | Z39: 0.92850147 | AA39: 0.95324675 | AB39: 0.95137976 | AC39: 0.95773895 | AD39: 0.92 | AE39: 0.99531616 | AF39: 0.99815072 | AG39: 0.95151515 | AH39: 0.99042487 | AI39: 0.92 | AJ39: 0.95191956 | AK39: 0.96651414 | AL39: 0.96468254 | AM39: 0.97056541 | AN39: 0.99 | AO39: 1 | AP39: 1 | AQ39: 1 | AR39: 1 | AS39: 0.08721821 | AT39: 0.071428571 | AU39: 0.086956522 | AV39: 0.086956522 | AW39: 0.048442907
C40: JAKARTA雅加达 | D40: Pickup Delivery | E40: AGENT40 | F40: CP_UTAN_KAYU | G40: CP_UTAN_KAYU | H40: CP_UTAN_KAYU | I40: CP_UTAN_KAYU | J40: 0.9 | K40: - | L40: - | M40: - | N40: - | O40: 0.9 | P40: 0 | Q40: 0 | R40: 0 | S40: 0.19303483 | T40: 0.9 | U40: 1 | V40: 1 | W40: 0.94444444 | X40: 0.98208955 | Y40: 0.92 | Z40: 1 | AA40: 1 | AB40: 1 | AC40: 0.99853157 | AD40: 0.92 | AE40: - | AF40: - | AG40: - | AH40: 0.97989759 | AI40: 0.92 | AJ40: 1 | AK40: 1 | AL40: 0.98181818 | AM40: 0.98940553 | AN40: 0.99 | AO40: - | AP40: - | AQ40: - | AR40: 1 | AS40: 0.08721821 | AT40: - | AU40: - | AV40: - | AW40: 11
C41: JAKARTA雅加达 | D41: Pickup Delivery | E41: AGENT40 | F41: KALIBARU_01 | G41: KALIBARU_01 | H41: KALIBARU_01 | I41: KALIBARU_01 | J41: 0.9 | K41: 0.89166667 | L41: 0.9137931 | M41: 0.96907216 | N41: 0.96284032 | O41: 0.9 | P41: 0.99171665 | Q41: 0.98985646 | R41: 0.99306326 | S41: 0.99232703 | T41: 0.9 | U41: 0.87746358 | V41: 0.8907177 | W41: 0.87097669 | X41: 0.89605357 | Y41: 0.92 | Z41: 0.93487143 | AA41: 0.94950739 | AB41: 0.9479921 | AC41: 0.95922399 | AD41: 0.92 | AE41: 0.9872679 | AF41: 0.9942789 | AG41: 0.99605133 | AH41: 0.99138525 | AI41: 0.92 | AJ41: 0.95575063 | AK41: 0.96097851 | AL41: 0.96798751 | AM41: 0.97325461 | AN41: 0.99 | AO41: 1 | AP41: 1 | AQ41: 1 | AR41: 1 | AS41: 0.08721821 | AT41: 0.08 | AU41: 0.028169014 | AV41: 0.028571429 | AW41: 0.045576408
...

Sheet Display Absensi 630
A1: =CONCATENATE("网管-打卡准点率报表爪哇-巴厘",TEXT($T$3,"MM月DD日")," NM-Persentase Absensi Tepat Waktu Sprinter Agent Jawa-Bali ",TEXT($T$3,"DD MMM YYYY")) -> 网管-打卡准点率报表爪哇-巴厘09月23日 NM-Persentase Absensi Tepat Waktu Sprinter Agent Jawa-Bali 23 Sep 2026
A2: 代理区 Agent | B2: RM | C2: 网点名称 Nama DP | D2: 总人数 Total Orang | E2: 打卡人数 Jumlah yang Absensi | F2: ="总人数"&CHAR(10)&"Total Orang"&CHAR(10)&TEXT($U$3,"dd/mm/yyyy") -> 总人数 Total Orang 22/09/2026 | G2: ="打卡人数"&CHAR(10)&"Jumlah yang Absensi"&CHAR(10)&TEXT($U$3,"dd/mm/yyyy") -> 打卡人数 Jumlah yang Absensi 22/09/2026 | H2: ="总人数"&CHAR(10)&"Total Orang"&CHAR(10)&TEXT($V$3,"dd/mm/yyyy") -> 总人数 Total Orang 21/09/2026 | I2: ="打卡人数"&CHAR(10)&"Jumlah yang Absensi"&CHAR(10)&TEXT($V$3,"dd/mm/yyyy") -> 打卡人数 Jumlah yang Absensi 21/09/2026 | J2: 目标值 Target | K2: =CONCATENATE(TEXT($T$3,"DD日"),"打卡率 Persentase Absensi") -> 23日打卡率 Persentase Absensi | N2: 总人数 Total Orang Bulanan | O2: 准点打卡人数 Jumlah Absensi Tepat Waktu Bulanan | P2: 准点打卡人数 Jumlah Absensi Tepat Waktu | Q2: ="准点打卡人数"&CHAR(10)&"Jumlah Absensi Tepat Waktu"&CHAR(10)&TEXT($U$3,"dd/mm/yyyy") -> 准点打卡人数 Jumlah Absensi Tepat Waktu 22/09/2026 | R2: ="准点打卡人数"&CHAR(10)&"Jumlah Absensi Tepat Waktu"&CHAR(10)&TEXT($V$3,"dd/mm/yyyy") -> 准点打卡人数 Jumlah Absensi Tepat Waktu 21/09/2026 | S2: 月累计 打卡准点率 Persentase Bulanan | T2: 打卡准点率 Persentase Absensi Tepat Waktu | W2: 对比昨天 Perbandingan H-1 | X2: ="总人数"&CHAR(10)&"Total Orang Mingguan"&CHAR(10)&TEXT($AJ$6,"dd/mm/yyyy")&" - "&TEXT($AJ$5,"dd/mm/yyyy") -> 总人数 Total Orang Mingguan 17/09/2026 - 23/09/2026 | Y2: ="准点打卡人数"&CHAR(10)&"Jumlah Absensi Tepat Waktu"&CHAR(10)&TEXT($AJ$6,"dd/mm/yyyy")&" - "&TEXT($AJ$5,"dd/mm/yyyy") -> 准点打卡人数 Jumlah Absensi Tepat Waktu 17/09/2026 - 23/09/2026 | Z2: ="总人数"&CHAR(10)&"Total Orang Mingguan"&CHAR(10)&TEXT($AK$6,"dd/mm/yyyy")&" - "&TEXT($AK$5,"dd/mm/yyyy") -> 总人数 Total Orang Mingguan 10/09/2026 - 16/09/2026 | AA2: ="准点打卡人数"&CHAR(10)&"Jumlah Absensi Tepat Waktu"&CHAR(10)&TEXT($AK$6,"dd/mm/yyyy")&" - "&TEXT($AK$5,"dd/mm/yyyy") -> 准点打卡人数 Jumlah Absensi Tepat Waktu 10/09/2026 - 16/09/2026 | AB2: 打卡准点周度率 Persentase Mingguan Absensi Tepat Waktu | AD2: 对比上周 Perbandingan Mingguan
K3: =T3 -> 46288 | L3: =K3-1 -> 46287 | M3: =K3-2 -> 46286 | T3: ='ALL DP DATA'!K8 -> 46288 | U3: =T3-1 -> 46287 | V3: =T3-2 -> 46286 | AB3: =TEXT(AJ6,"dd mmm")&" - "&TEXT(AJ5,"dd mmm") -> 17 Sep - 23 Sep | AC3: =TEXT(AK6,"dd mmm")&" - "&TEXT(AK5,"dd mmm") -> 10 Sep - 16 Sep
D4: 47314 | E4: 46386 | F4: 5933 | G4: 5755 | H4: 5055 | I4: 4823 | J4: 0.9 | K4: 0.98038635 | L4: 0.96999831 | M4: 0.95410485 | N4: 1012571 | O4: 949234 | P4: 44706 | Q4: 5470 | R4: 4682 | S4: 0.93744932 | T4: 0.94487889 | U4: 0.92196191 | V4: 0.92621167 | W4: 0.022916986 | X4: 39626 | Y4: 36820 | Z4: 40576 | AA4: 37926 | AB4: 0.92918791 | AC4: 0.93469046 | AD4: -0.0055025505 | AE4: 5
AJ5: =K3 -> 46288 | AK5: =AJ6-1 -> 46281
A6: JAKARTA雅加达 | B6: AGISTA PRIYANTONO | C6: DC_SUNTER | D6: 0 | E6: 0 | F6: 0 | G6: 0 | H6: 0 | I6: 0 | J6: 0.9 | K6: 0 | L6: 0 | M6: 0 | N6: 0 | O6: 0 | P6: 0 | Q6: 0 | R6: 0 | S6: 0 | T6: 0 | U6: 0 | V6: 0 | W6: 0 | X6: 0 | Y6: 0 | Z6: 0 | AA6: 0 | AB6: 0 | AC6: 0 | AD6: 0 | AJ6: =K3-6 -> 46282 | AK6: =AJ5-13 -> 46275
A7: JAKARTA雅加达 | B7: AGISTA PRIYANTONO | C7: CP_DANAUSUNTER_UTARA | D7: 122 | E7: 118 | F7: 122 | G7: 115 | H7: 99 | I7: 91 | J7: 0.9 | K7: 0.96721311 | L7: 0.94262295 | M7: 0.91919192 | N7: 2647 | O7: 2327 | P7: 113 | Q7: 114 | R7: 84 | S7: 0.87910842 | T7: 0.92622951 | U7: 0.93442623 | V7: 0.84848485 | W7: -0.0081967213 | X7: 812 | Y7: 720 | Z7: 815 | AA7: 716 | AB7: 0.88669951 | AC7: 0.87852761 | AD7: 0.0081719
A8: JAKARTA雅加达 | B8: AGISTA PRIYANTONO | C8: PLUIT_PERMAI | D8: 0 | E8: 0 | F8: 0 | G8: 0 | H8: 0 | I8: 0 | J8: 0.9 | K8: 0 | L8: 0 | M8: 0 | N8: 0 | O8: 0 | P8: 0 | Q8: 0 | R8: 0 | S8: 0 | T8: 0 | U8: 0 | V8: 0 | W8: 0 | X8: 0 | Y8: 0 | Z8: 0 | AA8: 0 | AB8: 0 | AC8: 0 | AD8: 0 | AJ8: 46266
A9: JAKARTA雅加达 | B9: AGISTA PRIYANTONO | C9: CP_TELUK_GONG_RAYA | D9: 52 | E9: 52 | F9: 51 | G9: 51 | H9: 45 | I9: 43 | J9: 0.9 | K9: 1 | L9: 1 | M9: 0.95555556 | N9: 1200 | O9: 1066 | P9: 49 | Q9: 48 | R9: 43 | S9: 0.88833333 | T9: 0.94230769 | U9: 0.94117647 | V9: 0.95555556 | W9: 0.0011312217 | X9: 351 | Y9: 315 | Z9: 366 | AA9: 328 | AB9: 0.8974359 | AC9: 0.89617486 | AD9: 0.001261034
A10: JAKARTA雅加达 | B10: AGISTA PRIYANTONO | C10: KEPULAUAN_SERIBU | D10: 31 | E10: 30 | F10: 17 | G10: 17 | H10: 27 | I10: 27 | J10: 0.9 | K10: 0.96774194 | L10: 1 | M10: 1 | N10: 614 | O10: 590 | P10: 30 | Q10: 17 | R10: 27 | S10: 0.96091205 | T10: 0.96774194 | U10: 1 | V10: 1 | W10: -0.032258065 | X10: 190 | Y10: 189 | Z10: 191 | AA10: 180 | AB10: 0.99473684 | AC10: 0.94240838 | AD10: 0.052328465
A11: JAKARTA雅加达 | B11: AGISTA PRIYANTONO | C11: CP_PADEMANGAN_4 | D11: 0 | E11: 0 | F11: 0 | G11: 0 | H11: 0 | I11: 0 | J11: 0.9 | K11: 0 | L11: 0 | M11: 0 | N11: 0 | O11: 0 | P11: 0 | Q11: 0 | R11: 0 | S11: 0 | T11: 0 | U11: 0 | V11: 0 | W11: 0 | X11: 0 | Y11: 0 | Z11: 0 | AA11: 0 | AB11: 0 | AC11: 0 | AD11: 0
A12: JAKARTA雅加达 | B12: AGISTA PRIYANTONO | C12: CP_PLUIT_PERMAI | D12: 66 | E12: 63 | F12: 65 | G12: 60 | H12: 53 | I12: 52 | J12: 0.9 | K12: 0.95454545 | L12: 0.92307692 | M12: 0.98113208 | N12: 1375 | O12: 1245 | P12: 61 | Q12: 54 | R12: 52 | S12: 0.90545455 | T12: 0.92424242 | U12: 0.83076923 | V12: 0.98113208 | W12: 0.093473193 | X12: 425 | Y12: 381 | Z12: 412 | AA12: 370 | AB12: 0.89647059 | AC12: 0.89805825 | AD12: -0.0015876642
A13: JAKARTA雅加达 | B13: AGISTA PRIYANTONO | C13: TELUK_GONG | D13: 121 | E13: 116 | F13: 115 | G13: 110 | H13: 97 | I13: 94 | J13: 0.9 | K13: 0.95867769 | L13: 0.95652174 | M13: 0.96907216 | N13: 2607 | O13: 2401 | P13: 110 | Q13: 109 | R13: 94 | S13: 0.92098197 | T13: 0.90909091 | U13: 0.94782609 | V13: 0.96907216 | W13: -0.038735178 | X13: 791 | Y13: 726 | Z13: 806 | AA13: 744 | AB13: 0.91782554 | AC13: 0.92307692 | AD13: -0.0052513858
A14: JAKARTA雅加达 | B14: AGISTA PRIYANTONO | C14: ANCOL | D14: 85 | E14: 83 | F14: 85 | G14: 83 | H14: 81 | I14: 78 | J14: 0.9 | K14: 0.97647059 | L14: 0.97647059 | M14: 0.96296296 | N14: 1878 | O14: 1749 | P14: 83 | Q14: 75 | R14: 74 | S14: 0.9313099 | T14: 0.97647059 | U14: 0.97647059 | V14: 1.0246914 | W14: 0 | X14: 577 | Y14: 532 | Z14: 586 | AA14: 545 | AB14: 0.9220104 | AC14: 0.93003413 | AD14: -0.0080237311
A15: JAKARTA雅加达 | B15: AGISTA PRIYANTONO | C15: CP_ANCOL_SELATAN_1 | D15: 129 | E15: 126 | F15: 119 | G15: 119 | H15: 113 | I15: 112 | J15: 0.9 | K15: 0.97674419 | L15: 1 | M15: 0.99115044 | N15: 2800 | O15: 2768 | P15: 126 | Q15: 119 | R15: 111 | S15: 0.98857143 | T15: 0.97674419 | U15: 1 | V15: 0.98230088 | W15: -0.023255814 | X15: 848 | Y15: 838 | Z15: 864 | AA15: 853 | AB15: 0.98820755 | AC15: 0.98726852 | AD15: 0.00093902865
A16: JAKARTA雅加达 | B16: AGISTA PRIYANTONO | C16: KAMAL_MUARA | D16: 30 | E16: 28 | F16: 31 | G16: 31 | H16: 27 | I16: 25 | J16: 0.9 | K16: 0.93333333 | L16: 1 | M16: 0.92592593 | N16: 658 | O16: 613 | P16: 28 | Q16: 31 | R16: 25 | S16: 0.93161094 | T16: 0.93333333 | U16: 1 | V16: 0.92592593 | W16: -0.066666667 | X16: 196 | Y16: 184 | Z16: 206 | AA16: 188 | AB16: 0.93877551 | AC16: 0.91262136 | AD16: 0.026154151
A17: JAKARTA雅加达 | B17: ANDI PRASETIYO | C17: KOTA_TUA | D17: 0 | E17: 0 | F17: 0 | G17: 0 | H17: 0 | I17: 0 | J17: 0.9 | K17: 0 | L17: 0 | M17: 0 | N17: 0 | O17: 0 | P17: 0 | Q17: 0 | R17: 0 | S17: 0 | T17: 0 | U17: 0 | V17: 0 | W17: 0 | X17: 0 | Y17: 0 | Z17: 0 | AA17: 0 | AB17: 0 | AC17: 0 | AD17: 0
A18: JAKARTA雅加达 | B18: ANDI PRASETIYO | C18: CP_PINANGSIA_RAYA | D18: 17 | E18: 15 | F18: 18 | G18: 17 | H18: 17 | I18: 17 | J18: 0.9 | K18: 0.88235294 | L18: 0.94444444 | M18: 1 | N18: 413 | O18: 333 | P18: 14 | Q18: 14 | R18: 16 | S18: 0.8062954 | T18: 0.82352941 | U18: 0.77777778 | V18: 0.94117647 | W18: 0.045751634 | X18: 124 | Y18: 101 | Z18: 128 | AA18: 102 | AB18: 0.81451613 | AC18: 0.796875 | AD18: 0.017641129
A19: JAKARTA雅加达 | B19: ANDI PRASETIYO | C19: TANAH_ABANG | D19: 99 | E19: 97 | F19: 101 | G19: 96 | H19: 85 | I19: 81 | J19: 0.9 | K19: 0.97979798 | L19: 0.95049505 | M19: 0.95294118 | N19: 2146 | O19: 1899 | P19: 93 | Q19: 96 | R19: 76 | S19: 0.88490214 | T19: 0.93939394 | U19: 0.95049505 | V19: 0.89411765 | W19: -0.01110111 | X19: 644 | Y19: 577 | Z19: 651 | AA19: 577 | AB19: 0.89596273 | AC19: 0.88632873 | AD19: 0.0096340079
A20: JAKARTA雅加达 | B20: ANDI PRASETIYO | C20: CP_MANGGA_BESAR_2 | D20: 45 | E20: 45 | F20: 45 | G20: 45 | H20: 43 | I20: 42 | J20: 0.9 | K20: 1 | L20: 1 | M20: 0.97674419 | N20: 1040 | O20: 942 | P20: 41 | Q20: 40 | R20: 40 | S20: 0.90576923 | T20: 0.91111111 | U20: 0.88888889 | V20: 0.93023256 | W20: 0.022222222 | X20: 315 | Y20: 283 | Z20: 324 | AA20: 294 | AB20: 0.8984127 | AC20: 0.90740741 | AD20: -0.008994709
... A1711: BALI巴厘 | B1711: Prisilia Nansiana Akong | C1711: KUPANG_TIMUR | D1711: 8 | E1711: 7 | F1711: 7 | G1711: 6 | H1711: 10 | I1711: 8 | J1711: 0.9 | K1711: 0.875 | L1711: 0.85714286 | M1711: 0.8 | N1711: 214 | O1711: 53 | P1711: 2 | Q1711: 2 | R1711: 4 | S1711: 0.24766355 | T1711: 0.25 | U1711: 0.28571429 | V1711: 0.4 | W1711: -0.035714286 | X1711: 62 | Y1711: 18 | Z1711: 57 | AA1711: 19 | AB1711: 0.29032258 | AC1711: 0.33333333 | AD1711: -0.043010753

Sheet Display 730 & 1200
A1: =CONCATENATE("网管-爪哇-巴厘班0730出仓率&1200签收率",TEXT($W$3,"MM月DD日")," NM-Persentase 0730 & TTD 1200 Agent Jawa-Bali ",TEXT($W$3,"DD MMM YYYY")) -> 网管-爪哇-巴厘班0730出仓率&1200签收率09月23日 NM-Persentase 0730 & TTD 1200 Agent Jawa-Bali 23 Sep 2026
A2: 代理区 Agent | B2: RM | C2: 网点名称 Nama DP | D2: Rit-1应签收 Seharusnya TTD Rit-1 | E2: 0730出仓率 Persentase Keluar Gudang 0730 | F2: 1200前已签收 TTD Sebelum 1200 | G2: ="Rit-1应签收"&CHAR(10)&"Seharusnya TTD Rit-1"&CHAR(10)&TEXT($X$3,"dd/mm/yyyy") -> Rit-1应签收 Seharusnya TTD Rit-1 22/09/2026 | H2: ="0730出仓率"&CHAR(10)&"Persentase Keluar Gudang 0730"&CHAR(10)&TEXT($X$3,"dd/mm/yyyy") -> 0730出仓率 Persentase Keluar Gudang 0730 22/09/2026 | I2: ="1200前已签收"&CHAR(10)&"TTD Sebelum"&CHAR(10)&"1200"&CHAR(10)&TEXT($X$3,"dd/mm/yyyy") -> 1200前已签收 TTD Sebelum 1200 22/09/2026 | J2: ="Rit-1应签收"&CHAR(10)&"Seharusnya TTD Rit-1"&CHAR(10)&TEXT($Y$3,"dd/mm/yyyy") -> Rit-1应签收 Seharusnya TTD Rit-1 21/09/2026 | K2: ="0730出仓率"&CHAR(10)&"Persentase Keluar Gudang 0730"&CHAR(10)&TEXT($Y$3,"dd/mm/yyyy") -> 0730出仓率 Persentase Keluar Gudang 0730 21/09/2026 | L2: ="1200前已签收"&CHAR(10)&"TTD Sebelum"&CHAR(10)&"1200"&CHAR(10)&TEXT($Y$3,"dd/mm/yyyy") -> 1200前已签收 TTD Sebelum 1200 21/09/2026 | M2: 月累计签收率 Persentase Bulanan | N2: 0730出仓率 Persentase Keluar Gudang 0730 Bulanan | O2: 目标值 Target | P2: =CONCATENATE(TEXT($W$3,"DD日"),"0730出仓率 Persentase Keluar Gudang 0730") -> 23日0730出仓率 Persentase Keluar Gudang 0730 | S2: 对比昨天 Perbandingan H-1 | T2: Rit-1应签收 Seharusnya TTD Rit-1 Bulanan | U2: 1200前已签收 TTD Sebelum 1200 Bulanan | V2: 月累计签收率 Persentase Bulanan | W2: 1200前已签收 TTD Sebelum 1200 | Z2: 对比昨天 Perbandingan H-1 | AA2: ="Rit-1应签收"&CHAR(10)&"Seharusnya TTD Rit-1 Mingguan"&CHAR(10)&TEXT($AM$10,"dd/mm/yyyy")&" - "&TEXT($AM$9,"dd/mm/yyyy") -> Rit-1应签收 Seharusnya TTD Rit-1 Mingguan 17/09/2026 - 23/09/2026 | AB2: ="1200前已签收"&CHAR(10)&"TTD Sebelum 1200 Mingguan"&CHAR(10)&TEXT($AM$10,"dd/mm/yyyy")&" - "&TEXT($AM$9,"dd/mm/yyyy") -> 1200前已签收 TTD Sebelum 1200 Mingguan 17/09/2026 - 23/09/2026 | AC2: ="Rit-1应签收"&CHAR(10)&"Seharusnya TTD Rit-1 Mingguan"&CHAR(10)&TEXT($AM$12,"dd/mm/yyyy")&" - "&TEXT($AM$11,"dd/mm/yyyy") -> Rit-1应签收 Seharusnya TTD Rit-1 Mingguan 10/09/2026 - 16/09/2026 | AD2: ="1200前已签收"&CHAR(10)&"TTD Sebelum 1200 Mingguan"&CHAR(10)&TEXT($AM$12,"dd/mm/yyyy")&" - "&TEXT($AM$11,"dd/mm/yyyy") -> 1200前已签收 TTD Sebelum 1200 Mingguan 10/09/2026 - 16/09/2026 | AE2: 1200前已签收周度率 Persentase Mingguan TTD 1200 | AG2: 对比上周 Perbandingan Mingguan
P3: =W3 -> 46288 | Q3: =P3-1 -> 46287 | R3: =P3-1 -> 46287 | W3: ='ALL DP DATA'!K8 -> 46288 | X3: =W3-1 -> 46287 | Y3: =X3-1 -> 46286 | AE3: =TEXT(AM10,"dd mmm")&" - "&TEXT(AM9,"dd mmm") -> 17 Sep - 23 Sep | AF3: =TEXT(AM12,"dd mmm")&" - "&TEXT(AM11,"dd mmm") -> 10 Sep - 16 Sep | AJ3: data mingguan harus difix, ga boleh hanya patokan jakarta doang
C4: AGENT40 | D4: 3273470 | E4: 3122790 | F4: 2921534 | G4: 372183 | H4: 355299 | I4: 325025 | J4: 262815 | K4: 246348 | L4: 224018 | M4: 0.95215257 | N4: 8242223 | O4: 0.9 | P4: 0.95396934 | Q4: 0.95463522 | R4: 0.93734376 | S4: -0.00066588448 | T4: 8656410 | U4: 7212198 | V4: 0.83316271 | W4: 0.8924884 | X4: 0.87329351 | Y4: 0.85237905 | Z4: 0.019194885 | AA4: 2536150 | AB4: 2165285 | AC4: 2706118 | AD4: 2253543 | AE4: 0.85376851 | AF4: 0.83275859 | AG4: 0.021009921 | AH4: 5
A6: JAKARTA雅加达 | B6: AGISTA PRIYANTONO | C6: DC_SUNTER | D6: 0 | E6: 0 | F6: 0 | G6: 0 | H6: 0 | I6: 0 | J6: 0 | K6: 0 | L6: 0 | M6: 0 | N6: 0 | O6: 0.9 | P6: 0 | Q6: 0 | R6: 0 | S6: 0 | T6: 0 | U6: 0 | V6: 0 | W6: 0 | X6: 0 | Y6: 0 | Z6: 0 | AA6: 0 | AB6: 0 | AC6: 0 | AD6: 0 | AE6: 0 | AF6: 0 | AG6: 0
A7: JAKARTA雅加达 | B7: AGISTA PRIYANTONO | C7: CP_PLUIT_PERMAI | D7: 7664 | E7: 7159 | F7: 5988 | G7: 7379 | H7: 7025 | I7: 6025 | J7: 5121 | K7: 5084 | L7: 4326 | M7: 0.94921213 | N7: 133370 | O7: 0.9 | P7: 0.93410752 | Q7: 0.95202602 | R7: 0.99277485 | S7: -0.017918504 | T7: 140506 | U7: 102834 | V7: 0.73188334 | W7: 0.78131524 | X7: 0.8165063 | Y7: 0.84475688 | Z7: -0.035191062 | AA7: 46141 | AB7: 37681 | AC7: 44234 | AD7: 31473 | AE7: 0.81664897 | AF7: 0.71151151 | AG7: 0.10513746
A8: JAKARTA雅加达 | B8: AGISTA PRIYANTONO | C8: PLUIT_PERMAI | D8: 0 | E8: 0 | F8: 0 | G8: 0 | H8: 0 | I8: 0 | J8: 0 | K8: 0 | L8: 0 | M8: 0 | N8: 0 | O8: 0.9 | P8: 0 | Q8: 0 | R8: 0 | S8: 0 | T8: 0 | U8: 0 | V8: 0 | W8: 0 | X8: 0 | Y8: 0 | Z8: 0 | AA8: 0 | AB8: 0 | AC8: 0 | AD8: 0 | AE8: 0 | AF8: 0 | AG8: 0
A9: JAKARTA雅加达 | B9: AGISTA PRIYANTONO | C9: CP_DANAUSUNTER_UTARA | D9: 8342 | E9: 8076 | F9: 6839 | G9: 7359 | H9: 7230 | I9: 6546 | J9: 5558 | K9: 5372 | L9: 4578 | M9: 0.98540779 | N9: 171458 | O9: 0.9 | P9: 0.96811316 | Q9: 0.98247044 | R9: 0.96653472 | S9: -0.014357282 | T9: 173997 | U9: 139272 | V9: 0.80042759 | W9: 0.81982738 | X9: 0.88952303 | Y9: 0.82367758 | Z9: -0.069695653 | AA9: 51243 | AB9: 42671 | AC9: 56249 | AD9: 45738 | AE9: 0.83271862 | AF9: 0.81313446 | AG9: 0.01958416 | AL9: =W3 -> 46288 | AM9: =AL9 -> 46288
A10: JAKARTA雅加达 | B10: AGISTA PRIYANTONO | C10: TELUK_GONG | D10: 9210 | E10: 8142 | F10: 7560 | G10: 7153 | H10: 6804 | I10: 6195 | J10: 5382 | K10: 4539 | L10: 4469 | M10: 0.91364197 | N10: 165932 | O10: 0.9 | P10: 0.88403909 | Q10: 0.95120928 | R10: 0.84336678 | S10: -0.067170195 | T10: 181616 | U10: 149844 | V10: 0.82505947 | W10: 0.82084691 | X10: 0.86607018 | Y10: 0.83036046 | Z10: -0.045223275 | AA10: 51512 | AB10: 43566 | AC10: 56029 | AD10: 46510 | AE10: 0.84574468 | AF10: 0.83010584 | AG10: 0.015638843 | AM10: =AM9-6 -> 46282
A11: JAKARTA雅加达 | B11: AGISTA PRIYANTONO | C11: ANCOL | D11: 7091 | E11: 6439 | F11: 6367 | G11: 6052 | H11: 5464 | I11: 5430 | J11: 5034 | K11: 3904 | L11: 4472 | M11: 0.88030453 | N11: 125108 | O11: 0.9 | P11: 0.90805246 | Q11: 0.90284204 | R11: 0.77552642 | S11: 0.0052104252 | T11: 142119 | U11: 128425 | V11: 0.90364413 | W11: 0.89789874 | X11: 0.89722406 | Y11: 0.88835916 | Z11: 0.00067468673 | AA11: 41789 | AB11: 37988 | AC11: 45097 | AD11: 41367 | AE11: 0.90904305 | AF11: 0.9172894 | AG11: -0.0082463488 | AM11: =AM10-1 -> 46281
A12: JAKARTA雅加达 | B12: AGISTA PRIYANTONO | C12: KAMAL_MUARA | D12: 1495 | E12: 1488 | F12: 1294 | G12: 1326 | H12: 1319 | I12: 1162 | J12: 1233 | K12: 1214 | L12: 1024 | M12: 0.93744423 | N12: 29417 | O12: 0.9 | P12: 0.99531773 | Q12: 0.99472097 | R12: 0.98459043 | S12: 0.00059676044 | T12: 31380 | U12: 27847 | V12: 0.88741236 | W12: 0.86555184 | X12: 0.87631976 | Y12: 0.83049473 | Z12: -0.010767919 | AA12: 11113 | AB12: 9999 | AC12: 8730 | AD12: 7642 | AE12: 0.89975704 | AF12: 0.87537228 | AG12: 0.024384762 | AM12: =AM11-6 -> 46275
A13: JAKARTA雅加达 | B13: AGISTA PRIYANTONO | C13: KEPULAUAN_SERIBU | D13: 2062 | E13: 2061 | F13: 2039 | G13: 2856 | H13: 2854 | I13: 2829 | J13: 2755 | K13: 2753 | L13: 2727 | M13: 0.95204887 | N13: 67168 | O13: 0.9 | P13: 0.99951503 | Q13: 0.99929972 | R13: 0.99927405 | S13: 0.00021531406 | T13: 70551 | U13: 67119 | V13: 0.95135434 | W13: 0.98884578 | X13: 0.99054622 | Y13: 0.98983666 | Z13: -0.0017004377 | AA13: 21368 | AB13: 21136 | AC13: 20388 | AD13: 19015 | AE13: 0.98914264 | AF13: 0.93265646 | AG13: 0.056486179 | AM13: 46266
A14: JAKARTA雅加达 | B14: AGISTA PRIYANTONO | C14: CP_ANCOL_SELATAN_1 | D14: 10694 | E14: 10588 | F14: 9756 | G14: 9818 | H14: 9748 | I14: 9021 | J14: 7080 | K14: 7025 | L14: 6562 | M14: 0.9820134 | N14: 211454 | O14: 0.9 | P14: 0.9900879 | Q14: 0.99287024 | R14: 0.99223164 | S14: -0.0027823386 | T14: 215327 | U14: 198088 | V14: 0.91994037 | W14: 0.91228726 | X14: 0.91882257 | Y14: 0.92683616 | Z14: -0.0065353069 | AA14: 66204 | AB14: 61201 | AC14: 67954 | AD14: 62673 | AE14: 0.92443055 | AF14: 0.92228566 | AG14: 0.0021448842
A15: JAKARTA雅加达 | B15: AGISTA PRIYANTONO | C15: CP_TELUK_GONG_RAYA | D15: 5289 | E15: 5166 | F15: 4894 | G15: 5407 | H15: 5327 | I15: 5088 | J15: 4491 | K15: 3992 | L15: 4170 | M15: 0.96187703 | N15: 102387 | O15: 0.9 | P15: 0.97674419 | Q15: 0.98520436 | R15: 0.88888889 | S15: -0.0084601787 | T15: 106445 | U15: 99865 | V15: 0.93818404 | W15: 0.9253167 | X15: 0.9410024 | Y15: 0.92852371 | Z15: -0.015685709 | AA15: 34530 | AB15: 32610 | AC15: 33862 | AD15: 32079 | AE15: 0.94439618 | AF15: 0.94734511 | AG15: -0.0029489294
A16: JAKARTA雅加达 | B16: AGISTA PRIYANTONO | C16: CP_PADEMANGAN_4 | D16: 0 | E16: 0 | F16: 0 | G16: 0 | H16: 0 | I16: 0 | J16: 0 | K16: 0 | L16: 0 | M16: 0.125 | N16: 7 | O16: 0.9 | P16: 0 | Q16: 0 | R16: 0 | S16: 0 | T16: 56 | U16: 54 | V16: 0.96428571 | W16: 0 | X16: 0 | Y16: 0 | Z16: 0 | AA16: 0 | AB16: 0 | AC16: 5 | AD16: 5 | AE16: 0 | AF16: 1 | AG16: -1
A17: JAKARTA雅加达 | B17: ANDI PRASETIYO | C17: KOTA_TUA | D17: 0 | E17: 0 | F17: 0 | G17: 0 | H17: 0 | I17: 0 | J17: 0 | K17: 0 | L17: 0 | M17: 0 | N17: 0 | O17: 0.9 | P17: 0 | Q17: 0 | R17: 0 | S17: 0 | T17: 0 | U17: 0 | V17: 0 | W17: 0 | X17: 0 | Y17: 0 | Z17: 0 | AA17: 0 | AB17: 0 | AC17: 0 | AD17: 0 | AE17: 0 | AF17: 0 | AG17: 0
A18: JAKARTA雅加达 | B18: ANDI PRASETIYO | C18: CP_PINANGSIA_RAYA | D18: 2167 | E18: 2145 | F18: 1490 | G18: 1665 | H18: 1637 | I18: 1386 | J18: 1086 | K18: 1059 | L18: 687 | M18: 0.88711148 | N18: 35991 | O18: 0.9 | P18: 0.98984772 | Q18: 0.98318318 | R18: 0.97513812 | S18: 0.0066645326 | T18: 40571 | U18: 25985 | V18: 0.64048212 | W18: 0.68758653 | X18: 0.83243243 | Y18: 0.63259669 | Z18: -0.14484591 | AA18: 11950 | AB18: 8082 | AC18: 12596 | AD18: 7822 | AE18: 0.67631799 | AF18: 0.62099079 | AG18: 0.055327201
A19: JAKARTA雅加达 | B19: ANDI PRASETIYO | C19: TANAH_ABANG | D19: 6659 | E19: 6616 | F19: 4947 | G19: 5080 | H19: 5058 | I19: 3925 | J19: 3469 | K19: 3457 | L19: 2520 | M19: 0.99423061 | N19: 129591 | O19: 0.9 | P19: 0.99354257 | Q19: 0.99566929 | R19: 0.99654079 | S19: -0.0021267174 | T19: 130343 | U19: 94247 | V19: 0.72306913 | W19: 0.74290434 | X19: 0.7726378 | Y19: 0.72643413 | Z19: -0.029733455 | AA19: 36767 | AB19: 26487 | AC19: 41114 | AD19: 29520 | AE19: 0.72040145 | AF19: 0.7180036 | AG19: 0.0023978472
A20: JAKARTA雅加达 | B20: ANDI PRASETIYO | C20: CP_MANGGA_BESAR_2 | D20: 4877 | E20: 4782 | F20: 4422 | G20: 4825 | H20: 4205 | I20: 4465 | J20: 3833 | K20: 3253 | L20: 3527 | M20: 0.91466735 | N20: 92375 | O20: 0.9 | P20: 0.98052081 | Q20: 0.87150259 | R20: 0.84868249 | S20: 0.10901822 | T20: 100993 | U20: 90205 | V20: 0.89318072 | W20: 0.90670494 | X20: 0.9253886 | Y20: 0.92016697 | Z20: -0.018683659 | AA20: 32080 | AB20: 29690 | AC20: 31942 | AD20: 28883 | AE20: 0.92549875 | AF20: 0.90423267 | AG20: 0.021266081
A21: JAKARTA雅加达 | B21: ANDI PRASETIYO | C21: JOHAR_BARU_01 | D21: 6262 | E21: 6233 | F21: 5426 | G21: 4691 | H21: 4660 | I21: 4105 | J21: 3462 | K21: 3453 | L21: 2992 | M21: 0.99357817 | N21: 118360 | O21: 0.9 | P21: 0.99536889 | Q21: 0.9933916 | R21: 0.99740035 | S21: 0.0019772908 | T21: 119125 | U21: 104042 | V21: 0.8733851 | W21: 0.86649633 | X21: 0.87507994 | Y21: 0.86424032 | Z21: -0.0085836133 | AA21: 34186 | AB21: 29777 | AC21: 35885 | AD21: 31546 | AE21: 0.87102908 | AF21: 0.87908597 | AG21: -0.0080568928
A22: JAKARTA雅加达 | B22: ANDI PRASETIYO | C22: SENEN | D22: 8734 | E22: 8667 | F22: 7654 | G22: 7129 | H22: 7018 | I22: 6424 | J22: 4330 | K22: 4315 | L22: 3797 | M22: 0.9923751 | N22: 171797 | O22: 0.9 | P22: 0.99232883 | Q22: 0.98442979 | R22: 0.9965358 | S22: 0.0078990361 | T22: 173117 | U22: 153609 | V22: 0.8873132 | W22: 0.87634532 | X22: 0.90110815 | Y22: 0.87690531 | Z22: -0.024762833 | AA22: 48004 | AB22: 42610 | AC22: 52748 | AD22: 47025 | AE22: 0.88763436 | AF22: 0.891503 | AG22: -0.0038686316
A23: JAKARTA雅加达 | B23: ANDI PRASETIYO | C23: CP_ZAINUL_ARIFIN | D23: 1931 | E23: 1910 | F23: 1721 | G23: 2245 | H23: 2208 | I23: 2046 | J23: 1605 | K23: 1580 | L23: 1406 | M23: 0.97867512 | N23: 35797 | O23: 0.9 | P23: 0.98912481 | Q23: 0.98351893 | R23: 0.98442368 | S23: 0.0056058748 | T23: 36577 | U23: 31378 | V23: 0.8578615 | W23: 0.89124806 | X23: 0.91135857 | Y23: 0.87601246 | Z23: -0.020110517 | AA23: 13485 | AB23: 12094 | AC23: 10385 | AD23: 9146 | AE23: 0.89684835 | AF23: 0.88069331 | AG23: 0.016155042
A24: JAKARTA雅加达 | B24: ARIS YULIANTO | C24: DC_CIPAYUNG | D24: 0 | E24: 0 | F24: 0 | G24: 0 | H24: 0 | I24: 0 | J24: 0 | K24: 0 | L24: 0 | M24: 0 | N24: 0 | O24: 0.9 | P24: 0 | Q24: 0 | R24: 0 | S24: 0 | T24: 0 | U24: 0 | V24: 0 | W24: 0 | X24: 0 | Y24: 0 | Z24: 0 | AA24: 0 | AB24: 0 | AC24: 0 | AD24: 0 | AE24: 0 | AF24: 0 | AG24: 0
A25: JAKARTA雅加达 | B25: ARIS YULIANTO | C25: KELAPA_DUA_01 | D25: 0 | E25: 0 | F25: 0 | G25: 0 | H25: 0 | I25: 0 | J25: 0 | K25: 0 | L25: 0 | M25: 0 | N25: 0 | O25: 0.9 | P25: 0 | Q25: 0 | R25: 0 | S25: 0 | T25: 0 | U25: 0 | V25: 0 | W25: 0 | X25: 0 | Y25: 0 | Z25: 0 | AA25: 0 | AB25: 0 | AC25: 0 | AD25: 0 | AE25: 0 | AF25: 0 | AG25: 0
... A1711: BALI巴厘 | B1711: Prisilia Nansiana Akong | C1711: KUPANG_TIMUR | D1711: 76 | E1711: 50 | F1711: 50 | G1711: 340 | H1711: 336 | I1711: 233 | J1711: 588 | K1711: 573 | L1711: 239 | M1711: 0.91227181 | N1711: 7196 | O1711: 0.9 | P1711: 0.65789474 | Q1711: 0.98823529 | R1711: 0.9744898 | S1711: -0.33034056 | T1711: 7888 | U1711: 5770 | V1711: 0.73149087 | W1711: 0.65789474 | X1711: 0.68529412 | Y1711: 0.40646259 | Z1711: -0.027399381 | AA1711: 2921 | AB1711: 1978 | AC1711: 1001 | AD1711: 883 | AE1711: 0.67716535 | AF1711: 0.88211788 | AG1711: -0.20495253

Sheet Display Ritase Keseluruhan
A1: =CONCATENATE("网管-爪哇-巴厘班次全天签收率报表",TEXT($R$3,"MM月DD日")," NM-'Display Absensi 630'!E:E ",TEXT($R$3,"DD MMM YYYY")) -> 网管-爪哇-巴厘班次全天签收率报表09月23日 NM-'Display Absensi 630'!E:E 23 Sep 2026
A2: 代理区 Agent | B2: RM | C2: 网点名称 Nama DP | D2: T-1应签收 Seharusnya TTD H-1 | E2: 2359前已签收 TTD Sebelum 2359 | F2: 未签收 Belum TTD | G2: ="T-1应签收"&CHAR(10)&"Seharusnya TTD "&TEXT($S$3,"dd/mm/yyyy") -> T-1应签收 Seharusnya TTD 22/09/2026 | H2: ="2359前已签收"&CHAR(10)&"TTD Sebelum"&CHAR(10)&"2359"&CHAR(10)&TEXT($S$3,"dd/mm/yyyy") -> 2359前已签收 TTD Sebelum 2359 22/09/2026 | I2: ="未签收"&CHAR(10)&"Belum TTD"&CHAR(10)&TEXT($S$3,"dd/mm/yyyy") -> 未签收 Belum TTD 22/09/2026 | J2: ="T-1应签收"&CHAR(10)&"Seharusnya TTD "&TEXT($T$3,"dd/mm/yyyy") -> T-1应签收 Seharusnya TTD 21/09/2026 | K2: ="2359前已签收"&CHAR(10)&"TTD Sebelum"&CHAR(10)&"2359"&CHAR(10)&TEXT($T$3,"dd/mm/yyyy") -> 2359前已签收 TTD Sebelum 2359 21/09/2026 | L2: ="未签收"&CHAR(10)&"Belum TTD"&CHAR(10)&TEXT($T$3,"dd/mm/yyyy") -> 未签收 Belum TTD 21/09/2026 | M2: 目标值 Target | N2: 累计应签收量 Seharusnya TTD Bulanan | O2: 累计签收量 TTD Bulanan | P2: 累计未签收 Belum TTD Bulanan | Q2: 月累计 签收率 Persentase Bulanan | R2: 全天签收率 Persentase TTD All Ritase | U2: 对比昨天 Perbandingan H-1 | V2: ="累计应签收量"&CHAR(10)&"Seharusnya TTD Mingguan"&CHAR(10)&TEXT($AG$10,"dd/mm/yyyy")&" - "&TEXT($AG$9,"dd/mm/yyyy") -> 累计应签收量 Seharusnya TTD Mingguan 17/09/2026 - 23/09/2026 | W2: ="累计签收量"&CHAR(10)&"TTD Mingguan"&CHAR(10)&TEXT($AG$10,"dd/mm/yyyy")&" - "&TEXT($AG$9,"dd/mm/yyyy") -> 累计签收量 TTD Mingguan 17/09/2026 - 23/09/2026 | X2: ="累计应签收量"&CHAR(10)&"Seharusnya TTD Mingguan"&CHAR(10)&TEXT($AG$12,"dd/mm/yyyy")&" - "&TEXT($AG$11,"dd/mm/yyyy") -> 累计应签收量 Seharusnya TTD Mingguan 10/09/2026 - 16/09/2026 | Y2: ="累计签收量"&CHAR(10)&"TTD Mingguan"&CHAR(10)&TEXT($AG$12,"dd/mm/yyyy")&" - "&TEXT($AG$11,"dd/mm/yyyy") -> 累计签收量 TTD Mingguan 10/09/2026 - 16/09/2026 | Z2: 全天签收率周度率 Persentase Mingguan TTD All Ritase | AB2: 对比上周 Perbandingan Mingguan
R3: ='ALL DP DATA'!K8 -> 46288 | S3: =R3-1 -> 46287 | T3: =S3-1 -> 46286 | Z3: =TEXT(AG10,"dd mmm")&" - "&TEXT(AG9,"dd mmm") -> 17 Sep - 23 Sep | AA3: =TEXT(AG12,"dd mmm")&" - "&TEXT(AG11,"dd mmm") -> 10 Sep - 16 Sep
D4: 710045 | E4: 674695 | F4: 35350 | G4: 690023 | H4: 661419 | I4: 28604 | J4: 377836 | K4: 363285 | L4: 14551 | M4: 0.93 | N4: 104440387 | O4: 100434314 | P4: 4006073 | Q4: 0.96164249 | R4: 0.95021442 | S4: 0.95854631 | T4: 0.96148858 | U4: -0.0083318863 | V4: 4230546 | W4: 4039842 | X4: 4500837 | Y4: 4313210 | Z4: 0.95492213 | AA4: 0.95831286 | AB4: -0.0033907343 | AC4: 5
A6: JAKARTA雅加达 | B6: AGISTA PRIYANTONO | C6: DC_SUNTER | D6: 0 | E6: 0 | F6: 0 | G6: 0 | H6: 0 | I6: 0 | J6: 0 | K6: 0 | L6: 0 | M6: 0.93 | N6: 0 | O6: 0 | P6: 0 | Q6: 0 | R6: 0 | S6: 0 | T6: 0 | U6: 0 | V6: 0 | W6: 0 | X6: 0 | Y6: 0 | Z6: 0 | AA6: 0 | AB6: 0
A7: JAKARTA雅加达 | B7: AGISTA PRIYANTONO | C7: ANCOL | D7: 10986 | E7: 10652 | F7: 334 | G7: 10634 | H7: 10243 | I7: 391 | J7: 6652 | K7: 6415 | L7: 237 | M7: 0.93 | N7: 225873 | O7: 221686 | P7: 4187 | Q7: 0.98146303 | R7: 0.96959767 | S7: 0.96323115 | T7: 0.96437162 | U7: 0.0063665244 | V7: 65443 | W7: 63691 | X7: 70370 | Y7: 69495 | Z7: 0.97322861 | AA7: 0.98756572 | AB7: -0.014337113
A8: JAKARTA雅加达 | B8: AGISTA PRIYANTONO | C8: PLUIT_PERMAI | D8: 0 | E8: 0 | F8: 0 | G8: 0 | H8: 0 | I8: 0 | J8: 0 | K8: 0 | L8: 0 | M8: 0.93 | N8: 0 | O8: 0 | P8: 0 | Q8: 0 | R8: 0 | S8: 0 | T8: 0 | U8: 0 | V8: 0 | W8: 0 | X8: 0 | Y8: 0 | Z8: 0 | AA8: 0 | AB8: 0
A9: JAKARTA雅加达 | B9: AGISTA PRIYANTONO | C9: CP_PLUIT_PERMAI | D9: 12791 | E9: 12236 | F9: 555 | G9: 12538 | H9: 11924 | I9: 614 | J9: 7472 | K9: 7197 | L9: 275 | M9: 0.93 | N9: 236567 | O9: 222029 | P9: 14538 | Q9: 0.93854595 | R9: 0.95661012 | S9: 0.95102887 | T9: 0.96319593 | U9: 0.0055812443 | V9: 75857 | W9: 72157 | X9: 73866 | Y9: 68852 | Z9: 0.95122401 | AA9: 0.93212033 | AB9: 0.019103688 | AG9: =R3 -> 46288
A10: JAKARTA雅加达 | B10: AGISTA PRIYANTONO | C10: CP_PADEMANGAN_4 | D10: 0 | E10: 0 | F10: 0 | G10: 0 | H10: 0 | I10: 0 | J10: 1 | K10: 1 | L10: 0 | M10: 0.93 | N10: 72 | O10: 70 | P10: 2 | Q10: 0.97222222 | R10: 0 | S10: 0 | T10: 1 | U10: 0 | V10: 1 | W10: 1 | X10: 6 | Y10: 6 | Z10: 1 | AA10: 1 | AB10: 0 | AG10: =R3-6 -> 46282
A11: JAKARTA雅加达 | B11: AGISTA PRIYANTONO | C11: TELUK_GONG | D11: 14714 | E11: 13861 | F11: 853 | G11: 13466 | H11: 13263 | I11: 203 | J11: 7645 | K11: 7323 | L11: 322 | M11: 0.93 | N11: 306538 | O11: 299818 | P11: 6720 | Q11: 0.97807776 | R11: 0.942028 | S11: 0.984925 | T11: 0.95788097 | U11: -0.042896996 | V11: 85409 | W11: 83003 | X11: 92869 | Y11: 91150 | Z11: 0.97182967 | AA11: 0.98149006 | AB11: -0.0096603892 | AG11: =R3-7 -> 46281
A12: JAKARTA雅加达 | B12: AGISTA PRIYANTONO | C12: CP_DANAUSUNTER_UTARA | D12: 14360 | E12: 13648 | F12: 712 | G12: 12863 | H12: 12537 | I12: 326 | J12: 8410 | K12: 8160 | L12: 250 | M12: 0.93 | N12: 293031 | O12: 284231 | P12: 8800 | Q12: 0.96996905 | R12: 0.95041783 | S12: 0.97465599 | T12: 0.97027348 | U12: -0.024238163 | V12: 85284 | W12: 82860 | X12: 89662 | Y12: 87589 | Z12: 0.97157732 | AA12: 0.97687984 | AB12: -0.0053025195 | AG12: =R3-13 -> 46275
A13: JAKARTA雅加达 | B13: AGISTA PRIYANTONO | C13: KEPULAUAN_SERIBU | D13: 2062 | E13: 2046 | F13: 16 | G13: 2856 | H13: 2847 | I13: 9 | J13: 2755 | K13: 2744 | L13: 11 | M13: 0.93 | N13: 70554 | O13: 70146 | P13: 408 | Q13: 0.9942172 | R13: 0.99224054 | S13: 0.99684874 | T13: 0.99600726 | U13: -0.0046081963 | V13: 21369 | W13: 21294 | X13: 20389 | Y13: 20291 | Z13: 0.99649024 | AA13: 0.99519349 | AB13: 0.0012967562 | AG13: 46266
A14: JAKARTA雅加达 | B14: AGISTA PRIYANTONO | C14: CP_ANCOL_SELATAN_1 | D14: 17981 | E14: 17411 | F14: 570 | G14: 17830 | H14: 17317 | I14: 513 | J14: 10475 | K14: 10244 | L14: 231 | M14: 0.93 | N14: 367423 | O14: 359509 | P14: 7914 | Q14: 0.97846079 | R14: 0.96829987 | S14: 0.97122827 | T14: 0.97794749 | U14: -0.0029283949 | V14: 110371 | W14: 107752 | X14: 114875 | Y14: 112583 | Z14: 0.97627094 | AA14: 0.98004788 | AB14: -0.0037769374
A15: JAKARTA雅加达 | B15: AGISTA PRIYANTONO | C15: KAMAL_MUARA | D15: 2576 | E15: 2441 | F15: 135 | G15: 2615 | H15: 2497 | I15: 118 | J15: 1792 | K15: 1712 | L15: 80 | M15: 0.93 | N15: 54826 | O15: 52883 | P15: 1943 | Q15: 0.96456061 | R15: 0.94759317 | S15: 0.95487572 | T15: 0.95535714 | U15: -0.0072825493 | V15: 18258 | W15: 17617 | X15: 16036 | Y15: 15440 | Z15: 0.9648921 | AA15: 0.96283362 | AB15: 0.0020584777
A16: JAKARTA雅加达 | B16: AGISTA PRIYANTONO | C16: CP_TELUK_GONG_RAYA | D16: 9006 | E16: 8733 | F16: 273 | G16: 9429 | H16: 9227 | I16: 202 | J16: 6158 | K16: 5991 | L16: 167 | M16: 0.93 | N16: 176895 | O16: 172355 | P16: 4540 | Q16: 0.97433506 | R16: 0.96968688 | S16: 0.97857673 | T16: 0.97288081 | U16: -0.0088898559 | V16: 56359 | W16: 54972 | X16: 55968 | Y16: 54535 | Z16: 0.97538991 | AA16: 0.97439608 | AB16: 0.00099382763
A17: JAKARTA雅加达 | B17: ANDI PRASETIYO | C17: KOTA_TUA | D17: 0 | E17: 0 | F17: 0 | G17: 0 | H17: 0 | I17: 0 | J17: 0 | K17: 0 | L17: 0 | M17: 0.93 | N17: 0 | O17: 0 | P17: 0 | Q17: 0 | R17: 0 | S17: 0 | T17: 0 | U17: 0 | V17: 0 | W17: 0 | X17: 0 | Y17: 0 | Z17: 0 | AA17: 0 | AB17: 0
A18: JAKARTA雅加达 | B18: ANDI PRASETIYO | C18: TANAH_ABANG | D18: 10913 | E18: 9923 | F18: 990 | G18: 9947 | H18: 9063 | I18: 884 | J18: 5102 | K18: 4713 | L18: 389 | M18: 0.93 | N18: 226439 | O18: 204344 | P18: 22095 | Q18: 0.90242405 | R18: 0.90928251 | S18: 0.91112898 | T18: 0.92375539 | U18: -0.0018464765 | V18: 63302 | W18: 56335 | X18: 69766 | Y18: 62736 | Z18: 0.88994029 | AA18: 0.89923458 | AB18: -0.0092942979
A19: JAKARTA雅加达 | B19: ANDI PRASETIYO | C19: SENEN | D19: 13910 | E19: 13200 | F19: 710 | G19: 13646 | H19: 13063 | I19: 583 | J19: 6405 | K19: 6074 | L19: 331 | M19: 0.93 | N19: 295411 | O19: 281758 | P19: 13653 | Q19: 0.95378303 | R19: 0.94895758 | S19: 0.95727686 | T19: 0.94832162 | U19: -0.0083192732 | V19: 81241 | W19: 76895 | X19: 88459 | Y19: 84703 | Z19: 0.94650484 | AA19: 0.95753965 | AB19: -0.011034808
A20: JAKARTA雅加达 | B20: ANDI PRASETIYO | C20: CP_MANGGA_BESAR_2 | D20: 8308 | E20: 7950 | F20: 358 | G20: 8608 | H20: 8387 | I20: 221 | J20: 5406 | K20: 5321 | L20: 85 | M20: 0.93 | N20: 169794 | O20: 165640 | P20: 4154 | Q20: 0.97553506 | R20: 0.956909 | S20: 0.97432621 | T20: 0.98427673 | U20: -0.017417205 | V20: 52861 | W20: 51514 | X20: 53062 | Y20: 51785 | Z20: 0.97451808 | AA20: 0.97593381 | AB20: -0.0014157376
A21: JAKARTA雅加达 | B21: ANDI PRASETIYO | C21: CP_PINANGSIA_RAYA | D21: 3396 | E21: 2971 | F21: 425 | G21: 3061 | H21: 2812 | I21: 249 | J21: 1597 | K21: 1485 | L21: 112 | M21: 0.93 | N21: 67334 | O21: 57753 | P21: 9581 | Q21: 0.85770933 | R21: 0.87485277 | S21: 0.91865403 | T21: 0.9298685 | U21: -0.043801267 | V21: 19595 | W21: 16989 | X21: 20408 | Y21: 18068 | Z21: 0.86700689 | AA21: 0.88533908 | AB21: -0.018332193
