Workbook

Sheet Display ALL DP
B1: ="网管-雅加达网点质量达成 "&TEXT(BB2,"YYYY-MM-DD")&" "&"NM - Pencapaian Kualitas DropPoint Jakarta "&TEXT(BB2,"YYYY-MM-DD") -> 网管-雅加达网点质量达成 2026-09-29 NM - Pencapaian Kualitas DropPoint Jakarta 2026-09-29 | BB1: Date
BB2: =L8 -> 46294 | BC2: =EOMONTH(BB2,-1)+1 -> 46266 | BD2: report kualitas agent | BG2: =COUNTIFS(#REF!,J:J,#REF!,1,#REF!,"<="&#REF!) -> #REF! | BH2: =COUNTIFS(#REF!,J:J,#REF!,1) -> #REF! | BI2: =BG2/BH2 -> #REF!
BB3: =BB2-2 -> 46292 | BC3: =EOMONTH(BB3,-1)+1 -> 46266 | BD3: report ramadan
C4: 定义: 一派质量考核项 1. 快递员出勤准点率 = 当天当地时间06:30前打卡且当日有签收的快递员人数/ 当天已打卡且有签收的快递员人数 2. 0730出仓率 = 0730前出仓量/ 一班应签收量 3. 1200签收率 = 1200前签收量/ 一班应签收量 4. 一班：散货数量,按照散货班次第一班 目标：90% 质量达成 1. 交件准点率: 准点交件票数 / 应交件票数*100% 目标: 93% 2. 全天签收率 = 按规划时效网点当天签收票数/应签收票数 目标：A92%，B90%，C90% 非平台质量 1. 非平台揽收及时率 = (实际揽收及时量 + 揽收失败及时量)/ 订单量 目标：98% 2. 非平台COD退件率 = (退件登记票数 - 退件作废票数) / 派件量 | V4: Penjelasan: Penilaian Kualitas Delivery Ritase Pertama 1. Tingkat Ketepatan Waktu Kehadiran Spirnter = Jumlah sprinter yang melakukan absen sebelum 06.30 waktu setempat dan melakukan TTD/ jumlah sprinter yang melakukan absen dan melakukan TTD 2. Persentase Deliv 7.30 = Total delivery sebelum jam 7.30/ Total Seharusnya TTD Rit 1 3. Persentase TTD 12.00 = Total TTD sebelum jam 1200/ Total seharusnya TTD Rit 1 4. Ritase Pertama: Jumlah penyebaran paket massal kargo Rit 1 Target : 90% Pencapaian Kualitas 1. TPTW = Total kirim tepat waktu / Total seharusnya kirim Target: 93% 2. Persentase TTD = Jumlah TTD Hari H/Jumlah Seharusnya TTD Target: A92%, B90%, C90% Kualitas Non Platform 1. % Pickup Non-ecommerce = (On Time Pick Up + On Time Gagal Pick Up) / Total Order Target : 98% 2. % Retur COD Non-Ecommerce = (Jumlah regis retur - jumlah batal retur)/ jumlah delivery
C6: 代理区 Agent | D6: Fungsi DP | E6: 代理区编码 Kode Agent | F6: 网点代码 Kode DP | G6: 网点 Nama Drop point | H6: Nama agent | J6: 代理区编码 Kode Agent | K6: 一派质量达成 Penilaian Kualitas Delivery Ritase Pertama | Z6: 二派质量达成 Penilaian Kualitas Delivery Ritase Kedua | AE6: 全天收派质量达成 Pencapaian Kualitas Operasional Harian
K7: 快递员出勤准点率 Tingkat Ketepatan Waktu Kehadiran Spirnter | P7: 0730出仓率 Persenase Keluar Gudang 0730 | U7: 1200签收率 Persentase TTD 1200 | Z7: 二派签收率 Persentase TTD Delivery Kedua | AE7: 交件准点率 TPTW | AJ7: 全天签收率 Persentase TTD | AO7: 非平台揽收及时率 % Pickup Non- Ecommerce | AT7: 非平台COD退件率 % Retur COD Non-Ecommerce | BB7: =BB2-1 -> 46293
K8: Target | L8: 46294 | M8: =L8-1 -> 46293 | N8: =L8-2 -> 46292 | O8: 月度达成 Pencapaian Bulanan | P8: Target | Q8: =L8 -> 46294 | R8: =M8 -> 46293 | S8: =N8 -> 46292 | T8: 月度达成 Pencapaian Bulanan | U8: Target | V8: =Q8 -> 46294 | W8: =R8 -> 46293 | X8: =S8 -> 46292 | Y8: 月度达成 Pencapaian Bulanan | Z8: Target | AA8: =V8 -> 46294 | AB8: =W8 -> 46293 | AC8: =X8 -> 46292 | AD8: 月度达成 Pencapaian Bulanan | AE8: Target | AF8: =AA8 -> 46294 | AG8: =AB8 -> 46293 | AH8: =AC8 -> 46292 | AI8: 月度达成 Pencapaian Bulanan | AJ8: Target | AK8: =AF8 -> 46294 | AL8: =AG8 -> 46293 | AM8: =AH8 -> 46292 | AN8: 月度达成 Pencapaian Bulanan | AO8: Target | AP8: =AK8 -> 46294 | AQ8: =AL8 -> 46293 | AR8: =AM8 -> 46292 | AS8: 月度达成 Pencapaian Bulanan | AT8: 目标 Target | AU8: =AP8 -> 46294 | AV8: =AQ8 -> 46293 | AW8: =AR8 -> 46292 | AX8: 月度达成 Pencapaian Bulanan
C9: JAKARTA雅加达 | D9: Pickup Delivery | E9: AGENT40 | F9: JKT41W | G9: CP_PLUIT_PERMAI | H9: CP_PLUIT_PERMAI | I9: CP_PLUIT_PERMAI | J9: CP_PLUIT_PERMAI | K9: 0.9 | L9: 0.88333333 | M9: 0.87755102 | N9: 0.83928571 | O9: 0.89792388 | P9: 0.9 | Q9: 0.97273467 | R9: 0.9931986 | S9: 0.99477646 | T9: 0.95058141 | U9: 0.9 | V9: 0.80059685 | W9: 0.86280606 | X9: 0.76048548 | Y9: 0.73393152 | Z9: 0.92 | AA9: 0.89898459 | AB9: 0.94573955 | AC9: 0.88121272 | AD9: 0.91640581 | AE9: 0.92 | AF9: 0.99581729 | AG9: 0.94018136 | AH9: 0.93948345 | AI9: 0.96323125 | AJ9: 0.92 | AK9: 0.92622263 | AL9: 0.95565149 | AM9: 0.91850095 | AN9: 0.93724547 | AO9: 0.99 | AP9: 1 | AQ9: 1 | AR9: 1 | AS9: 1 | AT9: 0.08721821 | AU9: 0.03030303 | AV9: 0 | AW9: 0.10344828 | AX9: 0.049281314
C10: JAKARTA雅加达 | D10: Pickup Delivery | E10: AGENT40 | F10: JKT43D | G10: CP_DANAUSUNTER_UTARA | H10: CP_DANAUSUNTER_UTARA | I10: CP_DANAUSUNTER_UTARA | J10: CP_DANAUSUNTER_UTARA | K10: 0.9 | L10: 0.92436975 | M10: 0.88118812 | N10: 0.89320388 | O10: 0.88345411 | P10: 0.9 | Q10: 1.0268256 | R10: 1.0075298 | S10: 1.0716947 | T10: 1.0678284 | U10: 0.9 | V10: 0.88348462 | W10: 0.89715335 | X10: 0.88984946 | Y10: 0.87039997 | Z10: 0.92 | AA10: 0.92763053 | AB10: 0.94879725 | AC10: 0.93536041 | AD10: 0.96015341 | AE10: 0.92 | AF10: 0.99766684 | AG10: 0.97239679 | AH10: 0.98293129 | AI10: 0.99256873 | AJ10: 0.92 | AK10: 0.94077642 | AL10: 0.95449335 | AM10: 0.95797065 | AN10: 0.96897284 | AO10: 0.99 | AP10: 1 | AQ10: 1 | AR10: 1 | AS10: 1 | AT10: 0.08721821 | AU10: 0.020833333 | AV10: 0.064516129 | AW10: 0.014492754 | AX10: 0.05388941
C11: JAKARTA雅加达 | D11: Pickup Delivery | E11: AGENT40 | F11: JKT08L | G11: KAMAL_MUARA | H11: KAMAL_MUARA | I11: KAMAL_MUARA | J11: KAMAL_MUARA | K11: 0.9 | L11: 0.90322581 | M11: 0.96 | N11: 0.96153846 | O11: 0.92839806 | P11: 0.9 | Q11: 0.995149 | R11: 0.99763965 | S11: 0.99204455 | T11: 0.94789676 | U11: 0.9 | V11: 0.88704089 | W11: 0.90637293 | X11: 0.90930788 | Y11: 0.88715451 | Z11: 0.92 | AA11: 0.9333796 | AB11: 0.9279661 | AC11: 0.9533404 | AD11: 0.94807407 | AE11: 0.92 | AF11: 0.99507112 | AG11: 0.96488369 | AH11: 0.95518207 | AI11: 0.94992173 | AJ11: 0.92 | AK11: 0.94258042 | AL11: 0.95530086 | AM11: 0.95820082 | AN11: 0.96270497 | AO11: 0.99 | AP11: 1 | AQ11: 1 | AR11: 1 | AS11: 1 | AT11: 0.08721821 | AU11: 0.090909091 | AV11: 0 | AW11: 0 | AX11: 0.034810127
C12: JAKARTA雅加达 | D12: Pickup Delivery | E12: AGENT40 | F12: JKT08I | G12: TELUK_GONG | H12: TELUK_GONG | I12: TELUK_GONG | J12: TELUK_GONG | K12: 0.9 | L12: 0.91735537 | M12: 0.94339623 | N12: 0.94117647 | O12: 0.92059629 | P12: 0.9 | Q12: 0.99163582 | R12: 0.87773488 | S12: 0.97713346 | T12: 0.94993301 | U12: 0.9 | V12: 0.90278349 | W12: 0.86964516 | X12: 0.8636975 | Y12: 0.8633913 | Z12: 0.92 | AA12: 0.94943639 | AB12: 0.91773676 | AC12: 0.95428696 | AD12: 0.97321782 | AE12: 0.92 | AF12: 0.98499166 | AG12: 0.96533333 | AH12: 0.95961003 | AI12: 0.93750852 | AJ12: 0.92 | AK12: 0.96128121 | AL12: 0.93955031 | AM12: 0.956948 | AN12: 0.9783483 | AO12: 0.99 | AP12: 1 | AQ12: 1 | AR12: 1 | AS12: 1 | AT12: 0.08721821 | AU12: 0.020833333 | AV12: 0.069767442 | AW12: 0.039215686 | AX12: 0.066760365
C13: JAKARTA雅加达 | D13: Pickup Delivery | E13: AGENT40 | F13: JKT41T | G13: CP_TELUK_GONG_RAYA | H13: CP_TELUK_GONG_RAYA | I13: CP_TELUK_GONG_RAYA | J13: CP_TELUK_GONG_RAYA | K13: 0.9 | L13: 0.88461538 | M13: 0.93333333 | N13: 0.93333333 | O13: 0.89906417 | P13: 0.9 | Q13: 0.970237 | R13: 0.86728395 | S13: 0.96836862 | T13: 0.96040278 | U13: 0.9 | V13: 0.93955539 | W13: 0.9510582 | X13: 0.91855542 | Y13: 0.93755608 | Z13: 0.92 | AA13: 0.97512195 | AB13: 0.98648649 | AC13: 0.97168476 | AD13: 0.95912016 | AE13: 0.92 | AF13: 0.93773637 | AG13: 0.90523125 | AH13: 0.9981598 | AI13: 0.96753164 | AJ13: 0.92 | AK13: 0.97840826 | AL13: 0.99121125 | AM13: 0.97672147 | AN13: 0.97449859 | AO13: 0.99 | AP13: 1 | AQ13: 1 | AR13: 1 | AS13: 1 | AT13: 0.08721821 | AU13: 0 | AV13: 0 | AW13: 0.041666667 | AX13: 0.038718291
C14: JAKARTA雅加达 | D14: Pickup Delivery | E14: AGENT40 | F14: JKT30A | G14: CP_PADEMANGAN_4 | H14: CP_PADEMANGAN_4 | I14: CP_PADEMANGAN_4 | J14: CP_PADEMANGAN_4 | K14: 0.9 | L14: - | M14: - | N14: - | O14: - | P14: 0.9 | Q14: - | R14: - | S14: - | T14: 0.38888889 | U14: 0.9 | V14: - | W14: - | X14: - | Y14: 0.94444444 | Z14: 0.92 | AA14: - | AB14: - | AC14: - | AD14: 1 | AE14: 0.92 | AF14: - | AG14: - | AH14: - | AI14: 0.99639617 | AJ14: 0.92 | AK14: - | AL14: - | AM14: - | AN14: 0.96774194 | AO14: 0.99 | AP14: - | AQ14: - | AR14: - | AS14: 1 | AT14: 0.08721821 | AU14: - | AV14: - | AW14: - | AX14: -
C15: JAKARTA雅加达 | D15: Pickup Delivery | E15: AGENT40 | F15: JKT43Q | G15: CP_ANCOL_SELATAN_1 | H15: CP_ANCOL_SELATAN_1 | I15: CP_ANCOL_SELATAN_1 | J15: CP_ANCOL_SELATAN_1 | K15: 0.9 | L15: 1 | M15: 0.99130435 | N15: 0.98198198 | O15: 0.98836549 | P15: 0.9 | Q15: 1.0043437 | R15: 0.99907113 | S15: 1.0071109 | T15: 0.99327666 | U15: 0.9 | V15: 0.93418319 | W15: 0.9336518 | X15: 0.91761479 | Y15: 0.92586382 | Z15: 0.92 | AA15: 0.94147833 | AB15: 0.96141844 | AC15: 0.95059975 | AD15: 0.9652336 | AE15: 0.92 | AF15: 0.98518911 | AG15: 0.99437572 | AH15: 0.99692726 | AI15: 0.99306436 | AJ15: 0.92 | AK15: 0.95880489 | AL15: 0.97463476 | AM15: 0.96695323 | AN15: 0.97718191 | AO15: 0.99 | AP15: 1 | AQ15: 1 | AR15: 1 | AS15: 1 | AT15: 0.08721821 | AU15: 0 | AV15: 0 | AW15: 0.013157895 | AX15: 0.026188835
C16: JAKARTA雅加达 | D16: Pickup Delivery | E16: AGENT40 | F16: JKT08C | G16: KEPULAUAN_SERIBU | H16: KEPULAUAN_SERIBU | I16: KEPULAUAN_SERIBU | J16: KEPULAUAN_SERIBU | K16: 0.9 | L16: 0.94117647 | M16: 0.96428571 | N16: 0.96428571 | O16: 0.96103896 | P16: 0.9 | Q16: 1.002609 | R16: 1.0008022 | S16: 0.99894143 | T16: 0.9702088 | U16: 0.9 | V16: 0.98770034 | W16: 0.99237866 | X16: 0.99470713 | Y16: 0.96240169 | Z16: 0.92 | AA16: 0 | AB16: - | AC16: - | AD16: 0 | AE16: 0.92 | AF16: 0.33333333 | AG16: 0.55555556 | AH16: 0 | AI16: 0.49785408 | AJ16: 0.92 | AK16: 0.9877551 | AL16: 0.99679616 | AM16: 0.9968321 | AN16: 0.99476596 | AO16: 0.99 | AP16: 1 | AQ16: 1 | AR16: 1 | AS16: 1 | AT16: 0.08721821 | AU16: 0 | AV16: 0 | AW16: 0 | AX16: 0.058219178
C17: JAKARTA雅加达 | D17: Pickup Delivery | E17: AGENT40 | F17: JKT11 | G17: TANAH_ABANG | H17: TANAH_ABANG | I17: TANAH_ABANG | J17: TANAH_ABANG | K17: 0.9 | L17: 0.95652174 | M17: 0.85555556 | N17: 0.87671233 | O17: 0.88764464 | P17: 0.9 | Q17: 1.0830996 | R17: 1.1492777 | S17: 1.2635779 | T17: 1.1586802 | U17: 0.9 | V17: 0.83345021 | W17: 0.84077047 | X17: 0.66814454 | Y17: 0.84337799 | Z17: 0.92 | AA17: 0.83874829 | AB17: 0.89127838 | AC17: 0.63598435 | AD17: 0.87348986 | AE17: 0.92 | AF17: 0.99777679 | AG17: 0.99232566 | AH17: 0.99271592 | AI17: 0.98638273 | AJ17: 0.92 | AK17: 0.87781271 | AL17: 0.91742597 | AM17: 0.69888437 | AN17: 0.89894393 | AO17: 0.99 | AP17: 1 | AQ17: 1 | AR17: 1 | AS17: 1 | AT17: 0.08721821 | AU17: 0.041666667 | AV17: 0.055555556 | AW17: 0.078125 | AX17: 0.046610169
C18: JAKARTA雅加达 | D18: Pickup Delivery | E18: AGENT40 | F18: JKT12 | G18: SENEN | H18: SENEN | I18: SENEN | J18: SENEN | K18: 0.9 | L18: 0.95833333 | M18: 0.97321429 | N18: 0.9537037 | O18: 0.97767333 | P18: 0.9 | Q18: 1.0430967 | R18: 1.0488467 | S18: 1.0780347 | T18: 1.0444271 | U18: 0.9 | V18: 0.90909091 | W18: 0.91406603 | X18: 0.84469121 | Y18: 0.92964525 | Z18: 0.92 | AA18: 0.93074167 | AB18: 0.9208135 | AC18: 0.86476726 | AD18: 0.93523362 | AE18: 0.92 | AF18: 0.99583333 | AG18: 0.98096102 | AH18: 0.99038462 | AI18: 0.98083518 | AJ18: 0.92 | AK18: 0.94418843 | AL18: 0.94447633 | AM18: 0.87787771 | AN18: 0.95290977 | AO18: 0.99 | AP18: 1 | AQ18: 1 | AR18: 1 | AS18: 1 | AT18: 0.08721821 | AU18: 0.032258065 | AV18: 0.046875 | AW18: 0.041666667 | AX18: 0.058872651
C19: JAKARTA雅加达 | D19: Pickup Delivery | E19: AGENT40 | F19: JKT45I | G19: CP_PINANGSIA_RAYA | H19: CP_PINANGSIA_RAYA | I19: CP_PINANGSIA_RAYA | J19: CP_PINANGSIA_RAYA | K19: 0.9 | L19: 0.875 | M19: 0.8125 | N19: 0.63636364 | O19: 0.80670611 | P19: 0.9 | Q19: 0.98343457 | R19: 1.0246508 | S19: 1.014571 | T19: 0.94896279 | U19: 0.9 | V19: 0.77636665 | W19: 0.68693509 | X19: 0.38478144 | Y19: 0.67146878 | Z19: 0.92 | AA19: 0.86182519 | AB19: 0.92765957 | AC19: 0.45275591 | AD19: 0.80762053 | AE19: 0.92 | AF19: 0.995366 | AG19: 0.99239977 | AH19: 0.996878 | AI19: 0.99441521 | AJ19: 0.92 | AK19: 0.92273666 | AL19: 0.94297235 | AM19: 0.57948718 | AN19: 0.85704075 | AO19: 0.99 | AP19: 1 | AQ19: 1 | AR19: 1 | AS19: 1 | AT19: 0.08721821 | AU19: 0 | AV19: 0.1 | AW19: 0.2 | AX19: 0.061320755
C20: JAKARTA雅加达 | D20: Pickup Delivery | E20: AGENT40 | F20: JKT13K | G20: JOHAR_BARU_01 | H20: JOHAR_BARU_01 | I20: JOHAR_BARU_01 | J20: JOHAR_BARU_01 | K20: 0.9 | L20: 0.9516129 | M20: 0.96491228 | N20: 0.91525424 | O20: 0.93721591 | P20: 0.9 | Q20: 1.0318915 | R20: 1.0504056 | S20: 1.0588117 | T20: 1.0595896 | U20: 0.9 | V20: 0.90359238 | W20: 0.93366165 | X20: 0.92773986 | Y20: 0.93304044 | Z20: 0.92 | AA20: 0.91405365 | AB20: 0.93731778 | AC20: 0.90187627 | AD20: 0.94538138 | AE20: 0.92 | AF20: 0.9894775 | AG20: 0.99530201 | AH20: 0.9728 | AI20: 0.97906574 | AJ20: 0.92 | AK20: 0.93568105 | AL20: 0.95450553 | AM20: 0.93666523 | AN20: 0.96241282 | AO20: 0.99 | AP20: 1 | AQ20: 1 | AR20: 1 | AS20: 1 | AT20: 0.08721821 | AU20: 0 | AV20: 0 | AW20: 0.038461538 | AX20: 0.05879422
C21: JAKARTA雅加达 | D21: Pickup Delivery | E21: AGENT40 | F21: JKT45L | G21: CP_ZAINUL_ARIFIN | H21: CP_ZAINUL_ARIFIN | I21: CP_ZAINUL_ARIFIN | J21: CP_ZAINUL_ARIFIN | K21: 0.9 | L21: 0.8125 | M21: 0.875 | N21: 0.58823529 | O21: 0.88888889 | P21: 0.9 | Q21: 0.95614482 | R21: 0.96251768 | S21: 0.93428723 | T21: 0.97326203 | U21: 0.9 | V21: 0.87149414 | W21: 0.91089109 | X21: 0.8335983 | Y21: 0.85078854 | Z21: 0.92 | AA21: 0.89709172 | AB21: 0.95638126 | AC21: 0.91506572 | AD21: 0.91624277 | AE21: 0.92 | AF21: 0.9924876 | AG21: 0.9858662 | AH21: 0.99795918 | AI21: 0.97332497 | AJ21: 0.92 | AK21: 0.93742443 | AL21: 0.96851943 | AM21: 0.933287 | AN21: 0.95177828 | AO21: 0.99 | AP21: 1 | AQ21: 1 | AR21: 1 | AS21: 1 | AT21: 0.08721821 | AU21: 0.2 | AV21: 0 | AW21: 0.25 | AX21: 0.10555556
C22: JAKARTA雅加达 | D22: Pickup Delivery | E22: AGENT40 | F22: JKT45B | G22: CP_MANGGA_BESAR_2 | H22: CP_MANGGA_BESAR_2 | I22: CP_MANGGA_BESAR_2 | J22: CP_MANGGA_BESAR_2 | K22: 0.9 | L22: 0.86956522 | M22: 0.88636364 | N22: 0.86046512 | O22: 0.90436113 | P22: 0.9 | Q22: 0.97209821 | R22: 0.85114991 | S22: 0.98146109 | T22: 0.92612761 | U22: 0.9 | V22: 0.93973214 | W22: 0.92078365 | X22: 0.93906021 | Y22: 0.89975421 | Z22: 0.92 | AA22: 0.93545256 | AB22: 0.97189257 | AC22: 0.96707472 | AD22: 0.9592248 | AE22: 0.92 | AF22: 0.99661296 | AG22: 0.99090664 | AH22: 0.99844479 | AI22: 0.98953718 | AJ22: 0.92 | AK22: 0.96294331 | AL22: 0.98365598 | AM22: 0.98274319 | AN22: 0.97562024 | AO22: 0.99 | AP22: 1 | AQ22: 1 | AR22: 1 | AS22: 1 | AT22: 0.08721821 | AU22: 0.041666667 | AV22: 0.083333333 | AW22: 0.041666667 | AX22: 0.093913043
C23: JAKARTA雅加达 | D23: Pickup Delivery | E23: AGENT40 | F23: JKT53C | G23: CP_CEGER | H23: CP_CEGER | I23: CP_CEGER | J23: CP_CEGER | K23: 0.9 | L23: 0.89820359 | M23: 0.81818182 | N23: 0.78030303 | O23: 0.88200238 | P23: 0.9 | Q23: 0.80699568 | R23: 0.82258065 | S23: 0.80255247 | T23: 0.83512925 | U23: 0.9 | V23: 0.72981057 | W23: 0.75654511 | X23: 0.74707309 | Y23: 0.68693279 | Z23: 0.92 | AA23: 0.94058005 | AB23: 0.99257196 | AC23: 0.98653637 | AD23: 0.96060357 | AE23: 0.92 | AF23: 0.76298348 | AG23: 0.73758683 | AH23: 0.85579642 | AI23: 0.7695871 | AJ23: 0.92 | AK23: 0.93315209 | AL23: 0.99374416 | AM23: 0.99119756 | AN23: 0.96957568 | AO23: 0.99 | AP23: 1 | AQ23: 1 | AR23: 1 | AS23: 1 | AT23: 0.08721821 | AU23: 0.068627451 | AV23: 0.012345679 | AW23: 0.011363636 | AX23: 0.051964512
C24: JAKARTA雅加达 | D24: Pickup Delivery | E24: AGENT40 | F24: JKT18N | G24: KAMPUNG_TENGAH | H24: KAMPUNG_TENGAH | I24: KAMPUNG_TENGAH | J24: KAMPUNG_TENGAH | K24: 0.9 | L24: 0.88435374 | M24: 0.86178862 | N24: 0.86507937 | O24: 0.88840049 | P24: 0.9 | Q24: 0.99794013 | R24: 0.99731484 | S24: 0.99482445 | T24: 0.97638486 | U24: 0.9 | V24: 0.76283988 | W24: 0.73215484 | X24: 0.69030634 | Y24: 0.7041255 | Z24: 0.92 | AA24: 0.88490305 | AB24: 0.8693609 | AC24: 0.87668394 | AD24: 0.89208526 | AE24: 0.92 | AF24: 0.93304451 | AG24: 0.99862417 | AH24: 0.99628713 | AI24: 0.97037372 | AJ24: 0.92 | AK24: 0.90891553 | AL24: 0.90954545 | AM24: 0.90664663 | AN24: 0.92341155 | AO24: 0.99 | AP24: 1 | AQ24: 1 | AR24: 1 | AS24: 1 | AT24: 0.08721821 | AU24: 0.085714286 | AV24: 0.048387097 | AW24: 0.0125 | AX24: 0.062893082
C25: JAKARTA雅加达 | D25: Pickup Delivery | E25: AGENT40 | F25: JKT61C | G25: CP_CIJANTUNG | H25: CP_CIJANTUNG | I25: CP_CIJANTUNG | J25: CP_CIJANTUNG | K25: 0.9 | L25: 0.91743119 | M25: 0.95121951 | N25: 0.94252874 | O25: 0.94019471 | P25: 0.9 | Q25: 0.96754493 | R25: 1.0212465 | S25: 1.0406945 | T25: 1.0420789 | U25: 0.9 | V25: 0.88309196 | W25: 0.86033994 | X25: 0.86724543 | Y25: 0.86967702 | Z25: 0.92 | AA25: 0.91094554 | AB25: 0.89538808 | AC25: 0.90462351 | AD25: 0.92243526 | AE25: 0.92 | AF25: 0.99878419 | AG25: 0.99718116 | AH25: 0.99671207 | AI25: 0.99119662 | AJ25: 0.92 | AK25: 0.93099577 | AL25: 0.92552995 | AM25: 0.9262278 | AN25: 0.94539255 | AO25: 0.99 | AP25: 1 | AQ25: 1 | AR25: 1 | AS25: 1 | AT25: 0.08721821 | AU25: 0.057471264 | AV25: 0.041666667 | AW25: 0.037037037 | AX25: 0.042562339
C26: JAKARTA雅加达 | D26: Pickup Delivery | E26: AGENT40 | F26: JKT20J | G26: DC_MAKASAR | H26: DC_MAKASAR | I26: DC_MAKASAR | J26: DC_MAKASAR | K26: 0.9 | L26: 0.92380952 | M26: 0.90804598 | N26: 0.91397849 | O26: 0.93030303 | P26: 0.9 | Q26: 0.99506086 | R26: 0.98423485 | S26: 0.98463932 | T26: 0.90706856 | U26: 0.9 | V26: 0.75939319 | W26: 0.78472411 | X26: 0.75442349 | Y26: 0.71800137 | Z26: 0.92 | AA26: 0.90102078 | AB26: 0.87942029 | AC26: 0.87101099 | AD26: 0.91410936 | AE26: 0.92 | AF26: 0.99924116 | AG26: 0.99807163 | AH26: 0.99884925 | AI26: 0.99739973 | AJ26: 0.92 | AK26: 0.92346209 | AL26: 0.92045035 | AM26: 0.91267162 | AN26: 0.93867201 | AO26: 0.99 | AP26: 1 | AQ26: 1 | AR26: 1 | AS26: 1 | AT26: 0.08721821 | AU26: 0.05 | AV26: 0.019230769 | AW26: 0.047619048 | AX26: 0.04058876
C27: JAKARTA雅加达 | D27: Pickup Delivery | E27: AGENT40 | F27: JKT19K | G27: DC_CIRACAS | H27: DC_CIRACAS | I27: DC_CIRACAS | J27: DC_CIRACAS | K27: 0.9 | L27: 0.95283019 | M27: 0.94186047 | N27: 0.90909091 | O27: 0.95053763 | P27: 0.9 | Q27: 0.96361607 | R27: 0.95657938 | S27: 0.96991067 | T27: 0.95666206 | U27: 0.9 | V27: 0.88526786 | W27: 0.86973815 | X27: 0.84743771 | Y27: 0.88401288 | Z27: 0.92 | AA27: 0.9265233 | AB27: 0.90867925 | AC27: 0.92647533 | AD27: 0.94540252 | AE27: 0.92 | AF27: 0.96491228 | AG27: 0.625 | AH27: 0.69565217 | AI27: 0.82238443 | AJ27: 0.92 | AK27: 0.94752121 | AL27: 0.94725933 | AM27: 0.94851243 | AN27: 0.96507177 | AO27: 0.99 | AP27: 1 | AQ27: 1 | AR27: 1 | AS27: 1 | AT27: 0.08721821 | AU27: 0.033333333 | AV27: 0.019230769 | AW27: 0.054054054 | AX27: 0.062253743
C28: JAKARTA雅加达 | D28: Pickup Delivery | E28: AGENT40 | F28: JKT47C | G28: CP_RAYA_KELAPA | H28: CP_RAYA_KELAPA | I28: CP_RAYA_KELAPA | J28: CP_RAYA_KELAPA | K28: 0.9 | L28: 1 | M28: 0.97916667 | N28: 1 | O28: 0.98206278 | P28: 0.9 | Q28: 0.77975086 | R28: 0.96538751 | S28: 0.98555483 | T28: 0.96590176 | U28: 0.9 | V28: 0.89875431 | W28: 0.87509406 | X28: 0.88542351 | Y28: 0.89808266 | Z28: 0.92 | AA28: 0.9475819 | AB28: 0.96236559 | AC28: 0.94273545 | AD28: 0.96057205 | AE28: 0.92 | AF28: 0.99912587 | AG28: 0.99104287 | AH28: 0.99443801 | AI28: 0.99401934 | AJ28: 0.92 | AK28: 0.95975942 | AL28: 0.96505971 | AM28: 0.9607426 | AN28: 0.97252524 | AO28: 0.99 | AP28: 1 | AQ28: 1 | AR28: 1 | AS28: 1 | AT28: 0.08721821 | AU28: 0.035714286 | AV28: 0.12121212 | AW28: 0 | AX28: 0.066666667
C29: JAKARTA雅加达 | D29: Pickup Delivery | E29: AGENT40 | F29: JKT50K | G29: CP_PONDOK_BAMBU | H29: CP_PONDOK_BAMBU | I29: CP_PONDOK_BAMBU | J29: CP_PONDOK_BAMBU | K29: 0.9 | L29: 0.85074627 | M29: 0.92592593 | N29: 0.84482759 | O29: 0.91176471 | P29: 0.9 | Q29: 0.98087739 | R29: 0.96673307 | S29: 0.98056191 | T29: 0.96477715 | U29: 0.9 | V29: 0.9034027 | W29: 0.94043825 | X29: 0.88565828 | Y29: 0.90193109 | Z29: 0.92 | AA29: 0.94370022 | AB29: 0.98783359 | AC29: 0.97427653 | AD29: 0.9731459 | AE29: 0.92 | AF29: 0.94508858 | AG29: 0.92826905 | AH29: 0.99082995 | AI29: 0.96153823 | AJ29: 0.92 | AK29: 0.96192131 | AL29: 0.98837824 | AM29: 0.98236367 | AN29: 0.98138577 | AO29: 0.99 | AP29: 1 | AQ29: 1 | AR29: 1 | AS29: 1 | AT29: 0.08721821 | AU29: 0.013513514 | AV29: 0.014084507 | AW29: 0 | AX29: 0.019887592
C30: JAKARTA雅加达 | D30: Pickup Delivery | E30: AGENT40 | F30: JKT17K | G30: DC_JATINEGARA | H30: DC_JATINEGARA | I30: DC_JATINEGARA | J30: DC_JATINEGARA | K30: 0.9 | L30: 0.84375 | M30: 0.88135593 | N30: 0.85245902 | O30: 0.90336134 | P30: 0.9 | Q30: 0.97358705 | R30: 0.98073218 | S30: 0.98108676 | T30: 0.96659297 | U30: 0.9 | V30: 0.86481113 | W30: 0.83911368 | X30: 0.80516361 | Y30: 0.83317847 | Z30: 0.92 | AA30: 0.91213518 | AB30: 0.90928495 | AC30: 0.92660964 | AD30: 0.93576172 | AE30: 0.92 | AF30: 1 | AG30: 0.8 | AH30: 0 | AI30: 0.53932584 | AJ30: 0.92 | AK30: 0.93395116 | AL30: 0.93463835 | AM30: 0.94328412 | AN30: 0.9546272 | AO30: 0.99 | AP30: 1 | AQ30: 1 | AR30: - | AS30: 1 | AT30: 0.08721821 | AU30: 0.019230769 | AV30: 0 | AW30: 0.081081081 | AX30: 0.05635148
C31: JAKARTA雅加达 | D31: Pickup Delivery | E31: AGENT40 | F31: JKT25Q | G31: SETIABUDI | H31: SETIABUDI | I31: SETIABUDI | J31: SETIABUDI | K31: 0.9 | L31: 0.96938776 | M31: 1 | N31: 0.94285714 | O31: 0.97174001 | P31: 0.9 | Q31: 0.99534255 | R31: 1.002881 | S31: 1.0023144 | T31: 0.986728 | U31: 0.9 | V31: 0.92548077 | W31: 0.88360703 | X31: 0.73099519 | Y31: 0.84502027 | Z31: 0.92 | AA31: 0.94162746 | AB31: 0.9356383 | AC31: 0.79622642 | AD31: 0.90711394 | AE31: 0.92 | AF31: 0.99921213 | AG31: 0.99308084 | AH31: 0.99746479 | AI31: 0.99491672 | AJ31: 0.92 | AK31: 0.95911469 | AL31: 0.95590698 | AM31: 0.80654445 | AN31: 0.92775641 | AO31: 0.99 | AP31: 1 | AQ31: 1 | AR31: 1 | AS31: 1 | AT31: 0.08721821 | AU31: 0.056603774 | AV31: 0 | AW31: 0.020408163 | AX31: 0.066894198
C32: JAKARTA雅加达 | D32: Pickup Delivery | E32: AGENT40 | F32: JKT20C | G32: KLENDER | H32: KLENDER | I32: KLENDER | J32: KLENDER | K32: 0.9 | L32: 0.95774648 | M32: 0.85245902 | N32: 0.8852459 | O32: 0.93696848 | P32: 0.9 | Q32: 0.99700843 | R32: 1.0396723 | S32: 1.0024958 | T32: 1.0076713 | U32: 0.9 | V32: 0.88931194 | W32: 0.91332471 | X32: 0.90515807 | Y32: 0.91027731 | Z32: 0.92 | AA32: 0.94053911 | AB32: 0.94192377 | AC32: 0.92585089 | AD32: 0.95507398 | AE32: 0.92 | AF32: 0.9985108 | AG32: 0.99074788 | AH32: 0.9974898 | AI32: 0.99019792 | AJ32: 0.92 | AK32: 0.94861973 | AL32: 0.95886525 | AM32: 0.94071914 | AN32: 0.96593773 | AO32: 0.99 | AP32: 1 | AQ32: 1 | AR32: 1 | AS32: 1 | AT32: 0.08721821 | AU32: 0.016129032 | AV32: 0 | AW32: 0.040816327 | AX32: 0.047385621
C33: JAKARTA雅加达 | D33: Pickup Delivery | E33: AGENT40 | F33: JKT52I | G33: CP_JATINEGARA_BARAT | H33: CP_JATINEGARA_BARAT | I33: CP_JATINEGARA_BARAT | J33: CP_JATINEGARA_BARAT | K33: 0.9 | L33: 0.91549296 | M33: 0.91666667 | N33: 0.81666667 | O33: 0.92288049 | P33: 0.9 | Q33: 0.87726311 | R33: 0.83198708 | S33: 0.8697192 | T33: 0.89116373 | U33: 0.9 | V33: 0.81660005 | W33: 0.86171244 | X33: 0.78143182 | Y33: 0.80730571 | Z33: 0.92 | AA33: 0.91839671 | AB33: 0.94370861 | AC33: 0.85929067 | AD33: 0.94227637 | AE33: 0.92 | AF33: 0.9418999 | AG33: 0.95565309 | AH33: 0.93696011 | AI33: 0.95095815 | AJ33: 0.92 | AK33: 0.92552846 | AL33: 0.94877607 | AM33: 0.90639269 | AN33: 0.95527734 | AO33: 0.99 | AP33: 1 | AQ33: 1 | AR33: 1 | AS33: 1 | AT33: 0.08721821 | AU33: 0.024390244 | AV33: 0.086956522 | AW33: 0 | AX33: 0.072859745
C34: JAKARTA雅加达 | D34: Pickup Delivery | E34: AGENT40 | F34: JKT25 | G34: TEBET | H34: TEBET | I34: TEBET | J34: TEBET | K34: 0.9 | L34: 0.98360656 | M34: 0.96808511 | N34: 0.97979798 | O34: 0.97923563 | P34: 0.9 | Q34: 0.99490121 | R34: 0.99722838 | S34: 0.99705424 | T34: 0.99448684 | U34: 0.9 | V34: 0.89913958 | W34: 0.88913525 | X34: 0.86986657 | Y34: 0.88339288 | Z34: 0.92 | AA34: 0.92730646 | AB34: 0.92289157 | AC34: 0.9057877 | AD34: 0.9353089 | AE34: 0.92 | AF34: 0.99823737 | AG34: 0.98 | AH34: 0.98374512 | AI34: 0.98597469 | AJ34: 0.92 | AK34: 0.94888598 | AL34: 0.95218216 | AM34: 0.93074447 | AN34: 0.95766932 | AO34: 0.99 | AP34: 1 | AQ34: 1 | AR34: 1 | AS34: 1 | AT34: 0.08721821 | AU34: 0.034883721 | AV34: 0.06557377 | AW34: 0.042553191 | AX34: 0.066059226
C35: JAKARTA雅加达 | D35: Pickup Delivery | E35: AGENT40 | F35: JKT50I | G35: CP_HAJI_NAMAN_1 | H35: CP_HAJI_NAMAN_1 | I35: CP_HAJI_NAMAN_1 | J35: CP_HAJI_NAMAN_1 | K35: 0.9 | L35: 0.93333333 | M35: 0.89156627 | N35: 0.93023256 | O35: 0.91291062 | P35: 0.9 | Q35: 0.93116796 | R35: 0.92066861 | S35: 0.94053265 | T35: 0.98910067 | U35: 0.9 | V35: 0.85207001 | W35: 0.86893075 | X35: 0.88234221 | Y35: 0.93076721 | Z35: 0.92 | AA35: 0.91845056 | AB35: 0.96521259 | AC35: 0.95419847 | AD35: 0.94734707 | AE35: 0.92 | AF35: 0.99612606 | AG35: 0.91056223 | AH35: 0.98645541 | AI35: 0.96858683 | AJ35: 0.92 | AK35: 0.93484807 | AL35: 0.97586269 | AM35: 0.96423283 | AN35: 0.96293389 | AO35: 0.99 | AP35: 1 | AQ35: 1 | AR35: 1 | AS35: 0.99952711 | AT35: 0.08721821 | AU35: 0.014492754 | AV35: 0.081632653 | AW35: 0 | AX35: 0.068633353
C36: JAKARTA雅加达 | D36: Pickup Delivery | E36: AGENT40 | F36: JKT16Q | G36: PULOGEBANG_01 | H36: PULOGEBANG_01 | I36: PULOGEBANG_01 | J36: PULOGEBANG_01 | K36: 0.9 | L36: 0.94339623 | M36: 0.95588235 | N36: 0.93006993 | O36: 0.94885599 | P36: 0.9 | Q36: 1 | R36: 1.0637354 | S36: 1.0364618 | T36: 1.027212 | U36: 0.9 | V36: 0.88132082 | W36: 0.89995966 | X36: 0.85639068 | Y36: 0.87724198 | Z36: 0.92 | AA36: 0.92468468 | AB36: 0.92814371 | AC36: 0.91160125 | AD36: 0.93911758 | AE36: 0.92 | AF36: 0.99034749 | AG36: 0.9862543 | AH36: 0.99178645 | AI36: 0.95949063 | AJ36: 0.92 | AK36: 0.9401664 | AL36: 0.9475204 | AM36: 0.93430813 | AN36: 0.95720495 | AO36: 0.99 | AP36: 1 | AQ36: 1 | AR36: 1 | AS36: 1 | AT36: 0.08721821 | AU36: 0.011235955 | AV36: 0 | AW36: 0.10344828 | AX36: 0.053921569
C37: JAKARTA雅加达 | D37: Pickup Delivery | E37: AGENT40 | F37: JKT16O | G37: DC_PULO_GADUNG | H37: DC_PULO_GADUNG | I37: DC_PULO_GADUNG | J37: DC_PULO_GADUNG | K37: 0.9 | L37: - | M37: - | N37: - | O37: - | P37: 0.9 | Q37: - | R37: - | S37: - | T37: - | U37: 0.9 | V37: - | W37: - | X37: - | Y37: - | Z37: 0.92 | AA37: - | AB37: - | AC37: - | AD37: - | AE37: 0.92 | AF37: - | AG37: - | AH37: - | AI37: - | AJ37: 0.92 | AK37: - | AL37: - | AM37: - | AN37: - | AO37: 0.99 | AP37: - | AQ37: - | AR37: - | AS37: - | AT37: 0.08721821 | AU37: - | AV37: - | AW37: - | AX37: -
C38: JAKARTA雅加达 | D38: Pickup Delivery | E38: AGENT40 | F38: JKT10B | G38: ROROTAN | H38: ROROTAN | I38: ROROTAN | J38: ROROTAN | K38: 0.9 | L38: 0.9516129 | M38: 1 | N38: 0.953125 | O38: 0.97803964 | P38: 0.9 | Q38: 1.0331466 | R38: 1.0759124 | S38: 1.0524335 | T38: 1.0600384 | U38: 0.9 | V38: 0.91573296 | W38: 0.94562044 | X38: 0.91595585 | Y38: 0.92267977 | Z38: 0.92 | AA38: 0.91270219 | AB38: 0.92492492 | AC38: 0.9210796 | AD38: 0.93520487 | AE38: 0.92 | AF38: 0.93621127 | AG38: 0.99472119 | AH38: 0.9965366 | AI38: 0.99232537 | AJ38: 0.92 | AK38: 0.92903299 | AL38: 0.94667285 | AM38: 0.94298793 | AN38: 0.95571221 | AO38: 0.99 | AP38: 1 | AQ38: 1 | AR38: 1 | AS38: 1 | AT38: 0.08721821 | AU38: 0 | AV38: 0.125 | AW38: 0 | AX38: 0.065081352
C39: JAKARTA雅加达 | D39: Pickup Delivery | E39: AGENT40 | F39: JKT16R | G39: DC_UJUNG_MENTENG | H39: DC_UJUNG_MENTENG | I39: DC_UJUNG_MENTENG | J39: DC_UJUNG_MENTENG | K39: 0.9 | L39: 0.98214286 | M39: 0.96428571 | N39: 0.96491228 | O39: 0.93506494 | P39: 0.9 | Q39: 1.0166147 | R39: 1.0114763 | S39: 1.0131306 | T39: 1.0247803 | U39: 0.9 | V39: 0.94496366 | W39: 0.9494001 | X39: 0.93849343 | Y39: 0.92113324 | Z39: 0.92 | AA39: 0.9404136 | AB39: 0.96301189 | AC39: 0.94608088 | AD39: 0.95856478 | AE39: 0.92 | AF39: 0.99693878 | AG39: 0.93333333 | AH39: 0.98929336 | AI39: 0.9909337 | AJ39: 0.92 | AK39: 0.95516468 | AL39: 0.97665802 | AM39: 0.95950597 | AN39: 0.97155021 | AO39: 0.99 | AP39: 1 | AQ39: 1 | AR39: 1 | AS39: 1 | AT39: 0.08721821 | AU39: 0 | AV39: 0 | AW39: 0.052631579 | AX39: 0.040221914
C40: JAKARTA雅加达 | D40: Pickup Delivery | E40: AGENT40 | F40: JKT51G | G40: CP_UTAN_KAYU | H40: CP_UTAN_KAYU | I40: CP_UTAN_KAYU | J40: CP_UTAN_KAYU | K40: 0.9 | L40: - | M40: - | N40: - | O40: - | P40: 0.9 | Q40: 0 | R40: 0 | S40: 0 | T40: 0.079245283 | U40: 0.9 | V40: 1 | W40: 1 | X40: 1 | Y40: 0.96981132 | Z40: 0.92 | AA40: 1 | AB40: - | AC40: 1 | AD40: 1 | AE40: 0.92 | AF40: - | AG40: - | AH40: - | AI40: 0.97989759 | AJ40: 0.92 | AK40: 1 | AL40: 1 | AM40: 1 | AN40: 0.98126464 | AO40: 0.99 | AP40: - | AQ40: - | AR40: - | AS40: 1 | AT40: 0.08721821 | AU40: - | AV40: - | AW40: - | AX40: 11
C41: JAKARTA雅加达 | D41: Pickup Delivery | E41: AGENT40 | F41: JKT10H | G41: KALIBARU_01 | H41: KALIBARU_01 | I41: KALIBARU_01 | J41: KALIBARU_01 | K41: 0.9 | L41: 0.96396396 | M41: 0.95876289 | N41: 0.98039216 | O41: 0.96166419 | P41: 0.9 | Q41: 1.003112 | R41: 1.0218103 | S41: 1.0126095 | T41: 1.0120464 | U41: 0.9 | V41: 0.90214385 | W41: 0.90321701 | X41: 0.90420315 | Y41: 0.91459232 | Z41: 0.92 | AA41: 0.94509735 | AB41: 0.94642857 | AC41: 0.95332002 | AD41: 0.95934634 | AE41: 0.92 | AF41: 0.9973096 | AG41: 0.99457995 | AH41: 0.98897312 | AI41: 0.991894 | AJ41: 0.92 | AK41: 0.9578256 | AL41: 0.96457715 | AM41: 0.96568578 | AN41: 0.9734922 | AO41: 0.99 | AP41: 1 | AQ41: 1 | AR41: 1 | AS41: 1 | AT41: 0.08721821 | AU41: 0.04 | AV41: 0.076923077 | AW41: 0 | AX41: 0.042630058
...

Sheet Display Absensi 630
A1: 网管-打卡准点率报表爪哇-巴厘09月28日 NM-Persentase Absensi Tepat Waktu Sprinter Agent Jawa-Bali 28 Sep 2026
A2: 代理区 Agent | B2: RM | C2: 网点代码 Kode DP | D2: 网点名称 Nama DP | E2: 总人数 Total Orang | F2: 打卡人数 Jumlah yang Absensi | G2: 总人数 Total Orang 27/09/2026 | H2: 打卡人数 Jumlah yang Absensi 27/09/2026 | I2: 总人数 Total Orang 26/09/2026 | J2: 打卡人数 Jumlah yang Absensi 26/09/2026 | K2: 目标值 Target | L2: 28日打卡率 Persentase Absensi | O2: 总人数 Total Orang Bulanan | P2: 准点打卡人数 Jumlah Absensi Tepat Waktu Bulanan | Q2: 准点打卡人数 Jumlah Absensi Tepat Waktu | R2: 准点打卡人数 Jumlah Absensi Tepat Waktu 27/09/2026 | S2: 准点打卡人数 Jumlah Absensi Tepat Waktu 26/09/2026 | T2: 月累计 打卡准点率 Persentase Bulanan | U2: 打卡准点率 Persentase Absensi Tepat Waktu | X2: 对比昨天 Perbandingan H-1 | Y2: 总人数 Total Orang Mingguan 22/09/2026 - 28/09/2026 | Z2: 准点打卡人数 Jumlah Absensi Tepat Waktu 22/09/2026 - 28/09/2026 | AA2: 总人数 Total Orang Mingguan 15/09/2026 - 21/09/2026 | AB2: 准点打卡人数 Jumlah Absensi Tepat Waktu 15/09/2026 - 21/09/2026 | AC2: 打卡准点周度率 Persentase Mingguan Absensi Tepat Waktu | AE2: 对比上周 Perbandingan Mingguan
L3: ='Display ALL DP'!L8 -> 46294 | M3: =L3-1 -> 46293 | N3: =L3-2 -> 46292 | U3: =L3 -> 46294 | V3: =L3-1 -> 46293 | W3: =L3-2 -> 46292 | AC3: =TEXT(AK6,"DD MMM")&" - "&TEXT(AK5,"DD MMM") -> 23 Sep - 29 Sep | AD3: =TEXT(AL6,"DD MMM")&" - "&TEXT(AL5,"DD MMM") -> 16 Sep - 22 Sep
E4: 61812 | F4: 59941 | G4: 61909 | H4: 60109 | I4: 60645 | J4: 58827 | K4: 0.9 | L4: 0.9697308 | M4: 0.97092507 | N4: 0.97002226 | O4: 1876093 | P4: 1758317 | Q4: 57621 | R4: 57816 | S4: 56245 | T4: 0.93722273 | U4: 0.93219763 | V4: 0.93388683 | W4: 0.92744662 | X4: -0.0016892024 | Y4: 453292 | Z4: 424568 | AA4: 451386 | AB4: 423079 | AC4: 0.93663246 | AD4: 0.93728871 | AE4: -0.00065624867 | AF4: 5
AK5: =L3 -> 46294 | AL5: =AK6-1 -> 46287
A6: JAKARTA雅加达 | B6: AGISTA PRIYANTONO | C6: JKT07T | D6: DC_SUNTER | E6: 0 | F6: 0 | G6: 0 | H6: 0 | I6: 0 | J6: 0 | K6: 0.9 | L6: 0 | M6: 0 | N6: 0 | O6: 0 | P6: 0 | Q6: 0 | R6: 0 | S6: 0 | T6: 0 | U6: 0 | V6: 0 | W6: 0 | X6: 0 | Y6: 0 | Z6: 0 | AA6: 0 | AB6: 0 | AC6: 0 | AD6: 0 | AE6: 0 | AK6: =L3-6 -> 46288 | AL6: =AK5-13 -> 46281
A7: JAKARTA雅加达 | B7: AGISTA PRIYANTONO | C7: JKT43D | D7: CP_DANAUSUNTER_UTARA | E7: 119 | F7: 114 | G7: 101 | H7: 96 | I7: 103 | J7: 92 | K7: 0.9 | L7: 0.95798319 | M7: 0.95049505 | N7: 0.89320388 | O7: 3312 | P7: 2926 | Q7: 110 | R7: 89 | S7: 92 | T7: 0.88345411 | U7: 0.92436975 | V7: 0.88118812 | W7: 0.89320388 | X7: 0.043181629 | Y7: 787 | Z7: 712 | AA7: 809 | AB7: 715 | AC7: 0.9047014 | AD7: 0.88380717 | AE7: 0.020894228
A8: JAKARTA雅加达 | B8: AGISTA PRIYANTONO | C8: JKT08N | D8: PLUIT_PERMAI | E8: 0 | F8: 0 | G8: 0 | H8: 0 | I8: 0 | J8: 0 | K8: 0.9 | L8: 0 | M8: 0 | N8: 0 | O8: 0 | P8: 0 | Q8: 0 | R8: 0 | S8: 0 | T8: 0 | U8: 0 | V8: 0 | W8: 0 | X8: 0 | Y8: 0 | Z8: 0 | AA8: 0 | AB8: 0 | AC8: 0 | AD8: 0 | AE8: 0 | AK8: 46266
A9: JAKARTA雅加达 | B9: AGISTA PRIYANTONO | C9: JKT41T | D9: CP_TELUK_GONG_RAYA | E9: 52 | F9: 51 | G9: 45 | H9: 43 | I9: 45 | J9: 44 | K9: 0.9 | L9: 0.98076923 | M9: 0.95555556 | N9: 0.97777778 | O9: 1496 | P9: 1345 | Q9: 46 | R9: 42 | S9: 42 | T9: 0.89906417 | U9: 0.88461538 | V9: 0.93333333 | W9: 0.93333333 | X9: -0.048717949 | Y9: 348 | Z9: 328 | AA9: 356 | AB9: 316 | AC9: 0.94252874 | AD9: 0.88764045 | AE9: 0.054888286
A10: JAKARTA雅加达 | B10: AGISTA PRIYANTONO | C10: JKT08C | D10: KEPULAUAN_SERIBU | E10: 17 | F10: 17 | G10: 28 | H10: 28 | I10: 28 | J10: 28 | K10: 0.9 | L10: 1 | M10: 1 | N10: 1 | O10: 770 | P10: 740 | Q10: 16 | R10: 27 | S10: 27 | T10: 0.96103896 | U10: 0.94117647 | V10: 0.96428571 | W10: 0.96428571 | X10: -0.023109244 | Y10: 187 | Z10: 180 | AA10: 191 | AB10: 191 | AC10: 0.96256684 | AD10: 1 | AE10: -0.037433155
A11: JAKARTA雅加达 | B11: AGISTA PRIYANTONO | C11: JKT30A | D11: CP_PADEMANGAN_4 | E11: 0 | F11: 0 | G11: 0 | H11: 0 | I11: 0 | J11: 0 | K11: 0.9 | L11: 0 | M11: 0 | N11: 0 | O11: 0 | P11: 0 | Q11: 0 | R11: 0 | S11: 0 | T11: 0 | U11: 0 | V11: 0 | W11: 0 | X11: 0 | Y11: 0 | Z11: 0 | AA11: 0 | AB11: 0 | AC11: 0 | AD11: 0 | AE11: 0
A12: JAKARTA雅加达 | B12: AGISTA PRIYANTONO | C12: JKT41W | D12: CP_PLUIT_PERMAI | E12: 60 | F12: 56 | G12: 49 | H12: 45 | I12: 56 | J12: 53 | K12: 0.9 | L12: 0.93333333 | M12: 0.91836735 | N12: 0.94642857 | O12: 1734 | P12: 1557 | Q12: 53 | R12: 43 | S12: 47 | T12: 0.89792388 | U12: 0.88333333 | V12: 0.87755102 | W12: 0.83928571 | X12: 0.0057823129 | Y12: 425 | Z12: 373 | AA12: 424 | AB12: 378 | AC12: 0.87764706 | AD12: 0.89150943 | AE12: -0.013862375
A13: JAKARTA雅加达 | B13: AGISTA PRIYANTONO | C13: JKT08I | D13: TELUK_GONG | E13: 121 | F13: 113 | G13: 106 | H13: 100 | I13: 102 | J13: 98 | K13: 0.9 | L13: 0.9338843 | M13: 0.94339623 | N13: 0.96078431 | O13: 3287 | P13: 3026 | Q13: 111 | R13: 100 | S13: 96 | T13: 0.92059629 | U13: 0.91735537 | V13: 0.94339623 | W13: 0.94117647 | X13: -0.026040855 | Y13: 801 | Z13: 735 | AA13: 792 | AB13: 733 | AC13: 0.917603 | AD13: 0.92550505 | AE13: -0.0079020543
A14: JAKARTA雅加达 | B14: AGISTA PRIYANTONO | C14: JKT09A | D14: ANCOL | E14: 85 | F14: 82 | G14: 81 | H14: 73 | I14: 74 | J14: 71 | K14: 0.9 | L14: 0.96470588 | M14: 0.90123457 | N14: 0.95945946 | O14: 2365 | P14: 2174 | Q14: 78 | R14: 56 | S14: 66 | T14: 0.9192389 | U14: 0.91764706 | V14: 0.96296296 | W14: 1.0540541 | X14: -0.045315904 | Y14: 572 | Z14: 508 | AA14: 581 | AB14: 520 | AC14: 0.88811189 | AD14: 0.89500861 | AE14: -0.0068967177
A15: JAKARTA雅加达 | B15: AGISTA PRIYANTONO | C15: JKT43Q | D15: CP_ANCOL_SELATAN_1 | E15: 126 | F15: 126 | G15: 115 | H15: 115 | I15: 111 | J15: 110 | K15: 0.9 | L15: 1 | M15: 1 | N15: 0.99099099 | O15: 3524 | P15: 3483 | Q15: 126 | R15: 114 | S15: 109 | T15: 0.98836549 | U15: 1 | V15: 0.99130435 | W15: 0.98198198 | X15: 0.0086956522 | Y15: 853 | Z15: 841 | AA15: 849 | AB15: 842 | AC15: 0.985932 | AD15: 0.99175501 | AE15: -0.0058230012
A16: JAKARTA雅加达 | B16: AGISTA PRIYANTONO | C16: JKT08L | D16: KAMAL_MUARA | E16: 31 | F16: 29 | G16: 25 | H16: 24 | I16: 26 | J16: 25 | K16: 0.9 | L16: 0.93548387 | M16: 0.96 | N16: 0.96153846 | O16: 824 | P16: 765 | Q16: 28 | R16: 24 | S16: 25 | T16: 0.92839806 | U16: 0.90322581 | V16: 0.96 | W16: 0.96153846 | X16: -0.056774194 | Y16: 196 | Z16: 180 | AA16: 197 | AB16: 185 | AC16: 0.91836735 | AD16: 0.93908629 | AE16: -0.020718947
A17: JAKARTA雅加达 | B17: ANDI PRASETIYO | C17: JKT05L | D17: KOTA_TUA | E17: 0 | F17: 0 | G17: 0 | H17: 0 | I17: 0 | J17: 0 | K17: 0.9 | L17: 0 | M17: 0 | N17: 0 | O17: 0 | P17: 0 | Q17: 0 | R17: 0 | S17: 0 | T17: 0 | U17: 0 | V17: 0 | W17: 0 | X17: 0 | Y17: 0 | Z17: 0 | AA17: 0 | AB17: 0 | AC17: 0 | AD17: 0 | AE17: 0
A18: JAKARTA雅加达 | B18: ANDI PRASETIYO | C18: JKT45I | D18: CP_PINANGSIA_RAYA | E18: 16 | F18: 15 | G18: 16 | H18: 16 | I18: 11 | J18: 11 | K18: 0.9 | L18: 0.9375 | M18: 1 | N18: 1 | O18: 507 | P18: 409 | Q18: 14 | R18: 13 | S18: 7 | T18: 0.80670611 | U18: 0.875 | V18: 0.8125 | W18: 0.63636364 | X18: 0.0625 | Y18: 111 | Z18: 90 | AA18: 128 | AB18: 104 | AC18: 0.81081081 | AD18: 0.8125 | AE18: -0.0016891892
A19: JAKARTA雅加达 | B19: ANDI PRASETIYO | C19: JKT11 | D19: TANAH_ABANG | E19: 92 | F19: 91 | G19: 90 | H19: 85 | I19: 73 | J19: 70 | K19: 0.9 | L19: 0.98913043 | M19: 0.94444444 | N19: 0.95890411 | O19: 2679 | P19: 2378 | Q19: 88 | R19: 77 | S19: 64 | T19: 0.88764464 | U19: 0.95652174 | V19: 0.85555556 | W19: 0.87671233 | X19: 0.10096618 | Y19: 632 | Z19: 572 | AA19: 639 | AB19: 569 | AC19: 0.90506329 | AD19: 0.89045383 | AE19: 0.014609457
A20: JAKARTA雅加达 | B20: ANDI PRASETIYO | C20: JKT45B | D20: CP_MANGGA_BESAR_2 | E20: 46 | F20: 46 | G20: 44 | H20: 44 | I20: 43 | J20: 42 | K20: 0.9 | L20: 1 | M20: 1 | N20: 0.97674419 | O20: 1307 | P20: 1182 | Q20: 40 | R20: 39 | S20: 37 | T20: 0.90436113 | U20: 0.86956522 | V20: 0.88636364 | W20: 0.86046512 | X20: -0.016798419 | Y20: 312 | Z20: 281 | AA20: 317 | AB20: 283 | AC20: 0.90064103 | AD20: 0.89274448 | AE20: 0.0078965461
... A1717: BALI巴厘 | B1717: Prisilia Nansiana Akong | C1717: KOE17 | D1717: KUPANG_TIMUR | E1717: 12 | F1717: 9 | G1717: 12 | H1717: 9 | I1717: 9 | J1717: 7 | K1717: 0.9 | L1717: 0.75 | M1717: 0.75 | N1717: 0.77777778 | O1717: 279 | P1717: 67 | Q1717: 3 | R1717: 4 | S1717: 3 | T1717: 0.24014337 | U1717: 0.25 | V1717: 0.33333333 | W1717: 0.33333333 | X1717: -0.083333333 | Y1717: 73 | Z1717: 16 | AA1717: 64 | AB1717: 19 | AC1717: 0.21917808 | AD1717: 0.296875 | AE1717: -0.077696918

Sheet Display 730 & 1200
A1: 网管-爪哇-巴厘班0730出仓率&1200签收率09月28日 NM-Persentase 0730 & TTD 1200 Agent Jawa-Bali 28 Sep 2026
A2: 代理区 Agent | B2: RM | C2: 网点名称 Kode DP | D2: 网点名称 Nama DP | E2: Rit-1应签收 Seharusnya TTD Rit-1 | F2: 0730出仓率 Persentase Keluar Gudang 0730 | G2: 1200前已签收 TTD Sebelum 1200 | H2: Rit-1应签收 Seharusnya TTD Rit-1 27/09/2026 | I2: 0730出仓率 Persentase Keluar Gudang 0730 27/09/2026 | J2: 1200前已签收 TTD Sebelum 1200 27/09/2026 | K2: Rit-1应签收 Seharusnya TTD Rit-1 26/09/2026 | L2: 0730出仓率 Persentase Keluar Gudang 0730 26/09/2026 | M2: 1200前已签收 TTD Sebelum 1200 26/09/2026 | N2: 月累计签收率 Persentase Bulanan 0730 | O2: 0730出仓率 Persentase Keluar Gudang 0730 Bulanan | P2: 目标值 Target | Q2: 28日0730出仓率 Persentase Keluar Gudang 0730 | T2: 对比昨天 Perbandingan H-1 | U2: Rit-1应签收 Seharusnya TTD Rit-1 Bulanan | V2: 1200前已签收 TTD Sebelum 1200 Bulanan | W2: 月累计签收率 Persentase Bulanan 1200 | X2: 1200前已签收 TTD Sebelum 1200 | AA2: 对比昨天 Perbandingan H-1 | AB2: Rit-1应签收 Seharusnya TTD Rit-1 Mingguan 22/09/2026 - 28/09/2026 | AC2: 1200前已签收 TTD Sebelum 1200 Mingguan 22/09/2026 - 28/09/2026 | AD2: Rit-1应签收 Seharusnya TTD Rit-1 Mingguan 15/09/2026 - 21/09/2026 | AE2: 1200前已签收 TTD Sebelum 1200 Mingguan 15/09/2026 - 21/09/2026 | AF2: 1200前已签收周度率 Persentase Mingguan TTD 1200 | AH2: 对比上周 Perbandingan Mingguan
Q3: ='Display ALL DP'!L8 -> 46294 | R3: =Q3-1 -> 46293 | S3: =Q3-2 -> 46292 | X3: =Q3 -> 46294 | Y3: =R3 -> 46293 | Z3: =S3 -> 46292 | AF3: =TEXT(AN10,"DD MMM")&" - "&TEXT(AN9,"DD MMM") -> 23 Sep - 29 Sep | AG3: =TEXT(AN12,"DD MMM")&" - "&TEXT(AN11,"DD MMM") -> 16 Sep - 22 Sep | AK3: data mingguan harus difix, ga boleh hanya patokan jakarta doang
D4: AGENT40 | E4: 2921042 | F4: 2812015 | G4: 2631220 | H4: 3648365 | I4: 3496823 | J4: 3265545 | K4: 4146878 | L4: 3942869 | M4: 3665936 | N4: 0.95856522 | O4: 111697616 | P4: 0.9 | Q4: 0.96267531 | R4: 0.95846304 | S4: 0.9508042 | T4: 0.004212268 | U4: 116525839 | V4: 104652918 | W4: 0.89810911 | X4: 0.9007813 | Y4: 0.89507081 | Z4: 0.88402311 | AA4: 0.0057104908 | AB4: 27758509 | AC4: 25067009 | AD4: 27538374 | AE4: 24883701 | AF4: 0.90303874 | AG4: 0.90360095 | AH4: -0.00056221304 | AI4: 5
A6: JAKARTA雅加达 | B6: AGISTA PRIYANTONO | C6: JKT07T | D6: DC_SUNTER | E6: 0 | F6: 0 | G6: 0 | H6: 0 | I6: 0 | J6: 0 | K6: 0 | L6: 0 | M6: 0 | N6: 0 | O6: 0 | P6: 0.9 | Q6: 0 | R6: 0 | S6: 0 | T6: 0 | U6: 0 | V6: 0 | W6: 0 | X6: 0 | Y6: 0 | Z6: 0 | AA6: 0 | AB6: 0 | AC6: 0 | AD6: 0 | AE6: 0 | AF6: 0 | AG6: 0 | AH6: 0
A7: JAKARTA雅加达 | B7: AGISTA PRIYANTONO | C7: JKT41W | D7: CP_PLUIT_PERMAI | E7: 7372 | F7: 7171 | G7: 5902 | H7: 5146 | I7: 5111 | J7: 4440 | K7: 6509 | L7: 6475 | M7: 4950 | N7: 0.95058141 | O7: 159653 | P7: 0.9 | Q7: 0.97273467 | R7: 0.9931986 | S7: 0.99477646 | T7: -0.020463929 | U7: 167953 | V7: 123266 | W7: 0.73393152 | X7: 0.80059685 | Y7: 0.86280606 | Z7: 0.76048548 | AA7: -0.06220921 | AB7: 48052 | AC7: 39051 | AD7: 41631 | AE7: 33358 | AF7: 0.81268209 | AG7: 0.80127789 | AH7: 0.011404201
A8: JAKARTA雅加达 | B8: AGISTA PRIYANTONO | C8: JKT08N | D8: PLUIT_PERMAI | E8: 0 | F8: 0 | G8: 0 | H8: 0 | I8: 0 | J8: 0 | K8: 0 | L8: 0 | M8: 0 | N8: 0 | O8: 0 | P8: 0.9 | Q8: 0 | R8: 0 | S8: 0 | T8: 0 | U8: 0 | V8: 0 | W8: 0 | X8: 0 | Y8: 0 | Z8: 0 | AA8: 0 | AB8: 0 | AC8: 0 | AD8: 0 | AE8: 0 | AF8: 0 | AG8: 0 | AH8: 0
A9: JAKARTA雅加达 | B9: AGISTA PRIYANTONO | C9: JKT43D | D9: CP_DANAUSUNTER_UTARA | E9: 7381 | F9: 7579 | G9: 6521 | H9: 5445 | I9: 5486 | J9: 4885 | K9: 6709 | L9: 7190 | M9: 5970 | N9: 1.0678284 | O9: 202393 | P9: 0.9 | Q9: 1.0268256 | R9: 1.0075298 | S9: 1.0716947 | T9: 0.019295789 | U9: 189537 | V9: 164973 | W9: 0.87039997 | X9: 0.88348462 | Y9: 0.89715335 | Z9: 0.88984946 | AA9: -0.013668729 | AB9: 48503 | AC9: 43636 | AD9: 44941 | AE9: 39991 | AF9: 0.89965569 | AG9: 0.88985559 | AH9: 0.009800103 | AM9: =Q3 -> 46294 | AN9: =AM9 -> 46294
A10: JAKARTA雅加达 | B10: AGISTA PRIYANTONO | C10: JKT08I | D10: TELUK_GONG | E10: 7293 | F10: 7232 | G10: 6584 | H10: 5439 | I10: 4774 | J10: 4730 | K10: 6691 | L10: 6538 | M10: 5779 | N10: 0.94993301 | O10: 204911 | P10: 0.9 | Q10: 0.99163582 | R10: 0.87773488 | S10: 0.97713346 | T10: 0.11390094 | U10: 215711 | V10: 186243 | W10: 0.8633913 | X10: 0.90278349 | Y10: 0.86964516 | Z10: 0.8636975 | AA10: 0.033138336 | AB10: 49960 | AC10: 44309 | AD10: 48814 | AE10: 42966 | AF10: 0.88688951 | AG10: 0.8801983 | AH10: 0.0066912078 | AN10: =AN9-6 -> 46288
A11: JAKARTA雅加达 | B11: AGISTA PRIYANTONO | C11: JKT09A | D11: ANCOL | E11: 6492 | F11: 5990 | G11: 5717 | H11: 5189 | I11: 4356 | J11: 4495 | K11: 5752 | L11: 5234 | M11: 5035 | N11: 0.9135768 | O11: 157074 | P11: 0.9 | Q11: 0.92267406 | R11: 0.83946811 | S11: 0.90994437 | T11: 0.083205955 | U11: 171933 | V11: 155557 | W11: 0.9047536 | X11: 0.8806223 | Y11: 0.86625554 | Z11: 0.87534771 | AA11: 0.014366764 | AB11: 42391 | AC11: 38348 | AD11: 39036 | AE11: 36188 | AF11: 0.90462598 | AG11: 0.92704171 | AH11: -0.022415723 | AN11: =AN10-1 -> 46287
A12: JAKARTA雅加达 | B12: AGISTA PRIYANTONO | C12: JKT08L | D12: KAMAL_MUARA | E12: 1443 | F12: 1436 | G12: 1280 | H12: 1271 | I12: 1268 | J12: 1152 | K12: 1257 | L12: 1247 | M12: 1143 | N12: 0.94789676 | O12: 35221 | P12: 0.9 | Q12: 0.995149 | R12: 0.99763965 | S12: 0.99204455 | T12: -0.0024906587 | U12: 37157 | V12: 32964 | W12: 0.88715451 | X12: 0.88704089 | Y12: 0.90637293 | Z12: 0.90930788 | AA12: -0.019332048 | AB12: 9863 | AC12: 8932 | AD12: 10361 | AE12: 9272 | AF12: 0.90560681 | AG12: 0.89489432 | AH12: 0.010712498 | AN12: =AN9-13 -> 46281
A13: JAKARTA雅加达 | B13: AGISTA PRIYANTONO | C13: JKT08C | D13: KEPULAUAN_SERIBU | E13: 2683 | F13: 2690 | G13: 2650 | H13: 2493 | I13: 2495 | J13: 2474 | K13: 2834 | L13: 2831 | M13: 2819 | N13: 0.9702088 | O13: 84381 | P13: 0.9 | Q13: 1.002609 | R13: 1.0008022 | S13: 0.99894143 | T13: 0.0018067735 | U13: 86972 | V13: 83702 | W13: 0.96240169 | X13: 0.98770034 | Y13: 0.99237866 | Z13: 0.99470713 | AA13: -0.0046783248 | AB13: 18780 | AC13: 18654 | AD13: 21101 | AE13: 20744 | AF13: 0.99329073 | AG13: 0.98308137 | AH13: 0.010209364 | AN13: 46266
A14: JAKARTA雅加达 | B14: AGISTA PRIYANTONO | C14: JKT43Q | D14: CP_ANCOL_SELATAN_1 | E14: 10590 | F14: 10636 | G14: 9893 | H14: 7536 | I14: 7529 | J14: 7036 | K14: 9844 | L14: 9914 | M14: 9033 | N14: 0.99327666 | O14: 254696 | P14: 0.9 | Q14: 1.0043437 | R14: 0.99907113 | S14: 1.0071109 | T14: 0.0052725952 | U14: 256420 | V14: 237410 | W14: 0.92586382 | X14: 0.93418319 | Y14: 0.9336518 | Z14: 0.91761479 | AA14: 0.00053138702 | AB14: 68092 | AC14: 63454 | AD14: 61013 | AE14: 56823 | AF14: 0.93188627 | AG14: 0.93132611 | AH14: 0.00056016069
A15: JAKARTA雅加达 | B15: AGISTA PRIYANTONO | C15: JKT41T | D15: CP_TELUK_GONG_RAYA | E15: 5443 | F15: 5281 | G15: 5114 | H15: 4536 | I15: 3934 | J15: 4314 | K15: 4015 | L15: 3888 | M15: 3688 | N15: 0.96040278 | O15: 119889 | P15: 0.9 | Q15: 0.970237 | R15: 0.86728395 | S15: 0.96836862 | T15: 0.10295305 | U15: 124832 | V15: 117037 | W15: 0.93755608 | X15: 0.93955539 | Y15: 0.9510582 | Z15: 0.91855542 | AA15: -0.011502809 | AB15: 33889 | AC15: 32081 | AD15: 31153 | AE15: 29503 | AF15: 0.94664936 | AG15: 0.9470356 | AH15: -0.00038624325
A16: JAKARTA雅加达 | B16: AGISTA PRIYANTONO | C16: JKT30A | D16: CP_PADEMANGAN_4 | E16: 0 | F16: 0 | G16: 0 | H16: 0 | I16: 0 | J16: 0 | K16: 0 | L16: 0 | M16: 0 | N16: 0.38888889 | O16: 7 | P16: 0.9 | Q16: 0 | R16: 0 | S16: 0 | T16: 0 | U16: 18 | V16: 17 | W16: 0.94444444 | X16: 0 | Y16: 0 | Z16: 0 | AA16: 0 | AB16: 0 | AC16: 0 | AD16: 0 | AE16: 0 | AF16: 0 | AG16: 0 | AH16: 0
A17: JAKARTA雅加达 | B17: ANDI PRASETIYO | C17: JKT05L | D17: KOTA_TUA | E17: 0 | F17: 0 | G17: 0 | H17: 0 | I17: 0 | J17: 0 | K17: 0 | L17: 0 | M17: 0 | N17: 0 | O17: 0 | P17: 0.9 | Q17: 0 | R17: 0 | S17: 0 | T17: 0 | U17: 0 | V17: 0 | W17: 0 | X17: 0 | Y17: 0 | Z17: 0 | AA17: 0 | AB17: 0 | AC17: 0 | AD17: 0 | AE17: 0 | AF17: 0 | AG17: 0 | AH17: 0
A18: JAKARTA雅加达 | B18: ANDI PRASETIYO | C18: JKT45I | D18: CP_PINANGSIA_RAYA | E18: 1811 | F18: 1781 | G18: 1406 | H18: 1217 | I18: 1247 | J18: 836 | K18: 1853 | L18: 1880 | M18: 713 | N18: 0.94896279 | O18: 45517 | P18: 0.9 | Q18: 0.98343457 | R18: 1.0246508 | S18: 1.014571 | T18: -0.041216214 | U18: 47965 | V18: 32207 | W18: 0.67146878 | X18: 0.77636665 | Y18: 0.68693509 | Z18: 0.38478144 | AA18: 0.089431562 | AB18: 12342 | AC18: 8680 | AD18: 10937 | AE18: 7707 | AF18: 0.70328958 | AG18: 0.70467221 | AH18: -0.0013826333
A19: JAKARTA雅加达 | B19: ANDI PRASETIYO | C19: JKT11 | D19: TANAH_ABANG | E19: 5704 | F19: 6178 | G19: 4754 | H19: 3115 | I19: 3580 | J19: 2619 | K19: 4511 | L19: 5700 | M19: 3014 | N19: 1.1586802 | O19: 161571 | P19: 0.9 | Q19: 1.0830996 | R19: 1.1492777 | S19: 1.2635779 | T19: -0.066178109 | U19: 139444 | V19: 117604 | W19: 0.84337799 | X19: 0.83345021 | Y19: 0.84077047 | Z19: 0.66814454 | AA19: -0.0073202551 | AB19: 34313 | AC19: 28633 | AD19: 30577 | AE19: 25984 | AF19: 0.83446507 | AG19: 0.84978906 | AH19: -0.015323986
A20: JAKARTA雅加达 | B20: ANDI PRASETIYO | C20: JKT45B | D20: CP_MANGGA_BESAR_2 | E20: 7168 | F20: 6968 | G20: 6736 | H20: 4696 | I20: 3997 | J20: 4324 | K20: 5448 | L20: 5347 | M20: 5116 | N20: 0.92612761 | O20: 117182 | P20: 0.9 | Q20: 0.97209821 | R20: 0.85114991 | S20: 0.98146109 | T20: 0.1209483 | U20: 126529 | V20: 113845 | W20: 0.89975421 | X20: 0.93973214 | Y20: 0.92078365 | Z20: 0.93906021 | AA20: 0.018948497 | AB20: 37478 | AC20: 35039 | AD20: 29584 | AE20: 27294 | AF20: 0.93492182 | AG20: 0.92259329 | AH20: 0.012328527
A21: JAKARTA雅加达 | B21: ANDI PRASETIYO | C21: JKT13K | D21: JOHAR_BARU_01 | E21: 5456 | F21: 5630 | G21: 4930 | H21: 3452 | I21: 3626 | J21: 3223 | K21: 4982 | L21: 5275 | M21: 4622 | N21: 1.0595896 | O21: 148084 | P21: 0.9 | Q21: 1.0318915 | R21: 1.0504056 | S21: 1.0588117 | T21: -0.018514066 | U21: 139756 | V21: 130398 | W21: 0.93304044 | X21: 0.90359238 | Y21: 0.93366165 | Z21: 0.92773986 | AA21: -0.03006927 | AB21: 34268 | AC21: 32011 | AD21: 30792 | AE21: 28892 | AF21: 0.9341368 | AG21: 0.93829566 | AH21: -0.0041588572
A22: JAKARTA雅加达 | B22: ANDI PRASETIYO | C22: JKT12 | D22: SENEN | E22: 7634 | F22: 7963 | G22: 6940 | H22: 4422 | I22: 4638 | J22: 4042 | K22: 6574 | L22: 7087 | M22: 5553 | N22: 1.0444271 | O22: 212449 | P22: 0.9 | Q22: 1.0430967 | R22: 1.0488467 | S22: 1.0780347 | T22: -0.0057500029 | U22: 203412 | V22: 189101 | W22: 0.92964525 | X22: 0.90909091 | Y22: 0.91406603 | Z22: 0.84469121 | AA22: -0.0049751244 | AB22: 47377 | AC22: 43472 | AD22: 45034 | AE22: 42143 | AF22: 0.91757604 | AG22: 0.93580406 | AH22: -0.01822802
A23: JAKARTA雅加达 | B23: ANDI PRASETIYO | C23: JKT45L | D23: CP_ZAINUL_ARIFIN | E23: 1961 | F23: 1875 | G23: 1709 | H23: 1414 | I23: 1361 | J23: 1288 | K23: 1887 | L23: 1763 | M23: 1573 | N23: 0.97326203 | O23: 42952 | P23: 0.9 | Q23: 0.95614482 | R23: 0.96251768 | S23: 0.93428723 | T23: -0.0063728563 | U23: 44132 | V23: 37547 | W23: 0.85078854 | X23: 0.87149414 | Y23: 0.91089109 | Z23: 0.8335983 | AA23: -0.039396953 | AB23: 12519 | AC23: 10898 | AD23: 12209 | AE23: 10899 | AF23: 0.87051681 | AG23: 0.89270211 | AH23: -0.022185291
A24: JAKARTA雅加达 | B24: ARIS YULIANTO | C24: JKT19J | D24: DC_CIPAYUNG | E24: 0 | F24: 0 | G24: 0 | H24: 0 | I24: 0 | J24: 0 | K24: 0 | L24: 0 | M24: 0 | N24: 0 | O24: 0 | P24: 0.9 | Q24: 0 | R24: 0 | S24: 0 | T24: 0 | U24: 0 | V24: 0 | W24: 0 | X24: 0 | Y24: 0 | Z24: 0 | AA24: 0 | AB24: 0 | AC24: 0 | AD24: 0 | AE24: 0 | AF24: 0 | AG24: 0 | AH24: 0
A25: JAKARTA雅加达 | B25: ARIS YULIANTO | C25: JKT19L | D25: KELAPA_DUA_01 | E25: 0 | F25: 0 | G25: 0 | H25: 0 | I25: 0 | J25: 0 | K25: 0 | L25: 0 | M25: 0 | N25: 0 | O25: 0 | P25: 0.9 | Q25: 0 | R25: 0 | S25: 0 | T25: 0 | U25: 0 | V25: 0 | W25: 0 | X25: 0 | Y25: 0 | Z25: 0 | AA25: 0 | AB25: 0 | AC25: 0 | AD25: 0 | AE25: 0 | AF25: 0 | AG25: 0 | AH25: 0
... A1717: BALI巴厘 | B1717: Prisilia Nansiana Akong | C1717: KOE17 | D1717: KUPANG_TIMUR | E1717: 1215 | F1717: 1185 | G1717: 707 | H1717: 1187 | I1717: 1079 | J1717: 737 | K1717: 1098 | L1717: 974 | M1717: 828 | N1717: 0.91681736 | O1717: 11661 | P1717: 0.9 | Q1717: 0.97530864 | R1717: 0.90901432 | S1717: 0.8870674 | T1717: 0.06629432 | U1717: 12719 | V1717: 9217 | W1717: 0.72466389 | X1717: 0.581893 | Y1717: 0.62089301 | Z1717: 0.75409836 | AA1717: -0.039000003 | AB1717: 5206 | AC1717: 3527 | AD1717: 2574 | AE1717: 1917 | AF1717: 0.67748751 | AG1717: 0.74475524 | AH1717: -0.06726773

Sheet Display Ritase Keseluruhan
A1: 网管-爪哇-巴厘班次全天签收率报表09月28日 NM-Laporan Persentase Keseluruhan TTD Berdasarkan Ritase Agent Jawa-Bali 28 Sep 2026
A2: 代理区 Agent | B2: RM | C2: 网点代码 Kode DP | D2: 网点名称 Nama DP | E2: T-1应签收 Seharusnya TTD H-1 | F2: 2359前已签收 TTD Sebelum 2359 | G2: 未签收 Belum TTD | H2: T-1应签收 Seharusnya TTD 27/09/2026 | I2: 2359前已签收 TTD Sebelum 2359 27/09/2026 | J2: 未签收 Belum TTD 27/09/2026 | K2: T-1应签收 Seharusnya TTD 26/09/2026 | L2: 2359前已签收 TTD Sebelum 2359 26/09/2026 | M2: 未签收 Belum TTD 26/09/2026 | N2: 目标值 Target | O2: 累计应签收量 Seharusnya TTD Bulanan | P2: 累计签收量 TTD Bulanan | Q2: 累计未签收 Belum TTD Bulanan | R2: 月累计 签收率 Persentase Bulanan | S2: 全天签收率 Persentase TTD All Ritase | V2: 对比昨天 Perbandingan H-1 | W2: 累计应签收量 Seharusnya TTD Mingguan 22/09/2026 - 28/09/2026 | X2: 累计签收量 TTD Mingguan 22/09/2026 - 28/09/2026 | Y2: 累计应签收量 Seharusnya TTD Mingguan 15/09/2026 - 21/09/2026 | Z2: 累计签收量 TTD Mingguan 15/09/2026 - 21/09/2026 | AA2: 全天签收率周度率 Persentase Mingguan TTD All Ritase | AC2: 对比上周 Perbandingan Mingguan
S3: ='Display ALL DP'!L8 -> 46294 | T3: =S3-1 -> 46293 | U3: =S3-2 -> 46292 | AA3: =TEXT(AH10,"DD MMM")&" - "&TEXT(AH9,"DD MMM") -> 23 Sep - 29 Sep | AB3: =TEXT(AH12,"DD MMM")&" - "&TEXT(AH11,"DD MMM") -> 16 Sep - 22 Sep
E4: 5586838 | F4: 5261886 | G4: 324952 | H4: 5075604 | I4: 4835329 | J4: 240275 | K4: 6476726 | L4: 6093414 | M4: 383312 | N4: 0.93 | O4: 183668764 | P4: 176191772 | Q4: 7476992 | R4: 0.95929089 | S4: 0.94183615 | T4: 0.95266081 | U4: 0.94081701 | V4: -0.010824655 | W4: 43501383 | X4: 41637653 | Y4: 42794231 | Z4: 41133499 | AA4: 0.95715699 | AB4: 0.96119262 | AC4: -0.0040356253 | AD4: 5
A6: JAKARTA雅加达 | B6: AGISTA PRIYANTONO | C6: JKT07T | D6: DC_SUNTER | E6: 0 | F6: 0 | G6: 0 | H6: 0 | I6: 0 | J6: 0 | K6: 0 | L6: 0 | M6: 0 | N6: 0.93 | O6: 0 | P6: 0 | Q6: 0 | R6: 0 | S6: 0 | T6: 0 | U6: 0 | V6: 0 | W6: 0 | X6: 0 | Y6: 0 | Z6: 0 | AA6: 0 | AB6: 0 | AC6: 0
A7: JAKARTA雅加达 | B7: AGISTA PRIYANTONO | C7: JKT09A | D7: ANCOL | E7: 11735 | F7: 11375 | G7: 360 | H7: 6849 | I7: 6490 | J7: 359 | K7: 8878 | L7: 8372 | M7: 506 | N7: 0.93 | O7: 272792 | P7: 267842 | Q7: 4950 | R7: 0.98185431 | S7: 0.96932254 | T7: 0.94758359 | U7: 0.94300518 | V7: 0.021738951 | W7: 66575 | X7: 64738 | Y7: 61813 | Z7: 61039 | AA7: 0.97240706 | AB7: 0.98747836 | AC7: -0.015071302
A8: JAKARTA雅加达 | B8: AGISTA PRIYANTONO | C8: JKT08N | D8: PLUIT_PERMAI | E8: 0 | F8: 0 | G8: 0 | H8: 0 | I8: 0 | J8: 0 | K8: 0 | L8: 0 | M8: 0 | N8: 0.93 | O8: 0 | P8: 0 | Q8: 0 | R8: 0 | S8: 0 | T8: 0 | U8: 0 | V8: 0 | W8: 0 | X8: 0 | Y8: 0 | Z8: 0 | AA8: 0 | AB8: 0 | AC8: 0
A9: JAKARTA雅加达 | B9: AGISTA PRIYANTONO | C9: JKT41W | D9: CP_PLUIT_PERMAI | E9: 13107 | F9: 12140 | G9: 967 | H9: 7644 | I9: 7305 | J9: 339 | K9: 10540 | L9: 9681 | M9: 859 | N9: 0.93 | O9: 280665 | P9: 263052 | Q9: 17613 | R9: 0.93724547 | S9: 0.92622263 | T9: 0.95565149 | U9: 0.91850095 | V9: -0.029428862 | W9: 77577 | X9: 73695 | Y9: 68773 | Z9: 65207 | AA9: 0.9499594 | AB9: 0.94814826 | AC9: 0.0018111393 | AH9: =S3 -> 46294
A10: JAKARTA雅加达 | B10: AGISTA PRIYANTONO | C10: JKT30A | D10: CP_PADEMANGAN_4 | E10: 0 | F10: 0 | G10: 0 | H10: 0 | I10: 0 | J10: 0 | K10: 0 | L10: 0 | M10: 0 | N10: 0.93 | O10: 31 | P10: 30 | Q10: 1 | R10: 0.96774194 | S10: 0 | T10: 0 | U10: 0 | V10: 0 | W10: 0 | X10: 0 | Y10: 1 | Z10: 1 | AA10: 0 | AB10: 1 | AC10: -1 | AH10: =AH9-6 -> 46288
A11: JAKARTA雅加达 | B11: AGISTA PRIYANTONO | C11: JKT08I | D11: TELUK_GONG | E11: 10615 | F11: 10204 | G11: 411 | H11: 8139 | I11: 7647 | J11: 492 | K11: 11730 | L11: 11225 | M11: 505 | N11: 0.93 | O11: 372719 | P11: 364649 | Q11: 8070 | R11: 0.9783483 | S11: 0.96128121 | T11: 0.93955031 | U11: 0.956948 | V11: 0.021730893 | W11: 81522 | X11: 79213 | Y11: 84667 | Z11: 82909 | AA11: 0.97167636 | AB11: 0.9792363 | AC11: -0.0075599449 | AH11: =AH10-1 -> 46287
A12: JAKARTA雅加达 | B12: AGISTA PRIYANTONO | C12: JKT43D | D12: CP_DANAUSUNTER_UTARA | E12: 14116 | F12: 13280 | G12: 836 | H12: 8724 | I12: 8327 | J12: 397 | K12: 12063 | L12: 11556 | M12: 507 | N12: 0.93 | O12: 352691 | P12: 341748 | Q12: 10943 | R12: 0.96897284 | S12: 0.94077642 | T12: 0.95449335 | U12: 0.95797065 | V12: -0.013716928 | W12: 85602 | X12: 82726 | Y12: 81195 | Z12: 79449 | AA12: 0.96640265 | AB12: 0.97849621 | AC12: -0.012093559 | AH12: =AH11-6 -> 46281
A13: JAKARTA雅加达 | B13: AGISTA PRIYANTONO | C13: JKT08C | D13: KEPULAUAN_SERIBU | E13: 2695 | F13: 2662 | G13: 33 | H13: 2497 | I13: 2489 | J13: 8 | K13: 2841 | L13: 2832 | M13: 9 | N13: 0.93 | O13: 87313 | P13: 86856 | Q13: 457 | R13: 0.99476596 | S13: 0.9877551 | T13: 0.99679616 | U13: 0.9968321 | V13: -0.0090410533 | W13: 18839 | X13: 18763 | Y13: 21147 | Z13: 21089 | AA13: 0.99596582 | AB13: 0.99725729 | AC13: -0.0012914786 | AH13: 46266
A14: JAKARTA雅加达 | B14: AGISTA PRIYANTONO | C14: JKT43Q | D14: CP_ANCOL_SELATAN_1 | E14: 19881 | F14: 19062 | G14: 819 | H14: 11157 | I14: 10874 | J14: 283 | K14: 16401 | L14: 15859 | M14: 542 | N14: 0.93 | O14: 439432 | P14: 429405 | Q14: 10027 | R14: 0.97718191 | S14: 0.95880489 | T14: 0.97463476 | U14: 0.96695323 | V14: -0.015829869 | W14: 113379 | X14: 110428 | Y14: 103329 | Z14: 101232 | AA14: 0.97397225 | AB14: 0.9797056 | AC14: -0.0057333482
A15: JAKARTA雅加达 | B15: AGISTA PRIYANTONO | C15: JKT08L | D15: KAMAL_MUARA | E15: 2891 | F15: 2725 | G15: 166 | H15: 1745 | I15: 1667 | J15: 78 | K15: 2201 | L15: 2109 | M15: 92 | N15: 0.93 | O15: 64888 | P15: 62468 | Q15: 2420 | R15: 0.96270497 | S15: 0.94258042 | T15: 0.95530086 | U15: 0.95820082 | V15: -0.012720438 | W15: 16741 | X15: 16069 | Y15: 17184 | Z15: 16630 | AA15: 0.95985903 | AB15: 0.96776071 | AC15: -0.0079016789
A16: JAKARTA雅加达 | B16: AGISTA PRIYANTONO | C16: JKT41T | D16: CP_TELUK_GONG_RAYA | E16: 9587 | F16: 9380 | G16: 207 | H16: 6258 | I16: 6203 | J16: 55 | K16: 6143 | L16: 6000 | M16: 143 | N16: 0.93 | O16: 206067 | P16: 200812 | Q16: 5255 | R16: 0.97449859 | S16: 0.97840826 | T16: 0.99121125 | U16: 0.97672147 | V16: -0.012802988 | W16: 54230 | X16: 53148 | Y16: 51098 | Z16: 49884 | AA16: 0.98004794 | AB16: 0.97624173 | AC16: 0.0038062124
A17: JAKARTA雅加达 | B17: ANDI PRASETIYO | C17: JKT05L | D17: KOTA_TUA | E17: 0 | F17: 0 | G17: 0 | H17: 0 | I17: 0 | J17: 0 | K17: 0 | L17: 0 | M17: 0 | N17: 0.93 | O17: 0 | P17: 0 | Q17: 0 | R17: 0 | S17: 0 | T17: 0 | U17: 0 | V17: 0 | W17: 0 | X17: 0 | Y17: 0 | Z17: 0 | AA17: 0 | AB17: 0 | AC17: 0
A18: JAKARTA雅加达 | B18: ANDI PRASETIYO | C18: JKT11 | D18: TANAH_ABANG | E18: 12088 | F18: 10611 | G18: 1477 | H18: 5268 | I18: 4833 | J18: 435 | K18: 9591 | L18: 6703 | M18: 2888 | N18: 0.93 | O18: 281042 | P18: 252641 | Q18: 28401 | R18: 0.89894393 | S18: 0.87781271 | T18: 0.91742597 | U18: 0.69888437 | V18: -0.039613261 | W18: 66728 | X18: 58903 | Y18: 62264 | Z18: 55990 | AA18: 0.88273289 | AB18: 0.89923551 | AC18: -0.016502628
A19: JAKARTA雅加达 | B19: ANDI PRASETIYO | C19: JKT12 | D19: SENEN | E19: 15624 | F19: 14752 | G19: 872 | H19: 6970 | I19: 6583 | J19: 387 | K19: 12119 | L19: 10639 | M19: 1480 | N19: 0.93 | O19: 364874 | P19: 347692 | Q19: 17182 | R19: 0.95290977 | S19: 0.94418843 | T19: 0.94447633 | U19: 0.87787771 | V19: -0.00028789906 | W19: 84274 | X19: 79679 | Y19: 80214 | Z19: 76495 | AA19: 0.94547547 | AB19: 0.95363652 | AC19: -0.0081610494
A20: JAKARTA雅加达 | B20: ANDI PRASETIYO | C20: JKT45B | D20: CP_MANGGA_BESAR_2 | E20: 11307 | F20: 10888 | G20: 419 | H20: 6302 | I20: 6199 | J20: 103 | K20: 7823 | L20: 7688 | M20: 135 | N20: 0.93 | O20: 207016 | P20: 201969 | Q20: 5047 | R20: 0.97562024 | S20: 0.96294331 | T20: 0.98365598 | U20: 0.98274319 | V20: -0.020712673 | W20: 57205 | X20: 55832 | Y20: 49015 | Z20: 47960 | AA20: 0.9759986 | AB20: 0.97847598 | AC20: -0.0024773752
A21: JAKARTA雅加达 | B21: ANDI PRASETIYO | C21: JKT45I | D21: CP_PINANGSIA_RAYA | E21: 3391 | F21: 3129 | G21: 262 | H21: 1736 | I21: 1637 | J21: 99 | K21: 2925 | L21: 1695 | M21: 1230 | N21: 0.93 | O21: 82548 | P21: 70747 | Q21: 11801 | R21: 0.85704075 | S21: 0.92273666 | T21: 0.94297235 | U21: 0.57948718 | V21: -0.020235694 | W21: 20178 | X21: 17501 | Y21: 19068 | Z21: 16738 | AA21: 0.86733076 | AB21: 0.87780575 | AC21: -0.010474992
A22: JAKARTA雅加达 | B22: ANDI PRASETIYO | C22: JKT45L | D22: CP_ZAINUL_ARIFIN | E22: 3308 | F22: 3101 | G22: 207 | H22: 2033 | I22: 1969 | J22: 64 | K22: 2878 | L22: 2686 | M22: 192 | N22: 0.93 | O22: 69927 | P22: 66555 | Q22: 3372 | R22: 0.95177828 | S22: 0.93742443 | T22: 0.96851943 | U22: 0.933287 | V22: -0.031095004 | W22: 19213 | X22: 18466 | Y22: 18255 | Z22: 17696 | AA22: 0.96112007 | AB22: 0.96937825 | AC22: -0.0082581776
A23: JAKARTA雅加达 | B23: ANDI PRASETIYO | C23: JKT13K | D23: JOHAR_BARU_01 | E23: 10961 | F23: 10256 | G23: 705 | H23: 5693 | I23: 5434 | J23: 259 | K23: 9284 | L23: 8696 | M23: 588 | N23: 0.93 | O23: 260940 | P23: 251132 | Q23: 9808 | R23: 0.96241282 | S23: 0.93568105 | T23: 0.95450553 | U23: 0.93666523 | V23: -0.018824482 | W23: 63059 | X23: 60245 | Y23: 58562 | Z23: 56355 | AA23: 0.95537512 | AB23: 0.96231345 | AC23: -0.0069383207
A24: JAKARTA雅加达 | B24: ARIS YULIANTO | C24: JKT19J | D24: DC_CIPAYUNG | E24: 0 | F24: 0 | G24: 0 | H24: 0 | I24: 0 | J24: 0 | K24: 0 | L24: 0 | M24: 0 | N24: 0.93 | O24: 0 | P24: 0 | Q24: 0 | R24: 0 | S24: 0 | T24: 0 | U24: 0 | V24: 0 | W24: 0 | X24: 0 | Y24: 0 | Z24: 0 | AA24: 0 | AB24: 0 | AC24: 0
A25: JAKARTA雅加达 | B25: ARIS YULIANTO | C25: JKT19L | D25: KELAPA_DUA_01 | E25: 0 | F25: 0 | G25: 0 | H25: 0 | I25: 0 | J25: 0 | K25: 0 | L25: 0 | M25: 0 | N25: 0.93 | O25: 0 | P25: 0 | Q25: 0 | R25: 0 | S25: 0 | T25: 0 | U25: 0 | V25: 0 | W25: 0 | X25: 0 | Y25: 0 | Z25: 0 | AA25: 0 | AB25: 0 | AC25: 0
... A46: JAKARTA雅加达 | B46: DIFA HERDIANSAH MUNABARI | C46: JKT56 | D46: CP_UJUNG_MENTENG | E46: 0 | F46: 0 | G46: 0 | H46: 0 | I46: 0 | J46: 0 | K46: 0 | L46: 0 | M46: 0 | N46: 0.93 | O46: 0 | P46: 0 | Q46: 0 | R46: 0 | S46: 0 | T46: 0 | U46: 0 | V46: 0 | W46: 0 | X46: 0 | Y46: 0 | Z46: 0 | AA46: 0 | AB46: 0 | AC46: 0
A47: JAKARTA雅加达 | B47: DIFA HERDIANSAH MUNABARI | C47: #N/A | D47: CP_PISANGAN_TIMUR_2 | E47: 0 | F47: 0 | G47: 0 | H47: 0 | I47: 0 | J47: 0 | K47: 0 | L47: 0 | M47: 0 | N47: 0.93 | O47: 0 | P47: 0 | Q47: 0 | R47: 0 | S47: 0 | T47: 0 | U47: 0 | V47: 0 | W47: 0 | X47: 0 | Y47: 0 | Z47: 0 | AA47: 0 | AB47: 0 | AC47: 0
