Workbook

Sheet Display ALL DP
B1: ="网管-雅加达网点质量达成 "&TEXT(BB2,"YYYY-MM-DD")&" "&"NM - Pencapaian Kualitas DropPoint Jakarta "&TEXT(BB2,"YYYY-MM-DD") -> 网管-雅加达网点质量达成 2026-09-28 NM - Pencapaian Kualitas DropPoint Jakarta 2026-09-28 | BB1: Date
BB2: =L8 -> 46293 | BC2: =EOMONTH(BB2,-1)+1 -> 46266 | BD2: report kualitas agent | BG2: =COUNTIFS(#REF!,J:J,#REF!,1,#REF!,"<="&#REF!) -> #REF! | BH2: =COUNTIFS(#REF!,J:J,#REF!,1) -> #REF! | BI2: =BG2/BH2 -> #REF!
BB3: =BB2-2 -> 46291 | BC3: =EOMONTH(BB3,-1)+1 -> 46266 | BD3: report ramadan
C4: 定义: 一派质量考核项 1. 快递员出勤准点率 = 当天当地时间06:30前打卡且当日有签收的快递员人数/ 当天已打卡且有签收的快递员人数 2. 0730出仓率 = 0730前出仓量/ 一班应签收量 3. 1200签收率 = 1200前签收量/ 一班应签收量 4. 一班：散货数量,按照散货班次第一班 目标：90% 质量达成 1. 交件准点率: 准点交件票数 / 应交件票数*100% 目标: 93% 2. 全天签收率 = 按规划时效网点当天签收票数/应签收票数 目标：A92%，B90%，C90% 非平台质量 1. 非平台揽收及时率 = (实际揽收及时量 + 揽收失败及时量)/ 订单量 目标：98% 2. 非平台COD退件率 = (退件登记票数 - 退件作废票数) / 派件量 | V4: Penjelasan: Penilaian Kualitas Delivery Ritase Pertama 1. Tingkat Ketepatan Waktu Kehadiran Spirnter = Jumlah sprinter yang melakukan absen sebelum 06.30 waktu setempat dan melakukan TTD/ jumlah sprinter yang melakukan absen dan melakukan TTD 2. Persentase Deliv 7.30 = Total delivery sebelum jam 7.30/ Total Seharusnya TTD Rit 1 3. Persentase TTD 12.00 = Total TTD sebelum jam 1200/ Total seharusnya TTD Rit 1 4. Ritase Pertama: Jumlah penyebaran paket massal kargo Rit 1 Target : 90% Pencapaian Kualitas 1. TPTW = Total kirim tepat waktu / Total seharusnya kirim Target: 93% 2. Persentase TTD = Jumlah TTD Hari H/Jumlah Seharusnya TTD Target: A92%, B90%, C90% Kualitas Non Platform 1. % Pickup Non-ecommerce = (On Time Pick Up + On Time Gagal Pick Up) / Total Order Target : 98% 2. % Retur COD Non-Ecommerce = (Jumlah regis retur - jumlah batal retur)/ jumlah delivery
C6: 代理区 Agent | D6: Fungsi DP | E6: 代理区编码 Kode Agent | F6: 网点代码 Kode DP | G6: 网点 Nama Drop point | H6: Nama agent | J6: 代理区编码 Kode Agent | K6: 一派质量达成 Penilaian Kualitas Delivery Ritase Pertama | Z6: 二派质量达成 Penilaian Kualitas Delivery Ritase Kedua | AE6: 全天收派质量达成 Pencapaian Kualitas Operasional Harian
K7: 快递员出勤准点率 Tingkat Ketepatan Waktu Kehadiran Spirnter | P7: 0730出仓率 Persenase Keluar Gudang 0730 | U7: 1200签收率 Persentase TTD 1200 | Z7: 二派签收率 Persentase TTD Delivery Kedua | AE7: 交件准点率 TPTW | AJ7: 全天签收率 Persentase TTD | AO7: 非平台揽收及时率 % Pickup Non- Ecommerce | AT7: 非平台COD退件率 % Retur COD Non-Ecommerce | BB7: =BB2-1 -> 46292
K8: Target | L8: 46293 | M8: 46292 | N8: 46291 | O8: 月度达成 Pencapaian Bulanan | P8: Target | Q8: 46293 | R8: 46292 | S8: 46291 | T8: 月度达成 Pencapaian Bulanan | U8: Target | V8: 46293 | W8: 46292 | X8: 46291 | Y8: 月度达成 Pencapaian Bulanan | Z8: Target | AA8: 46293 | AB8: 46292 | AC8: 46291 | AD8: 月度达成 Pencapaian Bulanan | AE8: Target | AF8: 46293 | AG8: 46292 | AH8: 46291 | AI8: 月度达成 Pencapaian Bulanan | AJ8: Target | AK8: 46293 | AL8: 46292 | AM8: 46291 | AN8: 月度达成 Pencapaian Bulanan | AO8: Target | AP8: 46293 | AQ8: 46292 | AR8: 46291 | AS8: 月度达成 Pencapaian Bulanan | AT8: 目标 Target | AU8: 46293 | AV8: 46292 | AW8: 46291 | AX8: 月度达成 Pencapaian Bulanan
C9: JAKARTA雅加达 | D9: Pickup Delivery | E9: AGENT40 | F9: JKT41W | G9: CP_PLUIT_PERMAI | H9: CP_PLUIT_PERMAI | I9: CP_PLUIT_PERMAI | J9: CP_PLUIT_PERMAI | K9: 0.9 | L9: 0.87755102 | M9: 0.83928571 | N9: 0.85483871 | O9: 0.89844683 | P9: 0.9 | Q9: 0.98940598 | R9: 0.99329575 | S9: 0.91570294 | T9: 0.9488909 | U9: 0.9 | V9: 0.85641317 | W9: 0.75940881 | X9: 0.8077191 | Y9: 0.73278907 | Z9: 0.92 | AA9: 0.9405427 | AB9: 0.87678659 | AC9: 0.93202765 | AD9: 0.91771965 | AE9: 0.92 | AF9: 0.96733872 | AG9: 0.93924571 | AH9: 0.98360303 | AI9: 0.96272611 | AJ9: 0.92 | AK9: 0.94893508 | AL9: 0.91574092 | AM9: 0.9518972 | AN9: 0.93794104 | AO9: 0.99 | AP9: 1 | AQ9: 1 | AR9: 1 | AS9: 1 | AT9: 0.08721821 | AU9: 0 | AV9: 0.10344828 | AW9: 0.054054054 | AX9: 0.049946865
C10: JAKARTA雅加达 | D10: Pickup Delivery | E10: AGENT40 | F10: JKT43D | G10: CP_DANAUSUNTER_UTARA | H10: CP_DANAUSUNTER_UTARA | I10: CP_DANAUSUNTER_UTARA | J10: CP_DANAUSUNTER_UTARA | K10: 0.9 | L10: 0.88118812 | M10: 0.89320388 | N10: 0.88288288 | O10: 0.88192922 | P10: 0.9 | Q10: 0.93773867 | R10: 0.97293676 | S10: 0.97227131 | T10: 0.98235853 | U10: 0.9 | V10: 0.82483812 | W10: 0.80211683 | X10: 0.84694848 | Y10: 0.79964507 | Z10: 0.92 | AA10: 0.92598794 | AB10: 0.92393127 | AC10: 0.9583007 | AD10: 0.9606825 | AE10: 0.92 | AF10: 0.99594622 | AG10: 0.98214752 | AH10: 0.99337236 | AI10: 0.99323991 | AJ10: 0.92 | AK10: 0.93385128 | AL10: 0.94640085 | AM10: 0.96631106 | AN10: 0.96906269 | AO10: 0.99 | AP10: 1 | AQ10: 1 | AR10: 1 | AS10: 1 | AT10: 0.08721821 | AU10: 0.064516129 | AV10: 0.014492754 | AW10: 0.016949153 | AX10: 0.055446516
C11: JAKARTA雅加达 | D11: Pickup Delivery | E11: AGENT40 | F11: JKT08L | G11: KAMAL_MUARA | H11: KAMAL_MUARA | I11: KAMAL_MUARA | J11: KAMAL_MUARA | K11: 0.9 | L11: 0.96 | M11: 0.96153846 | N11: 0.88888889 | O11: 0.92938209 | P11: 0.9 | Q11: 0.99544419 | R11: 0.99129058 | S11: 0.99175412 | T11: 0.94294228 | U11: 0.9 | V11: 0.88914199 | W11: 0.90577989 | X11: 0.88755622 | Y11: 0.88478093 | Z11: 0.92 | AA11: 0.93603412 | AB11: 0.95243129 | AC11: 0.94655005 | AD11: 0.94926549 | AE11: 0.92 | AF11: 0.99883964 | AG11: 0.95462185 | AH11: 0.98548922 | AI11: 0.94884899 | AJ11: 0.92 | AK11: 0.94456887 | AL11: 0.95608873 | AM11: 0.95306554 | AN11: 0.96333642 | AO11: 0.99 | AP11: 1 | AQ11: 1 | AR11: 1 | AS11: 1 | AT11: 0.08721821 | AU11: 0 | AV11: 0 | AW11: 0 | AX11: 0.032786885
C12: JAKARTA雅加达 | D12: Pickup Delivery | E12: AGENT40 | F12: JKT08I | G12: TELUK_GONG | H12: TELUK_GONG | I12: TELUK_GONG | J12: TELUK_GONG | K12: 0.9 | L12: 0.94339623 | M12: 0.94117647 | N12: 0.92792793 | O12: 0.92072015 | P12: 0.9 | Q12: 0.83109504 | R12: 0.90996115 | S12: 0.91534099 | T12: 0.91411828 | U12: 0.9 | V12: 0.81439394 | W12: 0.80188679 | X12: 0.86180661 | Y12: 0.83069059 | Z12: 0.92 | AA12: 0.8982718 | AB12: 0.95137375 | AC12: 0.97246059 | AD12: 0.97315625 | AE12: 0.92 | AF12: 0.9836703 | AG12: 0.95961003 | AH12: 0.97183908 | AI12: 0.93589408 | AJ12: 0.92 | AK12: 0.91536988 | AL12: 0.95175922 | AM12: 0.97655612 | AN12: 0.97795663 | AO12: 0.99 | AP12: 1 | AQ12: 1 | AR12: 1 | AS12: 1 | AT12: 0.08721821 | AU12: 0.069767442 | AV12: 0.039215686 | AW12: 0 | AX12: 0.068363636
C13: JAKARTA雅加达 | D13: Pickup Delivery | E13: AGENT40 | F13: JKT41T | G13: CP_TELUK_GONG_RAYA | H13: CP_TELUK_GONG_RAYA | I13: CP_TELUK_GONG_RAYA | J13: CP_TELUK_GONG_RAYA | K13: 0.9 | L13: 0.93333333 | M13: 0.93333333 | N13: 0.95833333 | O13: 0.89958449 | P13: 0.9 | Q13: 0.85963027 | R13: 0.96490361 | S13: 0.98283073 | T13: 0.95865379 | U13: 0.9 | V13: 0.93766122 | W13: 0.91497776 | X13: 0.95597623 | Y13: 0.93634914 | Z13: 0.92 | AA13: 0.97851336 | AB13: 0.97086466 | AC13: 0.95730117 | AD13: 0.95849881 | AE13: 0.92 | AF13: 0.994914 | AG13: 0.99818716 | AH13: 0.98790495 | AI13: 0.97201753 | AJ13: 0.92 | AK13: 0.98133919 | AL13: 0.97474502 | AM13: 0.97044141 | AN13: 0.97416948 | AO13: 0.99 | AP13: 1 | AQ13: 1 | AR13: 1 | AS13: 1 | AT13: 0.08721821 | AU13: 0 | AV13: 0.041666667 | AW13: 0 | AX13: 0.039780521
C14: JAKARTA雅加达 | D14: Pickup Delivery | E14: AGENT40 | F14: JKT30A | G14: CP_PADEMANGAN_4 | H14: CP_PADEMANGAN_4 | I14: CP_PADEMANGAN_4 | J14: CP_PADEMANGAN_4 | K14: 0.9 | L14: - | M14: - | N14: - | O14: - | P14: 0.9 | Q14: - | R14: - | S14: - | T14: 0.36842105 | U14: 0.9 | V14: - | W14: - | X14: - | Y14: 0.94736842 | Z14: 0.92 | AA14: - | AB14: - | AC14: - | AD14: 1 | AE14: 0.92 | AF14: - | AG14: - | AH14: - | AI14: 0.99639617 | AJ14: 0.92 | AK14: - | AL14: - | AM14: - | AN14: 0.96969697 | AO14: 0.99 | AP14: - | AQ14: - | AR14: - | AS14: 1 | AT14: 0.08721821 | AU14: - | AV14: - | AW14: - | AX14: -
C15: JAKARTA雅加达 | D15: Pickup Delivery | E15: AGENT40 | F15: JKT43Q | G15: CP_ANCOL_SELATAN_1 | H15: CP_ANCOL_SELATAN_1 | I15: CP_ANCOL_SELATAN_1 | J15: CP_ANCOL_SELATAN_1 | K15: 0.9 | L15: 0.99130435 | M15: 0.98198198 | N15: 0.98333333 | O15: 0.98793408 | P15: 0.9 | Q15: 0.98563293 | R15: 0.98460172 | S15: 0.98876963 | T15: 0.98272513 | U15: 0.9 | V15: 0.91858659 | W15: 0.89458099 | X15: 0.9109521 | Y15: 0.9164217 | Z15: 0.92 | AA15: 0.95687711 | AB15: 0.94591629 | AC15: 0.96240489 | AD15: 0.96639035 | AE15: 0.92 | AF15: 0.99947649 | AG15: 0.99690852 | AH15: 0.98063044 | AI15: 0.99350784 | AJ15: 0.92 | AK15: 0.97046301 | AL15: 0.96287773 | AM15: 0.97340489 | AN15: 0.9777985 | AO15: 0.99 | AP15: 1 | AQ15: 1 | AR15: 1 | AS15: 1 | AT15: 0.08721821 | AU15: 0 | AV15: 0.013157895 | AW15: 0.015503876 | AX15: 0.027039848
C16: JAKARTA雅加达 | D16: Pickup Delivery | E16: AGENT40 | F16: JKT08C | G16: KEPULAUAN_SERIBU | H16: KEPULAUAN_SERIBU | I16: KEPULAUAN_SERIBU | J16: KEPULAUAN_SERIBU | K16: 0.9 | L16: 0.96428571 | M16: 0.96428571 | N16: 0.91304348 | O16: 0.96148738 | P16: 0.9 | Q16: 0.99920917 | R16: 0.99613221 | S16: 0.99090909 | T16: 0.96540034 | U16: 0.9 | V16: 0.97825227 | W16: 0.99120956 | X16: 0.99335664 | Y16: 0.95747395 | Z16: 0.92 | AA16: - | AB16: - | AC16: - | AD16: 0 | AE16: 0.92 | AF16: 0.55555556 | AG16: 0 | AH16: - | AI16: 0.5 | AJ16: 0.92 | AK16: 0.98418347 | AL16: 0.99578059 | AM16: 0.9986014 | AN16: 0.99457799 | AO16: 0.99 | AP16: 1 | AQ16: 1 | AR16: - | AS16: 1 | AT16: 0.08721821 | AU16: 0 | AV16: 0 | AW16: 0 | AX16: 0.059027778
C17: JAKARTA雅加达 | D17: Pickup Delivery | E17: AGENT40 | F17: JKT11 | G17: TANAH_ABANG | H17: TANAH_ABANG | I17: TANAH_ABANG | J17: TANAH_ABANG | K17: 0.9 | L17: 0.85555556 | M17: 0.87671233 | N17: 0.83529412 | O17: 0.88519521 | P17: 0.9 | Q17: 0.99148118 | R17: 0.99058219 | S17: 0.99097379 | T17: 0.99394094 | U17: 0.9 | V17: 0.72107722 | W17: 0.51643836 | X17: 0.70595383 | Y17: 0.72097686 | Z17: 0.92 | AA17: 0.88363851 | AB17: 0.62805663 | AC17: 0.8536297 | AD17: 0.87432174 | AE17: 0.92 | AF17: 0.99017682 | AG17: 0.99271592 | AH17: 0.99263984 | AI17: 0.98570708 | AJ17: 0.92 | AK17: 0.90810203 | AL17: 0.68980053 | AM17: 0.8765012 | AN17: 0.8987719 | AO17: 0.99 | AP17: 1 | AQ17: 1 | AR17: 1 | AS17: 1 | AT17: 0.08721821 | AU17: 0.055555556 | AV17: 0.078125 | AW17: 0.017241379 | AX17: 0.046758105
C18: JAKARTA雅加达 | D18: Pickup Delivery | E18: AGENT40 | F18: JKT12 | G18: SENEN | H18: SENEN | I18: SENEN | J18: SENEN | K18: 0.9 | L18: 0.97321429 | M18: 0.9537037 | N18: 0.9338843 | O18: 0.97838002 | P18: 0.9 | Q18: 0.9933916 | R18: 0.99331569 | S18: 0.99341552 | T18: 0.9928209 | U18: 0.9 | V18: 0.86228949 | W18: 0.77329063 | X18: 0.87685626 | Y18: 0.88384897 | Z18: 0.92 | AA18: 0.91412623 | AB18: 0.85976461 | AC18: 0.91557187 | AD18: 0.93481277 | AE18: 0.92 | AF18: 0.98096102 | AG18: 0.9896978 | AH18: 0.9808542 | AI18: 0.98009451 | AJ18: 0.92 | AK18: 0.93831909 | AL18: 0.87240672 | AM18: 0.93438896 | AN18: 0.95260379 | AO18: 0.99 | AP18: 1 | AQ18: 1 | AR18: 1 | AS18: 1 | AT18: 0.08721821 | AU18: 0.046875 | AV18: 0.041666667 | AW18: 0.086956522 | AX18: 0.059947871
C19: JAKARTA雅加达 | D19: Pickup Delivery | E19: AGENT40 | F19: JKT45I | G19: CP_PINANGSIA_RAYA | H19: CP_PINANGSIA_RAYA | I19: CP_PINANGSIA_RAYA | J19: CP_PINANGSIA_RAYA | K19: 0.9 | L19: 0.8125 | M19: 0.63636364 | N19: 0.66666667 | O19: 0.80448065 | P19: 0.9 | Q19: 0.98310292 | R19: 0.98561151 | S19: 0.99132791 | T19: 0.90251211 | U19: 0.9 | V19: 0.64976959 | W19: 0.36793422 | X19: 0.68455285 | Y19: 0.63562105 | Z19: 0.92 | AA19: 0.90495868 | AB19: 0.44326923 | AC19: 0.89278752 | AD19: 0.80393304 | AE19: 0.92 | AF19: 0.99334601 | AG19: 0.99663785 | AH19: 0.99560467 | AI19: 0.99438168 | AJ19: 0.92 | AK19: 0.92329227 | AL19: 0.56879813 | AM19: 0.92553932 | AN19: 0.85329714 | AO19: 0.99 | AP19: 1 | AQ19: 1 | AR19: 1 | AS19: 1 | AT19: 0.08721821 | AU19: 0.1 | AV19: 0.2 | AW19: 0 | AX19: 0.064356436
C20: JAKARTA雅加达 | D20: Pickup Delivery | E20: AGENT40 | F20: JKT13K | G20: JOHAR_BARU_01 | H20: JOHAR_BARU_01 | I20: JOHAR_BARU_01 | J20: JOHAR_BARU_01 | K20: 0.9 | L20: 0.96491228 | M20: 0.91525424 | N20: 0.93043478 | O20: 0.93669022 | P20: 0.9 | Q20: 0.99754031 | R20: 0.98776191 | S20: 0.99623494 | T20: 0.99315293 | U20: 0.9 | V20: 0.88138836 | W20: 0.85740775 | X20: 0.87688253 | Y20: 0.87420332 | Z20: 0.92 | AA20: 0.91900905 | AB20: 0.89192578 | AC20: 0.91905232 | AD20: 0.94595633 | AE20: 0.92 | AF20: 0.99530201 | AG20: 0.9728 | AH20: 0.95929444 | AI20: 0.97853849 | AJ20: 0.92 | AK20: 0.9440778 | AL20: 0.92729211 | AM20: 0.94980777 | AN20: 0.96281999 | AO20: 0.99 | AP20: 1 | AQ20: 1 | AR20: 1 | AS20: 1 | AT20: 0.08721821 | AU20: 0 | AV20: 0.038461538 | AW20: 0.057142857 | AX20: 0.061362454
C21: JAKARTA雅加达 | D21: Pickup Delivery | E21: AGENT40 | F21: JKT45L | G21: CP_ZAINUL_ARIFIN | H21: CP_ZAINUL_ARIFIN | I21: CP_ZAINUL_ARIFIN | J21: CP_ZAINUL_ARIFIN | K21: 0.9 | L21: 0.875 | M21: 0.58823529 | N21: 0.6875 | O21: 0.89154013 | P21: 0.9 | Q21: 0.9759887 | R21: 0.94002123 | S21: 0.946084 | T21: 0.97453785 | U21: 0.9 | V21: 0.92372881 | W21: 0.8381104 | X21: 0.86889898 | Y21: 0.85140817 | Z21: 0.92 | AA21: 0.9752883 | AB21: 0.92370295 | AC21: 0.93602362 | AD21: 0.91883987 | AE21: 0.92 | AF21: 0.99268476 | AG21: 0.99795918 | AH21: 0.98719111 | AI21: 0.97273586 | AJ21: 0.92 | AK21: 0.98319328 | AL21: 0.94000698 | AM21: 0.95356371 | AN21: 0.95367766 | AO21: 0.99 | AP21: 1 | AQ21: 1 | AR21: 1 | AS21: 1 | AT21: 0.08721821 | AU21: 0 | AV21: 0.25 | AW21: 0.090909091 | AX21: 0.10285714
C22: JAKARTA雅加达 | D22: Pickup Delivery | E22: AGENT40 | F22: JKT45B | G22: CP_MANGGA_BESAR_2 | H22: CP_MANGGA_BESAR_2 | I22: CP_MANGGA_BESAR_2 | J22: CP_MANGGA_BESAR_2 | K22: 0.9 | L22: 0.88636364 | M22: 0.86046512 | N22: 0.90697674 | O22: 0.90563045 | P22: 0.9 | Q22: 0.8440727 | R22: 0.98013124 | S22: 0.98378909 | T22: 0.92278732 | U22: 0.9 | V22: 0.89962825 | W22: 0.93528983 | X22: 0.93188145 | Y22: 0.89688114 | Z22: 0.92 | AA22: 0.94028951 | AB22: 0.96268344 | AC22: 0.94432773 | AD22: 0.96001919 | AE22: 0.92 | AF22: 0.99674989 | AG22: 0.99837988 | AH22: 0.99811627 | AI22: 0.98939008 | AJ22: 0.92 | AK22: 0.95907692 | AL22: 0.97916667 | AM22: 0.97478523 | AN22: 0.97555561 | AO22: 0.99 | AP22: 1 | AQ22: 1 | AR22: 1 | AS22: 1 | AT22: 0.08721821 | AU22: 0.083333333 | AV22: 0.041666667 | AW22: 0 | AX22: 0.096188748
C23: JAKARTA雅加达 | D23: Pickup Delivery | E23: AGENT40 | F23: JKT53C | G23: CP_CEGER | H23: CP_CEGER | I23: CP_CEGER | J23: CP_CEGER | K23: 0.9 | L23: 0.81818182 | M23: 0.78030303 | N23: 0.80555556 | O23: 0.88133069 | P23: 0.9 | Q23: 0.80452289 | R23: 0.80176861 | S23: 0.83961499 | T23: 0.83503291 | U23: 0.9 | V23: 0.71516823 | W23: 0.74607853 | X23: 0.79696049 | Y23: 0.68404615 | Z23: 0.92 | AA23: 0.92122256 | AB23: 0.98590327 | AC23: 0.98948921 | AD23: 0.9606846 | AE23: 0.92 | AF23: 0.9988147 | AG23: 0.85461828 | AH23: 0.9042155 | AI23: 0.7735726 | AJ23: 0.92 | AK23: 0.935634 | AL23: 0.9900078 | AM23: 0.989473 | AN23: 0.96978045 | AO23: 0.99 | AP23: 1 | AQ23: 1 | AR23: 1 | AS23: 1 | AT23: 0.08721821 | AU23: 0.012345679 | AV23: 0.011363636 | AW23: 0.02173913 | AX23: 0.051214128
C24: JAKARTA雅加达 | D24: Pickup Delivery | E24: AGENT40 | F24: JKT18N | G24: KAMPUNG_TENGAH | H24: KAMPUNG_TENGAH | I24: KAMPUNG_TENGAH | J24: KAMPUNG_TENGAH | K24: 0.9 | L24: 0.86178862 | M24: 0.86507937 | N24: 0.89552239 | O24: 0.88855117 | P24: 0.9 | Q24: 0.99648506 | R24: 0.99458108 | S24: 0.9939759 | T24: 0.97530908 | U24: 0.9 | V24: 0.71968366 | W24: 0.68598027 | X24: 0.71623335 | Y24: 0.7010433 | Z24: 0.92 | AA24: 0.8580705 | AB24: 0.86911855 | AC24: 0.85100643 | AD24: 0.8916669 | AE24: 0.92 | AF24: 0.99885321 | AG24: 0.99628713 | AH24: 0.99863326 | AI24: 0.97666282 | AJ24: 0.92 | AK24: 0.89549791 | AL24: 0.90019894 | AM24: 0.89548886 | AN24: 0.92316033 | AO24: 0.99 | AP24: 1 | AQ24: 1 | AR24: 1 | AS24: 1 | AT24: 0.08721821 | AU24: 0.048387097 | AV24: 0.0125 | AW24: 0.013333333 | AX24: 0.061671764
C25: JAKARTA雅加达 | D25: Pickup Delivery | E25: AGENT40 | F25: JKT61C | G25: CP_CIJANTUNG | H25: CP_CIJANTUNG | I25: CP_CIJANTUNG | J25: CP_CIJANTUNG | K25: 0.9 | L25: 0.95121951 | M25: 0.94252874 | N25: 0.91578947 | O25: 0.94109143 | P25: 0.9 | Q25: 0.9885465 | R25: 0.99483471 | S25: 0.99050313 | T25: 0.98414438 | U25: 0.9 | V25: 0.83310608 | W25: 0.82765152 | X25: 0.84805011 | Y25: 0.81811756 | Z25: 0.92 | AA25: 0.89411765 | AB25: 0.90263158 | AC25: 0.89722589 | AD25: 0.92226763 | AE25: 0.92 | AF25: 0.99982206 | AG25: 0.99624237 | AH25: 0.99864572 | AI25: 0.99094017 | AJ25: 0.92 | AK25: 0.92498166 | AL25: 0.92434176 | AM25: 0.92455638 | AN25: 0.94524954 | AO25: 0.99 | AP25: 1 | AQ25: 1 | AR25: 1 | AS25: 1 | AT25: 0.08721821 | AU25: 0.041666667 | AV25: 0.037037037 | AW25: -0.012820513 | AX25: 0.041983028
C26: JAKARTA雅加达 | D26: Pickup Delivery | E26: AGENT40 | F26: JKT20J | G26: DC_MAKASAR | H26: DC_MAKASAR | I26: DC_MAKASAR | J26: DC_MAKASAR | K26: 0.9 | L26: 0.90804598 | M26: 0.91397849 | N26: 0.92929293 | O26: 0.93054101 | P26: 0.9 | Q26: 0.98011287 | R26: 0.98233148 | S26: 0.9955607 | T26: 0.89933427 | U26: 0.9 | V26: 0.77613545 | W26: 0.74534281 | X26: 0.74387184 | Y26: 0.71240515 | Z26: 0.92 | AA26: 0.86849628 | AB26: 0.8643617 | AC26: 0.90250193 | AD26: 0.9139968 | AE26: 0.92 | AF26: 0.99862183 | AG26: 0.99884925 | AH26: 0.99793857 | AI26: 0.99732194 | AJ26: 0.92 | AK26: 0.91224863 | AL26: 0.90467165 | AM26: 0.92769621 | AN26: 0.93852759 | AO26: 0.99 | AP26: 1 | AQ26: 1 | AR26: 1 | AS26: 1 | AT26: 0.08721821 | AU26: 0.019230769 | AV26: 0.047619048 | AW26: 0.054545455 | AX26: 0.040240518
C27: JAKARTA雅加达 | D27: Pickup Delivery | E27: AGENT40 | F27: JKT19K | G27: DC_CIRACAS | H27: DC_CIRACAS | I27: DC_CIRACAS | J27: DC_CIRACAS | K27: 0.9 | L27: 0.94186047 | M27: 0.90909091 | N27: 0.97590361 | O27: 0.95044709 | P27: 0.9 | Q27: 0.95297599 | R27: 0.96827618 | S27: 0.95705521 | T27: 0.95584763 | U27: 0.9 | V27: 0.86287405 | W27: 0.84091439 | X27: 0.88556949 | Y27: 0.88306448 | Z27: 0.92 | AA27: 0.90254873 | AB27: 0.92053829 | AC27: 0.92095769 | AD27: 0.9458681 | AE27: 0.92 | AF27: 0.66666667 | AG27: 0.69565217 | AH27: 0.95238095 | AI27: 0.80397727 | AJ27: 0.92 | AK27: 0.94011429 | AL27: 0.94236739 | AM27: 0.95233892 | AN27: 0.96530816 | AO27: 0.99 | AP27: 1 | AQ27: 1 | AR27: 1 | AS27: 1 | AT27: 0.08721821 | AU27: 0.019230769 | AV27: 0.054054054 | AW27: 0.063829787 | AX27: 0.063688999
C28: JAKARTA雅加达 | D28: Pickup Delivery | E28: AGENT40 | F28: JKT47C | G28: CP_RAYA_KELAPA | H28: CP_RAYA_KELAPA | I28: CP_RAYA_KELAPA | J28: CP_RAYA_KELAPA | K28: 0.9 | L28: 0.97916667 | M28: 1 | N28: 0.98148148 | O28: 0.98138298 | P28: 0.9 | Q28: 0.95916852 | R28: 0.98180045 | S28: 0.98006769 | T28: 0.97216084 | U28: 0.9 | V28: 0.8671121 | W28: 0.87747806 | X28: 0.89394509 | Y28: 0.89534913 | Z28: 0.92 | AA28: 0.96038544 | AB28: 0.94012258 | AC28: 0.94251781 | AD28: 0.96080635 | AE28: 0.92 | AF28: 0.99167734 | AG28: 0.99443801 | AH28: 0.99748629 | AI28: 0.99374106 | AJ28: 0.92 | AK28: 0.95966681 | AL28: 0.95671412 | AM28: 0.96348374 | AN28: 0.97270192 | AO28: 0.99 | AP28: 1 | AQ28: 1 | AR28: 1 | AS28: 1 | AT28: 0.08721821 | AU28: 0.12121212 | AV28: 0 | AW28: 0.076923077 | AX28: 0.068384539
C29: JAKARTA雅加达 | D29: Pickup Delivery | E29: AGENT40 | F29: JKT50K | G29: CP_PONDOK_BAMBU | H29: CP_PONDOK_BAMBU | I29: CP_PONDOK_BAMBU | J29: CP_PONDOK_BAMBU | K29: 0.9 | L29: 0.92592593 | M29: 0.84482759 | N29: 0.86666667 | O29: 0.91407575 | P29: 0.9 | Q29: 0.96481337 | R29: 0.97889953 | S29: 0.98188223 | T29: 0.96400187 | U29: 0.9 | V29: 0.93409798 | W29: 0.8837851 | X29: 0.9077336 | Y29: 0.90270163 | Z29: 0.92 | AA29: 0.97902098 | AB29: 0.97333333 | AC29: 0.97669116 | AD29: 0.97504163 | AE29: 0.92 | AF29: 0.9919206 | AG29: 0.9905078 | AH29: 0.95181541 | AI29: 0.96378535 | AJ29: 0.92 | AK29: 0.98082653 | AL29: 0.98124054 | AM29: 0.985165 | AN29: 0.98238884 | AO29: 0.99 | AP29: 1 | AQ29: 1 | AR29: 1 | AS29: 1 | AT29: 0.08721821 | AU29: 0.014084507 | AV29: 0 | AW29: 0.0072992701 | AX29: 0.020098258
C30: JAKARTA雅加达 | D30: Pickup Delivery | E30: AGENT40 | F30: JKT17K | G30: DC_JATINEGARA | H30: DC_JATINEGARA | I30: DC_JATINEGARA | J30: DC_JATINEGARA | K30: 0.9 | L30: 0.88135593 | M30: 0.85245902 | N30: 0.90625 | O30: 0.90543478 | P30: 0.9 | Q30: 0.97482185 | R30: 0.98034544 | S30: 0.98312672 | T30: 0.96595834 | U30: 0.9 | V30: 0.82850356 | W30: 0.79898749 | X30: 0.8357438 | Y30: 0.83107756 | Z30: 0.92 | AA30: 0.89401889 | AB30: 0.91588785 | AC30: 0.90986167 | AD30: 0.9360753 | AE30: 0.92 | AF30: 0.8 | AG30: 0 | AH30: - | AI30: 0.53409091 | AJ30: 0.92 | AK30: 0.92184434 | AL30: 0.93487957 | AM30: 0.93956471 | AN30: 0.95470508 | AO30: 0.99 | AP30: 1 | AQ30: - | AR30: - | AS30: 1 | AT30: 0.08721821 | AU30: 0 | AV30: 0.081081081 | AW30: 0 | AX30: 0.058291457
C31: JAKARTA雅加达 | D31: Pickup Delivery | E31: AGENT40 | F31: JKT25Q | G31: SETIABUDI | H31: SETIABUDI | I31: SETIABUDI | J31: SETIABUDI | K31: 0.9 | L31: 1 | M31: 0.94285714 | N31: 0.97619048 | O31: 0.97183691 | P31: 0.9 | Q31: 0.9957483 | R31: 0.99263675 | S31: 0.98580122 | T31: 0.98393448 | U31: 0.9 | V31: 0.87018141 | W31: 0.72019635 | X31: 0.77484787 | Y31: 0.83913022 | Z31: 0.92 | AA31: 0.92921289 | AB31: 0.79153269 | AC31: 0.80358555 | AD31: 0.90469324 | AE31: 0.92 | AF31: 0.99963289 | AG31: 0.99661972 | AH31: 0.99160026 | AI31: 0.99486045 | AJ31: 0.92 | AK31: 0.94834901 | AL31: 0.80214074 | AM31: 0.83794338 | AN31: 0.92574722 | AO31: 0.99 | AP31: 1 | AQ31: 1 | AR31: 1 | AS31: 1 | AT31: 0.08721821 | AU31: 0 | AV31: 0.020408163 | AW31: 0.069767442 | AX31: 0.067280453
C32: JAKARTA雅加达 | D32: Pickup Delivery | E32: AGENT40 | F32: JKT20C | G32: KLENDER | H32: KLENDER | I32: KLENDER | J32: KLENDER | K32: 0.9 | L32: 0.85245902 | M32: 0.8852459 | N32: 0.89705882 | O32: 0.93620332 | P32: 0.9 | Q32: 0.99304419 | R32: 0.97565543 | S32: 0.98812424 | T32: 0.98469493 | U32: 0.9 | V32: 0.86702128 | W32: 0.87399679 | X32: 0.87606577 | Y32: 0.88905631 | Z32: 0.92 | AA32: 0.92927484 | AB32: 0.91733547 | AC32: 0.94132335 | AD32: 0.95494923 | AE32: 0.92 | AF32: 0.99728366 | AG32: 0.99717603 | AH32: 0.99532967 | AI32: 0.98993971 | AJ32: 0.92 | AK32: 0.9494524 | AL32: 0.93275558 | AM32: 0.95411392 | AN32: 0.96571112 | AO32: 0.99 | AP32: 1 | AQ32: 1 | AR32: 1 | AS32: 1 | AT32: 0.08721821 | AU32: 0 | AV32: 0.040816327 | AW32: 0.14705882 | AX32: 0.049053356
C33: JAKARTA雅加达 | D33: Pickup Delivery | E33: AGENT40 | F33: JKT52I | G33: CP_JATINEGARA_BARAT | H33: CP_JATINEGARA_BARAT | I33: CP_JATINEGARA_BARAT | J33: CP_JATINEGARA_BARAT | K33: 0.9 | L33: 0.91666667 | M33: 0.81666667 | N33: 0.81538462 | O33: 0.92315845 | P33: 0.9 | Q33: 0.79598051 | R33: 0.86261261 | S33: 0.90038887 | T33: 0.8751941 | U33: 0.9 | V33: 0.81668697 | W33: 0.77377377 | X33: 0.84116063 | Y33: 0.7921559 | Z33: 0.92 | AA33: 0.93061224 | AB33: 0.85747215 | AC33: 0.96089385 | AD33: 0.94369321 | AE33: 0.92 | AF33: 0.9956097 | AG33: 0.93681452 | AH33: 0.96169226 | AI33: 0.95268956 | AJ33: 0.92 | AK33: 0.9312791 | AL33: 0.90318182 | AM33: 0.96549957 | AN33: 0.95625162 | AO33: 0.99 | AP33: 1 | AQ33: 1 | AR33: 1 | AS33: 1 | AT33: 0.08721821 | AU33: 0.086956522 | AV33: 0 | AW33: 0.071428571 | AX33: 0.07473983
C34: JAKARTA雅加达 | D34: Pickup Delivery | E34: AGENT40 | F34: JKT25 | G34: TEBET | H34: TEBET | I34: TEBET | J34: TEBET | K34: 0.9 | L34: 0.96808511 | M34: 0.97979798 | N34: 0.98148148 | O34: 0.97906904 | P34: 0.9 | Q34: 0.996139 | R34: 0.99569633 | S34: 0.99552072 | T34: 0.99413706 | U34: 0.9 | V34: 0.88472146 | W34: 0.86434842 | X34: 0.885405 | Y34: 0.88208233 | Z34: 0.92 | AA34: 0.91681628 | AB34: 0.90111025 | AC34: 0.90563565 | AD34: 0.93523547 | AE34: 0.92 | AF34: 0.98 | AG34: 0.98374512 | AH34: 0.9832636 | AI34: 0.98544259 | AJ34: 0.92 | AK34: 0.94714987 | AL34: 0.92594505 | AM34: 0.93285372 | AN34: 0.9575923 | AO34: 0.99 | AP34: 1 | AQ34: 1 | AR34: 1 | AS34: 1 | AT34: 0.08721821 | AU34: 0.06557377 | AV34: 0.042553191 | AW34: 0.038961039 | AX34: 0.067330488
C35: JAKARTA雅加达 | D35: Pickup Delivery | E35: AGENT40 | F35: JKT50I | G35: CP_HAJI_NAMAN_1 | H35: CP_HAJI_NAMAN_1 | I35: CP_HAJI_NAMAN_1 | J35: CP_HAJI_NAMAN_1 | K35: 0.9 | L35: 0.89156627 | M35: 0.93023256 | N35: 0.9 | O35: 0.91218354 | P35: 0.9 | Q35: 0.91303226 | R35: 0.93644758 | S35: 0.95065312 | T35: 0.90060353 | U35: 0.9 | V35: 0.85316129 | W35: 0.87760275 | X35: 0.89052457 | Y35: 0.84856798 | Z35: 0.92 | AA35: 0.93944266 | AB35: 0.94998484 | AC35: 0.96875921 | AD35: 0.94846987 | AE35: 0.92 | AF35: 0.98229023 | AG35: 0.9865535 | AH35: 0.97489689 | AI35: 0.96903246 | AJ35: 0.92 | AK35: 0.95697614 | AL35: 0.96157769 | AM35: 0.97773181 | AN35: 0.96384477 | AO35: 0.99 | AP35: 1 | AQ35: 1 | AR35: 1 | AS35: 0.99950331 | AT35: 0.08721821 | AU35: 0.081632653 | AV35: 0 | AW35: 0.01754386 | AX35: 0.070979899
C36: JAKARTA雅加达 | D36: Pickup Delivery | E36: AGENT40 | F36: JKT16Q | G36: PULOGEBANG_01 | H36: PULOGEBANG_01 | I36: PULOGEBANG_01 | J36: PULOGEBANG_01 | K36: 0.9 | L36: 0.95588235 | M36: 0.93006993 | N36: 0.95454545 | O36: 0.94905792 | P36: 0.9 | Q36: 0.96420261 | R36: 0.95231214 | S36: 0.9567455 | T36: 0.96558117 | U36: 0.9 | V36: 0.79881869 | W36: 0.78359827 | X36: 0.84805784 | Y36: 0.82297519 | Z36: 0.92 | AA36: 0.91140729 | AB36: 0.90546835 | AC36: 0.94368865 | AD36: 0.93904874 | AE36: 0.92 | AF36: 0.99307958 | AG36: 0.98767967 | AH36: 0.97849462 | AI36: 0.95915428 | AJ36: 0.92 | AK36: 0.9276146 | AL36: 0.92901213 | AM36: 0.95941303 | AN36: 0.95710564 | AO36: 0.99 | AP36: 1 | AQ36: 1 | AR36: 1 | AS36: 1 | AT36: 0.08721821 | AU36: 0 | AV36: 0.10344828 | AW36: 0 | AX36: 0.055868785
C37: JAKARTA雅加达 | D37: Pickup Delivery | E37: AGENT40 | F37: JKT16O | G37: DC_PULO_GADUNG | H37: DC_PULO_GADUNG | I37: DC_PULO_GADUNG | J37: DC_PULO_GADUNG | K37: 0.9 | L37: - | M37: - | N37: - | O37: - | P37: 0.9 | Q37: - | R37: - | S37: - | T37: - | U37: 0.9 | V37: - | W37: - | X37: - | Y37: - | Z37: 0.92 | AA37: - | AB37: - | AC37: - | AD37: - | AE37: 0.92 | AF37: - | AG37: - | AH37: - | AI37: - | AJ37: 0.92 | AK37: - | AL37: - | AM37: - | AN37: - | AO37: 0.99 | AP37: - | AQ37: - | AR37: - | AS37: - | AT37: 0.08721821 | AU37: - | AV37: - | AW37: - | AX37: -
C38: JAKARTA雅加达 | D38: Pickup Delivery | E38: AGENT40 | F38: JKT10B | G38: ROROTAN | H38: ROROTAN | I38: ROROTAN | J38: ROROTAN | K38: 0.9 | L38: 1 | M38: 0.953125 | N38: 1 | O38: 0.97894737 | P38: 0.9 | Q38: 0.98817346 | R38: 0.97888631 | S38: 0.99226985 | T38: 0.98457865 | U38: 0.9 | V38: 0.85808147 | W38: 0.84779582 | X38: 0.8795971 | Y38: 0.85613061 | Z38: 0.92 | AA38: 0.91056911 | AB38: 0.91333785 | AC38: 0.93409091 | AD38: 0.93583625 | AE38: 0.92 | AF38: 0.99583116 | AG38: 0.9965366 | AH38: 0.99759005 | AI38: 0.99533233 | AJ38: 0.92 | AK38: 0.93336366 | AL38: 0.93640743 | AM38: 0.9541559 | AN38: 0.95628424 | AO38: 0.99 | AP38: 1 | AQ38: 1 | AR38: 1 | AS38: 1 | AT38: 0.08721821 | AU38: 0.125 | AV38: 0 | AW38: 0.23076923 | AX38: 0.067532468
C39: JAKARTA雅加达 | D39: Pickup Delivery | E39: AGENT40 | F39: JKT16R | G39: DC_UJUNG_MENTENG | H39: DC_UJUNG_MENTENG | I39: DC_UJUNG_MENTENG | J39: DC_UJUNG_MENTENG | K39: 0.9 | L39: 0.96428571 | M39: 0.96491228 | N39: 0.92727273 | O39: 0.93345543 | P39: 0.9 | Q39: 0.99847251 | R39: 0.99831138 | S39: 0.99914384 | T39: 0.99781767 | U39: 0.9 | V39: 0.92769857 | W39: 0.91725768 | X39: 0.92422945 | Y39: 0.89512192 | Z39: 0.92 | AA39: 0.94675325 | AB39: 0.94184891 | AC39: 0.95697849 | AD39: 0.95861226 | AE39: 0.92 | AF39: 0.96551724 | AG39: 0.98929336 | AH39: 0.99506417 | AI39: 0.99063853 | AJ39: 0.92 | AK39: 0.96488661 | AL39: 0.95256281 | AM39: 0.96493656 | AN39: 0.97143922 | AO39: 0.99 | AP39: 1 | AQ39: 1 | AR39: 1 | AS39: 1 | AT39: 0.08721821 | AU39: 0 | AV39: 0.052631579 | AW39: 0 | AX39: 0.041666667
C40: JAKARTA雅加达 | D40: Pickup Delivery | E40: AGENT40 | F40: JKT51G | G40: CP_UTAN_KAYU | H40: CP_UTAN_KAYU | I40: CP_UTAN_KAYU | J40: CP_UTAN_KAYU | K40: 0.9 | L40: - | M40: - | N40: - | O40: - | P40: 0.9 | Q40: 0 | R40: 0 | S40: 0 | T40: 0.06043956 | U40: 0.9 | V40: 1 | W40: 1 | X40: 1 | Y40: 0.97802198 | Z40: 0.92 | AA40: - | AB40: 1 | AC40: 1 | AD40: 1 | AE40: 0.92 | AF40: - | AG40: - | AH40: - | AI40: 0.97989759 | AJ40: 0.92 | AK40: 1 | AL40: 1 | AM40: 1 | AN40: 0.98671096 | AO40: 0.99 | AP40: - | AQ40: - | AR40: - | AS40: 1 | AT40: 0.08721821 | AU40: - | AV40: - | AW40: - | AX40: 11
C41: JAKARTA雅加达 | D41: Pickup Delivery | E41: AGENT40 | F41: JKT10H | G41: KALIBARU_01 | H41: KALIBARU_01 | I41: KALIBARU_01 | J41: KALIBARU_01 | K41: 0.9 | L41: 0.95876289 | M41: 0.98039216 | N41: 0.93457944 | O41: 0.96158574 | P41: 0.9 | Q41: 0.99367922 | R41: 0.99420092 | S41: 0.99379323 | T41: 0.99222997 | U41: 0.9 | V41: 0.87332104 | W41: 0.88077776 | X41: 0.89803157 | Y41: 0.89638038 | Z41: 0.92 | AA41: 0.93776693 | AB41: 0.9459995 | AC41: 0.95163241 | AD41: 0.95952564 | AE41: 0.92 | AF41: 0.99457995 | AG41: 0.98897312 | AH41: 0.99309392 | AI41: 0.99159433 | AJ41: 0.92 | AK41: 0.95714548 | AL41: 0.95808081 | AM41: 0.96818089 | AN41: 0.97359571 | AO41: 0.99 | AP41: 1 | AQ41: 1 | AR41: 1 | AS41: 1 | AT41: 0.08721821 | AU41: 0.076923077 | AV41: 0 | AW41: 0.046511628 | AX41: 0.042728636
...

Sheet Display Absensi 630
A1: 网管-打卡准点率报表爪哇-巴厘09月28日 NM-Persentase Absensi Tepat Waktu Sprinter Agent Jawa-Bali 28 Sep 2026
A2: 代理区 Agent | B2: RM | C2: 网点代码 Kode DP | D2: 网点名称 Nama DP | E2: 总人数 Total Orang | F2: 打卡人数 Jumlah yang Absensi | G2: 总人数 Total Orang 27/09/2026 | H2: 打卡人数 Jumlah yang Absensi 27/09/2026 | I2: 总人数 Total Orang 26/09/2026 | J2: 打卡人数 Jumlah yang Absensi 26/09/2026 | K2: 目标值 Target | L2: 28日打卡率 Persentase Absensi | O2: 总人数 Total Orang Bulanan | P2: 准点打卡人数 Jumlah Absensi Tepat Waktu Bulanan | Q2: 准点打卡人数 Jumlah Absensi Tepat Waktu | R2: 准点打卡人数 Jumlah Absensi Tepat Waktu 27/09/2026 | S2: 准点打卡人数 Jumlah Absensi Tepat Waktu 26/09/2026 | T2: 月累计 打卡准点率 Persentase Bulanan | U2: 打卡准点率 Persentase Absensi Tepat Waktu | X2: 对比昨天 Perbandingan H-1 | Y2: 总人数 Total Orang Mingguan 22/09/2026 - 28/09/2026 | Z2: 准点打卡人数 Jumlah Absensi Tepat Waktu 22/09/2026 - 28/09/2026 | AA2: 总人数 Total Orang Mingguan 15/09/2026 - 21/09/2026 | AB2: 准点打卡人数 Jumlah Absensi Tepat Waktu 15/09/2026 - 21/09/2026 | AC2: 打卡准点周度率 Persentase Mingguan Absensi Tepat Waktu | AE2: 对比上周 Perbandingan Mingguan
L3: ='Display ALL DP'!L8 -> 46293 | M3: =L3-1 -> 46292 | N3: =L3-2 -> 46291 | U3: =L3 -> 46293 | V3: =L3-1 -> 46292 | W3: =L3-2 -> 46291 | AC3: =TEXT(AK6,"DD MMM")&" - "&TEXT(AK5,"DD MMM") -> 22 Sep - 28 Sep | AD3: =TEXT(AL6,"DD MMM")&" - "&TEXT(AL5,"DD MMM") -> 15 Sep - 21 Sep
E4: 61909 | F4: 60109 | G4: 60645 | H4: 58827 | I4: 64088 | J4: 62284 | K4: 0.9 | L4: 0.97092507 | M4: 0.97002226 | N4: 0.9718512 | O4: 1814281 | P4: 1700696 | Q4: 57816 | R4: 56245 | S4: 59792 | T4: 0.93739393 | U4: 0.93388683 | V4: 0.92744662 | W4: 0.93296717 | X4: 0.0064402184 | Y4: 452736 | Z4: 424077 | AA4: 452026 | AB4: 423930 | AC4: 0.93669821 | AD4: 0.93784428 | AE4: -0.0011460751 | AF4: 5
AK5: =L3 -> 46293 | AL5: =AK6-1 -> 46286
A6: JAKARTA雅加达 | B6: AGISTA PRIYANTONO | C6: JKT07T | D6: DC_SUNTER | E6: 0 | F6: 0 | G6: 0 | H6: 0 | I6: 0 | J6: 0 | K6: 0.9 | L6: 0 | M6: 0 | N6: 0 | O6: 0 | P6: 0 | Q6: 0 | R6: 0 | S6: 0 | T6: 0 | U6: 0 | V6: 0 | W6: 0 | X6: 0 | Y6: 0 | Z6: 0 | AA6: 0 | AB6: 0 | AC6: 0 | AD6: 0 | AE6: 0 | AK6: =L3-6 -> 46287 | AL6: =AK5-13 -> 46280
A7: JAKARTA雅加达 | B7: AGISTA PRIYANTONO | C7: JKT43D | D7: CP_DANAUSUNTER_UTARA | E7: 101 | F7: 96 | G7: 103 | H7: 92 | I7: 111 | J7: 105 | K7: 0.9 | L7: 0.95049505 | M7: 0.89320388 | N7: 0.94594595 | O7: 3193 | P7: 2816 | Q7: 89 | R7: 92 | S7: 98 | T7: 0.88192922 | U7: 0.88118812 | V7: 0.89320388 | W7: 0.88288288 | X7: -0.012015765 | Y7: 790 | Z7: 716 | AA7: 810 | AB7: 714 | AC7: 0.90632911 | AD7: 0.88148148 | AE7: 0.024847632
A8: JAKARTA雅加达 | B8: AGISTA PRIYANTONO | C8: JKT08N | D8: PLUIT_PERMAI | E8: 0 | F8: 0 | G8: 0 | H8: 0 | I8: 0 | J8: 0 | K8: 0.9 | L8: 0 | M8: 0 | N8: 0 | O8: 0 | P8: 0 | Q8: 0 | R8: 0 | S8: 0 | T8: 0 | U8: 0 | V8: 0 | W8: 0 | X8: 0 | Y8: 0 | Z8: 0 | AA8: 0 | AB8: 0 | AC8: 0 | AD8: 0 | AE8: 0 | AK8: 46266
A9: JAKARTA雅加达 | B9: AGISTA PRIYANTONO | C9: JKT41T | D9: CP_TELUK_GONG_RAYA | E9: 45 | F9: 43 | G9: 45 | H9: 44 | I9: 48 | J9: 47 | K9: 0.9 | L9: 0.95555556 | M9: 0.97777778 | N9: 0.97916667 | O9: 1444 | P9: 1299 | Q9: 42 | R9: 42 | S9: 46 | T9: 0.89958449 | U9: 0.93333333 | V9: 0.93333333 | W9: 0.95833333 | X9: 0 | Y9: 347 | Z9: 330 | AA9: 360 | AB9: 317 | AC9: 0.95100865 | AD9: 0.88055556 | AE9: 0.07045309
A10: JAKARTA雅加达 | B10: AGISTA PRIYANTONO | C10: JKT08C | D10: KEPULAUAN_SERIBU | E10: 28 | F10: 28 | G10: 28 | H10: 28 | I10: 23 | J10: 22 | K10: 0.9 | L10: 1 | M10: 1 | N10: 0.95652174 | O10: 753 | P10: 724 | Q10: 27 | R10: 27 | S10: 21 | T10: 0.96148738 | U10: 0.96428571 | V10: 0.96428571 | W10: 0.91304348 | X10: 0 | Y10: 187 | Z10: 181 | AA10: 191 | AB10: 189 | AC10: 0.96791444 | AD10: 0.9895288 | AE10: -0.021614357
A11: JAKARTA雅加达 | B11: AGISTA PRIYANTONO | C11: JKT30A | D11: CP_PADEMANGAN_4 | E11: 0 | F11: 0 | G11: 0 | H11: 0 | I11: 0 | J11: 0 | K11: 0.9 | L11: 0 | M11: 0 | N11: 0 | O11: 0 | P11: 0 | Q11: 0 | R11: 0 | S11: 0 | T11: 0 | U11: 0 | V11: 0 | W11: 0 | X11: 0 | Y11: 0 | Z11: 0 | AA11: 0 | AB11: 0 | AC11: 0 | AD11: 0 | AE11: 0
A12: JAKARTA雅加达 | B12: AGISTA PRIYANTONO | C12: JKT41W | D12: CP_PLUIT_PERMAI | E12: 49 | F12: 45 | G12: 56 | H12: 53 | I12: 62 | J12: 56 | K12: 0.9 | L12: 0.91836735 | M12: 0.94642857 | N12: 0.90322581 | O12: 1674 | P12: 1504 | Q12: 43 | R12: 47 | S12: 53 | T12: 0.89844683 | U12: 0.87755102 | V12: 0.83928571 | W12: 0.85483871 | X12: 0.038265306 | Y12: 430 | Z12: 374 | AA12: 424 | AB12: 382 | AC12: 0.86976744 | AD12: 0.9009434 | AE12: -0.031175954
A13: JAKARTA雅加达 | B13: AGISTA PRIYANTONO | C13: JKT08I | D13: TELUK_GONG | E13: 106 | F13: 100 | G13: 102 | H13: 98 | I13: 111 | J13: 106 | K13: 0.9 | L13: 0.94339623 | M13: 0.96078431 | N13: 0.95495495 | O13: 3166 | P13: 2915 | Q13: 100 | R13: 96 | S13: 103 | T13: 0.92072015 | U13: 0.94339623 | V13: 0.94117647 | W13: 0.92792793 | X13: 0.0022197558 | Y13: 795 | Z13: 733 | AA13: 799 | AB13: 738 | AC13: 0.92201258 | AD13: 0.92365457 | AE13: -0.0016419896
A14: JAKARTA雅加达 | B14: AGISTA PRIYANTONO | C14: JKT09A | D14: ANCOL | E14: 81 | F14: 73 | G14: 74 | H14: 71 | I14: 80 | J14: 73 | K14: 0.9 | L14: 0.90123457 | M14: 0.95945946 | N14: 0.9125 | O14: 2280 | P14: 2096 | Q14: 56 | R14: 66 | S14: 70 | T14: 0.91929825 | U14: 0.69135802 | V14: 0.75675676 | W14: 0.7 | X14: -0.065398732 | Y14: 572 | Z14: 505 | AA14: 581 | AB14: 526 | AC14: 0.88286713 | AD14: 0.90533563 | AE14: -0.022468495
A15: JAKARTA雅加达 | B15: AGISTA PRIYANTONO | C15: JKT43Q | D15: CP_ANCOL_SELATAN_1 | E15: 115 | F15: 115 | G15: 111 | H15: 110 | I15: 120 | J15: 118 | K15: 0.9 | L15: 1 | M15: 0.99099099 | N15: 0.98333333 | O15: 3398 | P15: 3357 | Q15: 114 | R15: 109 | S15: 118 | T15: 0.98793408 | U15: 0.99130435 | V15: 0.98198198 | W15: 0.98333333 | X15: 0.0093223658 | Y15: 846 | Z15: 834 | AA15: 855 | AB15: 848 | AC15: 0.9858156 | AD15: 0.99181287 | AE15: -0.0059972627
A16: JAKARTA雅加达 | B16: AGISTA PRIYANTONO | C16: JKT08L | D16: KAMAL_MUARA | E16: 25 | F16: 24 | G16: 26 | H16: 25 | I16: 27 | J16: 25 | K16: 0.9 | L16: 0.96 | M16: 0.96153846 | N16: 0.92592593 | O16: 793 | P16: 737 | Q16: 24 | R16: 25 | S16: 24 | T16: 0.92938209 | U16: 0.96 | V16: 0.96153846 | W16: 0.88888889 | X16: -0.0015384615 | Y16: 196 | Z16: 183 | AA16: 198 | AB16: 185 | AC16: 0.93367347 | AD16: 0.93434343 | AE16: -0.00066996496
A17: JAKARTA雅加达 | B17: ANDI PRASETIYO | C17: JKT05L | D17: KOTA_TUA | E17: 0 | F17: 0 | G17: 0 | H17: 0 | I17: 0 | J17: 0 | K17: 0.9 | L17: 0 | M17: 0 | N17: 0 | O17: 0 | P17: 0 | Q17: 0 | R17: 0 | S17: 0 | T17: 0 | U17: 0 | V17: 0 | W17: 0 | X17: 0 | Y17: 0 | Z17: 0 | AA17: 0 | AB17: 0 | AC17: 0 | AD17: 0 | AE17: 0
A18: JAKARTA雅加达 | B18: ANDI PRASETIYO | C18: JKT45I | D18: CP_PINANGSIA_RAYA | E18: 16 | F18: 16 | G18: 11 | H18: 11 | I18: 15 | J18: 13 | K18: 0.9 | L18: 1 | M18: 1 | N18: 0.86666667 | O18: 491 | P18: 395 | Q18: 13 | R18: 7 | S18: 10 | T18: 0.80448065 | U18: 0.8125 | V18: 0.63636364 | W18: 0.66666667 | X18: 0.17613636 | Y18: 113 | Z18: 90 | AA18: 129 | AB18: 105 | AC18: 0.79646018 | AD18: 0.81395349 | AE18: -0.017493311
A19: JAKARTA雅加达 | B19: ANDI PRASETIYO | C19: JKT11 | D19: TANAH_ABANG | E19: 90 | F19: 85 | G19: 73 | H19: 70 | I19: 85 | J19: 78 | K19: 0.9 | L19: 0.94444444 | M19: 0.95890411 | N19: 0.91764706 | O19: 2587 | P19: 2290 | Q19: 77 | R19: 64 | S19: 71 | T19: 0.88519521 | U19: 0.85555556 | V19: 0.87671233 | W19: 0.83529412 | X19: -0.021156773 | Y19: 641 | Z19: 580 | AA19: 636 | AB19: 559 | AC19: 0.90483619 | AD19: 0.87893082 | AE19: 0.025905376
A20: JAKARTA雅加达 | B20: ANDI PRASETIYO | C20: JKT45B | D20: CP_MANGGA_BESAR_2 | E20: 44 | F20: 44 | G20: 43 | H20: 42 | I20: 43 | J20: 43 | K20: 0.9 | L20: 1 | M20: 0.97674419 | N20: 1 | O20: 1261 | P20: 1142 | Q20: 39 | R20: 37 | S20: 39 | T20: 0.90563045 | U20: 0.88636364 | V20: 0.86046512 | W20: 0.90697674 | X20: 0.02589852 | Y20: 311 | Z20: 281 | AA20: 319 | AB20: 284 | AC20: 0.90353698 | AD20: 0.89028213 | AE20: 0.013254846
... A1717: BALI巴厘 | B1717: Prisilia Nansiana Akong | C1717: KOE17 | D1717: KUPANG_TIMUR | E1717: 12 | F1717: 9 | G1717: 9 | H1717: 7 | I1717: 11 | J1717: 9 | K1717: 0.9 | L1717: 0.75 | M1717: 0.77777778 | N1717: 0.81818182 | O1717: 267 | P1717: 64 | Q1717: 4 | R1717: 3 | S1717: 1 | T1717: 0.23970037 | U1717: 0.33333333 | V1717: 0.33333333 | W1717: 0.090909091 | X1717: 0 | Y1717: 68 | Z1717: 15 | AA1717: 60 | AB1717: 18 | AC1717: 0.22058824 | AD1717: 0.3 | AE1717: -0.079411765

Sheet Display 730 & 1200
A1: 网管-爪哇-巴厘班0730出仓率&1200签收率09月28日 NM-Persentase 0730 & TTD 1200 Agent Jawa-Bali 28 Sep 2026
A2: 代理区 Agent | B2: RM | C2: 网点名称 Nama DP | D2: 网点名称 Nama DP | E2: Rit-1应签收 Seharusnya TTD Rit-1 | F2: 0730出仓率 Persentase Keluar Gudang 0730 | G2: 1200前已签收 TTD Sebelum 1200 | H2: Rit-1应签收 Seharusnya TTD Rit-1 27/09/2026 | I2: 0730出仓率 Persentase Keluar Gudang 0730 27/09/2026 | J2: 1200前已签收 TTD Sebelum 1200 27/09/2026 | K2: Rit-1应签收 Seharusnya TTD Rit-1 26/09/2026 | L2: 0730出仓率 Persentase Keluar Gudang 0730 26/09/2026 | M2: 1200前已签收 TTD Sebelum 1200 26/09/2026 | N2: 月累计签收率 Persentase Bulanan 0730 | O2: 0730出仓率 Persentase Keluar Gudang 0730 Bulanan | P2: 目标值 Target | Q2: 28日0730出仓率 Persentase Keluar Gudang 0730 | T2: 对比昨天 Perbandingan H-1 | U2: Rit-1应签收 Seharusnya TTD Rit-1 Bulanan | V2: 1200前已签收 TTD Sebelum 1200 Bulanan | W2: 月累计签收率 Persentase Bulanan 1200 | X2: 1200前已签收 TTD Sebelum 1200 | AA2: 对比昨天 Perbandingan H-1 | AB2: Rit-1应签收 Seharusnya TTD Rit-1 Mingguan 22/09/2026 - 28/09/2026 | AC2: 1200前已签收 TTD Sebelum 1200 Mingguan 22/09/2026 - 28/09/2026 | AD2: Rit-1应签收 Seharusnya TTD Rit-1 Mingguan 15/09/2026 - 21/09/2026 | AE2: 1200前已签收 TTD Sebelum 1200 Mingguan 15/09/2026 - 21/09/2026 | AF2: 1200前已签收周度率 Persentase Mingguan TTD 1200 | AH2: 对比上周 Perbandingan Mingguan
Q3: ='Display ALL DP'!L8 -> 46293 | R3: =Q3-1 -> 46292 | S3: =Q3-2 -> 46291 | X3: =Q3 -> 46293 | Y3: =R3 -> 46292 | Z3: =S3 -> 46291 | AF3: =TEXT(AN10,"DD MMM")&" - "&TEXT(AN9,"DD MMM") -> 22 Sep - 28 Sep | AG3: =TEXT(AN12,"DD MMM")&" - "&TEXT(AN11,"DD MMM") -> 15 Sep - 21 Sep | AK3: data mingguan harus difix, ga boleh hanya patokan jakarta doang
D4: AGENT40 | E4: 3698789 | F4: 3522358 | G4: 3270723 | H4: 4193140 | I4: 3963682 | J4: 3670951 | K4: 3892828 | L4: 3720329 | M4: 3506327 | N4: 0.95393094 | O4: 109146256 | P4: 0.9 | Q4: 0.95230033 | R4: 0.94527776 | S4: 0.955688 | T4: 0.0070225708 | U4: 114417356 | V4: 102251100 | W4: 0.89366774 | X4: 0.88426861 | Y4: 0.87546588 | Z4: 0.9007146 | AA4: 0.0088027279 | AB4: 27866992 | AC4: 25042018 | AD4: 27647876 | AE4: 24874366 | AF4: 0.89862652 | AG4: 0.89968452 | AH4: -0.0010579998 | AI4: 5
A6: JAKARTA雅加达 | B6: AGISTA PRIYANTONO | C6: JKT07T | D6: DC_SUNTER | E6: 0 | F6: 0 | G6: 0 | H6: 0 | I6: 0 | J6: 0 | K6: 0 | L6: 0 | M6: 0 | N6: 0 | O6: 0 | P6: 0.9 | Q6: 0 | R6: 0 | S6: 0 | T6: 0 | U6: 0 | V6: 0 | W6: 0 | X6: 0 | Y6: 0 | Z6: 0 | AA6: 0 | AB6: 0 | AC6: 0 | AD6: 0 | AE6: 0 | AF6: 0 | AG6: 0 | AH6: 0
A7: JAKARTA雅加达 | B7: AGISTA PRIYANTONO | C7: JKT41W | D7: CP_PLUIT_PERMAI | E7: 5286 | F7: 5230 | G7: 4527 | H7: 6563 | I7: 6519 | J7: 4984 | K7: 7177 | L7: 6572 | M7: 5797 | N7: 0.9488909 | O7: 154469 | P7: 0.9 | Q7: 0.98940598 | R7: 0.99329575 | S7: 0.91570294 | T7: -0.0038897708 | U7: 162789 | V7: 119290 | W7: 0.73278907 | X7: 0.85641317 | Y7: 0.75940881 | Z7: 0.8077191 | AA7: 0.09700436 | AB7: 48148 | AC7: 39197 | AD7: 41512 | AE7: 32916 | AF7: 0.81409404 | AG7: 0.79292735 | AH7: 0.021166697
A8: JAKARTA雅加达 | B8: AGISTA PRIYANTONO | C8: JKT08N | D8: PLUIT_PERMAI | E8: 0 | F8: 0 | G8: 0 | H8: 0 | I8: 0 | J8: 0 | K8: 0 | L8: 0 | M8: 0 | N8: 0 | O8: 0 | P8: 0.9 | Q8: 0 | R8: 0 | S8: 0 | T8: 0 | U8: 0 | V8: 0 | W8: 0 | X8: 0 | Y8: 0 | Z8: 0 | AA8: 0 | AB8: 0 | AC8: 0 | AD8: 0 | AE8: 0 | AF8: 0 | AG8: 0 | AH8: 0
A9: JAKARTA雅加达 | B9: AGISTA PRIYANTONO | C9: JKT43D | D9: CP_DANAUSUNTER_UTARA | E9: 6023 | F9: 5648 | G9: 4968 | H9: 7464 | I9: 7262 | J9: 5987 | K9: 7357 | L9: 7153 | M9: 6231 | N9: 0.98235853 | O9: 196511 | P9: 0.9 | Q9: 0.93773867 | R9: 0.97293676 | S9: 0.97227131 | T9: -0.035198095 | U9: 200040 | V9: 159961 | W9: 0.79964507 | X9: 0.82483812 | Y9: 0.80211683 | Z9: 0.84694848 | AA9: 0.022721293 | AB9: 51580 | AC9: 43798 | AD9: 48666 | AE9: 39733 | AF9: 0.84912757 | AG9: 0.81644269 | AH9: 0.032684878 | AM9: =Q3 -> 46293 | AN9: =AM9 -> 46293
A10: JAKARTA雅加达 | B10: AGISTA PRIYANTONO | C10: JKT08I | D10: TELUK_GONG | E10: 5808 | F10: 4827 | G10: 4730 | H10: 7208 | I10: 6559 | J10: 5780 | K10: 7229 | L10: 6617 | M10: 6230 | N10: 0.91411828 | O10: 197796 | P10: 0.9 | Q10: 0.83109504 | R10: 0.90996115 | S10: 0.91534099 | T10: -0.078866113 | U10: 216379 | V10: 179744 | W10: 0.83069059 | X10: 0.81439394 | Y10: 0.80188679 | Z10: 0.86180661 | AA10: 0.012507147 | AB10: 51428 | AC10: 43921 | AD10: 51575 | AE10: 43569 | AF10: 0.85402893 | AG10: 0.84476975 | AH10: 0.0092591809 | AN10: =AN9-6 -> 46287
A11: JAKARTA雅加达 | B11: AGISTA PRIYANTONO | C11: JKT09A | D11: ANCOL | E11: 5263 | F11: 4375 | G11: 4542 | H11: 5772 | I11: 5239 | J11: 5050 | K11: 6026 | L11: 5569 | M11: 5444 | N11: 0.90912973 | O11: 151171 | P11: 0.9 | Q11: 0.83127494 | R11: 0.90765766 | S11: 0.92416196 | T11: -0.076382719 | U11: 166281 | V11: 150552 | W11: 0.90540711 | X11: 0.86300589 | Y11: 0.87491337 | Z11: 0.90341852 | AA11: -0.011907485 | AB11: 41900 | AC11: 38118 | AD11: 39107 | AE11: 36334 | AF11: 0.90973747 | AG11: 0.92909198 | AH11: -0.019354508 | AN11: =AN10-1 -> 46286
A12: JAKARTA雅加达 | B12: AGISTA PRIYANTONO | C12: JKT08L | D12: KAMAL_MUARA | E12: 1317 | F12: 1311 | G12: 1171 | H12: 1263 | I12: 1252 | J12: 1144 | K12: 1334 | L12: 1323 | M12: 1184 | N12: 0.94294228 | O12: 34176 | P12: 0.9 | Q12: 0.99544419 | R12: 0.99129058 | S12: 0.99175412 | T12: 0.0041536134 | U12: 36244 | V12: 32068 | W12: 0.88478093 | X12: 0.88914199 | Y12: 0.90577989 | Z12: 0.88755622 | AA12: -0.0166379 | AB12: 9851 | AC12: 8875 | AD12: 10338 | AE12: 9248 | AF12: 0.90092376 | AG12: 0.89456375 | AH12: 0.0063600187 | AN12: =AN9-13 -> 46280
A13: JAKARTA雅加达 | B13: AGISTA PRIYANTONO | C13: JKT08C | D13: KEPULAUAN_SERIBU | E13: 2529 | F13: 2527 | G13: 2474 | H13: 2844 | I13: 2833 | J13: 2819 | K13: 2860 | L13: 2834 | M13: 2841 | N13: 0.96540034 | O13: 81725 | P13: 0.9 | Q13: 0.99920917 | R13: 0.99613221 | S13: 0.99090909 | T13: 0.0030769654 | U13: 84654 | V13: 81054 | W13: 0.95747395 | X13: 0.97825227 | Y13: 0.99120956 | Z13: 0.99335664 | AA13: -0.01295729 | AB13: 19029 | AC13: 18831 | AD13: 21052 | AE13: 20541 | AF13: 0.98959483 | AG13: 0.97572677 | AH13: 0.013868057 | AN13: 46266
A14: JAKARTA雅加达 | B14: AGISTA PRIYANTONO | C14: JKT43Q | D14: CP_ANCOL_SELATAN_1 | E14: 7726 | F14: 7615 | G14: 7097 | H14: 10131 | I14: 9975 | J14: 9063 | K14: 10062 | L14: 9949 | M14: 9166 | N14: 0.98272513 | O14: 246380 | P14: 0.9 | Q14: 0.98563293 | R14: 0.98460172 | S14: 0.98876963 | T14: 0.0010312103 | U14: 250711 | V14: 229757 | W14: 0.9164217 | X14: 0.91858659 | Y14: 0.89458099 | Z14: 0.9109521 | AA14: 0.024005602 | AB14: 68082 | AC14: 62584 | AD14: 62326 | AE14: 57668 | AF14: 0.91924444 | AG14: 0.92526393 | AH14: -0.0060194943
A15: JAKARTA雅加达 | B15: AGISTA PRIYANTONO | C15: JKT41T | D15: CP_TELUK_GONG_RAYA | E15: 4652 | F15: 3999 | G15: 4362 | H15: 4046 | I15: 3904 | J15: 3702 | K15: 4543 | L15: 4465 | M15: 4343 | N15: 0.95865379 | O15: 116046 | P15: 0.9 | Q15: 0.85963027 | R15: 0.96490361 | S15: 0.98283073 | T15: -0.10527334 | U15: 121051 | V15: 113346 | W15: 0.93634914 | X15: 0.93766122 | Y15: 0.91497776 | Z15: 0.95597623 | AA15: 0.022683465 | AB15: 33946 | AC15: 32062 | AD15: 31253 | AE15: 29682 | AF15: 0.94450009 | AG15: 0.94973283 | AH15: -0.0052327373
A16: JAKARTA雅加达 | B16: AGISTA PRIYANTONO | C16: JKT30A | D16: CP_PADEMANGAN_4 | E16: 0 | F16: 0 | G16: 0 | H16: 0 | I16: 0 | J16: 0 | K16: 0 | L16: 0 | M16: 0 | N16: 0.36842105 | O16: 7 | P16: 0.9 | Q16: 0 | R16: 0 | S16: 0 | T16: 0 | U16: 19 | V16: 18 | W16: 0.94736842 | X16: 0 | Y16: 0 | Z16: 0 | AA16: 0 | AB16: 0 | AC16: 0 | AD16: 0 | AE16: 0 | AF16: 0 | AG16: 0 | AH16: 0
A17: JAKARTA雅加达 | B17: ANDI PRASETIYO | C17: JKT05L | D17: KOTA_TUA | E17: 0 | F17: 0 | G17: 0 | H17: 0 | I17: 0 | J17: 0 | K17: 0 | L17: 0 | M17: 0 | N17: 0 | O17: 0 | P17: 0.9 | Q17: 0 | R17: 0 | S17: 0 | T17: 0 | U17: 0 | V17: 0 | W17: 0 | X17: 0 | Y17: 0 | Z17: 0 | AA17: 0 | AB17: 0 | AC17: 0 | AD17: 0 | AE17: 0 | AF17: 0 | AG17: 0 | AH17: 0
A18: JAKARTA雅加达 | B18: ANDI PRASETIYO | C18: JKT45I | D18: CP_PINANGSIA_RAYA | E18: 1302 | F18: 1280 | G18: 846 | H18: 1946 | I18: 1918 | J18: 716 | K18: 1845 | L18: 1829 | M18: 1263 | N18: 0.90251211 | O18: 43974 | P18: 0.9 | Q18: 0.98310292 | R18: 0.98561151 | S18: 0.99132791 | T18: -0.0025085922 | U18: 48724 | V18: 30970 | W18: 0.63562105 | X18: 0.64976959 | Y18: 0.36793422 | Z18: 0.68455285 | AA18: 0.28183536 | AB18: 12812 | AC18: 8669 | AD18: 11649 | AE18: 7585 | AF18: 0.67663128 | AG18: 0.65112885 | AH18: 0.025502431
A19: JAKARTA雅加达 | B19: ANDI PRASETIYO | C19: JKT11 | D19: TANAH_ABANG | E19: 3639 | F19: 3608 | G19: 2624 | H19: 5840 | I19: 5785 | J19: 3016 | K19: 5761 | L19: 5709 | M19: 4067 | N19: 0.99394094 | O19: 155676 | P19: 0.9 | Q19: 0.99148118 | R19: 0.99058219 | S19: 0.99097379 | T19: 0.00089898437 | U19: 156625 | V19: 112923 | W19: 0.72097686 | X19: 0.72107722 | Y19: 0.51643836 | Z19: 0.70595383 | AA19: 0.20463886 | AB19: 38442 | AC19: 27815 | AD19: 36334 | AE19: 26160 | AF19: 0.72355757 | AG19: 0.71998679 | AH19: 0.003570778
A20: JAKARTA雅加达 | B20: ANDI PRASETIYO | C20: JKT45B | D20: CP_MANGGA_BESAR_2 | E20: 4842 | F20: 4087 | G20: 4356 | H20: 5486 | I20: 5377 | J20: 5131 | K20: 6107 | L20: 6008 | M20: 5691 | N20: 0.92278732 | O20: 111278 | P20: 0.9 | Q20: 0.8440727 | R20: 0.98013124 | S20: 0.98378909 | T20: -0.13605855 | U20: 120589 | V20: 108154 | W20: 0.89688114 | X20: 0.89962825 | Y20: 0.93528983 | Z20: 0.93188145 | AA20: -0.035661576 | AB20: 35290 | AC20: 32793 | AD20: 29760 | AE20: 27443 | AF20: 0.92924341 | AG20: 0.92214382 | AH20: 0.0070995945
A21: JAKARTA雅加达 | B21: ANDI PRASETIYO | C21: JKT13K | D21: JOHAR_BARU_01 | E21: 3659 | F21: 3650 | G21: 3225 | H21: 5393 | I21: 5327 | J21: 4624 | K21: 5312 | L21: 5292 | M21: 4658 | N21: 0.99315293 | O21: 142582 | P21: 0.9 | Q21: 0.99754031 | R21: 0.98776191 | S21: 0.99623494 | T21: 0.009778398 | U21: 143565 | V21: 125505 | W21: 0.87420332 | X21: 0.88138836 | Y21: 0.85740775 | Z21: 0.87688253 | AA21: 0.023980607 | AB21: 35604 | AC21: 31189 | AD21: 33034 | AE21: 28878 | AF21: 0.87599708 | AG21: 0.87419023 | AH21: 0.0018068507
A22: JAKARTA雅加达 | B22: ANDI PRASETIYO | C22: JKT12 | D22: SENEN | E22: 4691 | F22: 4660 | G22: 4045 | H22: 7181 | I22: 7133 | J22: 5553 | K22: 7138 | L22: 7091 | M22: 6259 | N22: 0.9928209 | O22: 204674 | P22: 0.9 | Q22: 0.9933916 | R22: 0.99331569 | S22: 0.99341552 | T22: 7.5906745e-05 | U22: 206154 | V22: 182209 | W22: 0.88384897 | X22: 0.86228949 | Y22: 0.77329063 | Z22: 0.87685626 | AA22: 0.088998862 | AB22: 49273 | AC22: 42958 | AD22: 47528 | AE22: 42566 | AF22: 0.8718365 | AG22: 0.89559838 | AH22: -0.023761881
A23: JAKARTA雅加达 | B23: ANDI PRASETIYO | C23: JKT45L | D23: CP_ZAINUL_ARIFIN | E23: 1416 | F23: 1382 | G23: 1308 | H23: 1884 | I23: 1771 | J23: 1579 | K23: 1762 | L23: 1667 | M23: 1531 | N23: 0.97453785 | O23: 41489 | P23: 0.9 | Q23: 0.9759887 | R23: 0.94002123 | S23: 0.946084 | T23: 0.035967469 | U23: 42573 | V23: 36247 | W23: 0.85140817 | X23: 0.92372881 | Y23: 0.8381104 | Z23: 0.86889898 | AA23: 0.08561841 | AB23: 12795 | AC23: 11257 | AD23: 11458 | AE23: 10181 | AF23: 0.8797968 | AG23: 0.88854949 | AH23: -0.0087526895
A24: JAKARTA雅加达 | B24: ARIS YULIANTO | C24: JKT19J | D24: DC_CIPAYUNG | E24: 0 | F24: 0 | G24: 0 | H24: 0 | I24: 0 | J24: 0 | K24: 0 | L24: 0 | M24: 0 | N24: 0 | O24: 0 | P24: 0.9 | Q24: 0 | R24: 0 | S24: 0 | T24: 0 | U24: 0 | V24: 0 | W24: 0 | X24: 0 | Y24: 0 | Z24: 0 | AA24: 0 | AB24: 0 | AC24: 0 | AD24: 0 | AE24: 0 | AF24: 0 | AG24: 0 | AH24: 0
A25: JAKARTA雅加达 | B25: ARIS YULIANTO | C25: JKT19L | D25: KELAPA_DUA_01 | E25: 0 | F25: 0 | G25: 0 | H25: 0 | I25: 0 | J25: 0 | K25: 0 | L25: 0 | M25: 0 | N25: 0 | O25: 0 | P25: 0.9 | Q25: 0 | R25: 0 | S25: 0 | T25: 0 | U25: 0 | V25: 0 | W25: 0 | X25: 0 | Y25: 0 | Z25: 0 | AA25: 0 | AB25: 0 | AC25: 0 | AD25: 0 | AE25: 0 | AF25: 0 | AG25: 0 | AH25: 0
... A1717: BALI巴厘 | B1717: Prisilia Nansiana Akong | C1717: KOE17 | D1717: KUPANG_TIMUR | E1717: 1256 | F1717: 1140 | G1717: 744 | H1717: 1195 | I1717: 1052 | J1717: 855 | K1717: 1123 | L1717: 958 | M1717: 795 | N1717: 0.90831846 | O1717: 10690 | P1717: 0.9 | Q1717: 0.90764331 | R1717: 0.88033473 | S1717: 0.85307213 | T1717: 0.027308584 | U1717: 11769 | V1717: 8566 | W1717: 0.72784434 | X1717: 0.59235669 | Y1717: 0.71548117 | Z1717: 0.7079252 | AA1717: -0.12312448 | AB1717: 4528 | AC1717: 3107 | AD1717: 2331 | AE1717: 1713 | AF1717: 0.68617491 | AG1717: 0.73487773 | AH1717: -0.048702823

Sheet Display Ritase Keseluruhan
A1: 网管-爪哇-巴厘班次全天签收率报表09月28日 NM-Laporan Persentase Keseluruhan TTD Berdasarkan Ritase Agent Jawa-Bali 28 Sep 2026
A2: 代理区 Agent | B2: RM | C2: 网点代码 Kode DP | D2: 网点名称 Nama DP | E2: T-1应签收 Seharusnya TTD H-1 | F2: 2359前已签收 TTD Sebelum 2359 | G2: 未签收 Belum TTD | H2: T-1应签收 Seharusnya TTD 27/09/2026 | I2: 2359前已签收 TTD Sebelum 2359 27/09/2026 | J2: 未签收 Belum TTD 27/09/2026 | K2: T-1应签收 Seharusnya TTD 26/09/2026 | L2: 2359前已签收 TTD Sebelum 2359 26/09/2026 | M2: 未签收 Belum TTD 26/09/2026 | N2: 目标值 Target | O2: 累计应签收量 Seharusnya TTD Bulanan | P2: 累计签收量 TTD Bulanan | Q2: 累计未签收 Belum TTD Bulanan | R2: 月累计 签收率 Persentase Bulanan | S2: 全天签收率 Persentase TTD All Ritase | V2: 对比昨天 Perbandingan H-1 | W2: 累计应签收量 Seharusnya TTD Mingguan 22/09/2026 - 28/09/2026 | X2: 累计签收量 TTD Mingguan 22/09/2026 - 28/09/2026 | Y2: 累计应签收量 Seharusnya TTD Mingguan 15/09/2026 - 21/09/2026 | Z2: 累计签收量 TTD Mingguan 15/09/2026 - 21/09/2026 | AA2: 全天签收率周度率 Persentase Mingguan TTD All Ritase | AC2: 对比上周 Perbandingan Mingguan
S3: ='Display ALL DP'!L8 -> 46293 | T3: =S3-1 -> 46292 | U3: =S3-2 -> 46291 | AA3: =TEXT(AH10,"DD MMM")&" - "&TEXT(AH9,"DD MMM") -> 22 Sep - 28 Sep | AB3: =TEXT(AH12,"DD MMM")&" - "&TEXT(AH11,"DD MMM") -> 15 Sep - 21 Sep
E4: 5130648 | F4: 4844958 | G4: 285690 | H4: 6515537 | I4: 6100337 | J4: 415200 | K4: 6213168 | L4: 5939917 | M4: 273251 | N4: 0.93 | O4: 178530641 | P4: 171276801 | Q4: 7253840 | R4: 0.95936922 | S4: 0.94431698 | T4: 0.9362754 | U4: 0.95602066 | V4: 0.0080415768 | W4: 43212556 | X4: 41367791 | Y4: 42932338 | Z4: 41261503 | AA4: 0.95730951 | AB4: 0.96108213 | AC4: -0.0037726191 | AD4: 5
A6: JAKARTA雅加达 | B6: AGISTA PRIYANTONO | C6: JKT07T | D6: DC_SUNTER | E6: 0 | F6: 0 | G6: 0 | H6: 0 | I6: 0 | J6: 0 | K6: 0 | L6: 0 | M6: 0 | N6: 0.93 | O6: 0 | P6: 0 | Q6: 0 | R6: 0 | S6: 0 | T6: 0 | U6: 0 | V6: 0 | W6: 0 | X6: 0 | Y6: 0 | Z6: 0 | AA6: 0 | AB6: 0 | AC6: 0
A7: JAKARTA雅加达 | B7: AGISTA PRIYANTONO | C7: JKT09A | D7: ANCOL | E7: 6931 | F7: 6544 | G7: 387 | H7: 8902 | I7: 8392 | J7: 510 | K7: 9608 | L7: 9336 | M7: 272 | N7: 0.93 | O7: 262419 | P7: 257703 | Q7: 4716 | R7: 0.98202874 | S7: 0.9441639 | T7: 0.9427095 | U7: 0.97169026 | V7: 0.0014543978 | W7: 65398 | X7: 63644 | Y7: 61703 | Z7: 60984 | AA7: 0.97317961 | AB7: 0.98834741 | AC7: -0.015167798
A8: JAKARTA雅加达 | B8: AGISTA PRIYANTONO | C8: JKT08N | D8: PLUIT_PERMAI | E8: 0 | F8: 0 | G8: 0 | H8: 0 | I8: 0 | J8: 0 | K8: 0 | L8: 0 | M8: 0 | N8: 0.93 | O8: 0 | P8: 0 | Q8: 0 | R8: 0 | S8: 0 | T8: 0 | U8: 0 | V8: 0 | W8: 0 | X8: 0 | Y8: 0 | Z8: 0 | AA8: 0 | AB8: 0 | AC8: 0
A9: JAKARTA雅加达 | B9: AGISTA PRIYANTONO | C9: JKT41W | D9: CP_PLUIT_PERMAI | E9: 7794 | F9: 7396 | G9: 398 | H9: 10622 | I9: 9727 | J9: 895 | K9: 11517 | L9: 10963 | M9: 554 | N9: 0.93 | O9: 270952 | P9: 254137 | Q9: 16815 | R9: 0.93794104 | S9: 0.94893508 | T9: 0.91574092 | U9: 0.9518972 | V9: 0.033194163 | W9: 77125 | X9: 73538 | Y9: 68695 | Z9: 65151 | AA9: 0.95349109 | AB9: 0.94840964 | AC9: 0.0050814491 | AH9: =S3 -> 46293
A10: JAKARTA雅加达 | B10: AGISTA PRIYANTONO | C10: JKT30A | D10: CP_PADEMANGAN_4 | E10: 0 | F10: 0 | G10: 0 | H10: 0 | I10: 0 | J10: 0 | K10: 0 | L10: 0 | M10: 0 | N10: 0.93 | O10: 33 | P10: 32 | Q10: 1 | R10: 0.96969697 | S10: 0 | T10: 0 | U10: 0 | V10: 0 | W10: 0 | X10: 0 | Y10: 2 | Z10: 2 | AA10: 0 | AB10: 1 | AC10: -1 | AH10: =AH9-6 -> 46287
A11: JAKARTA雅加达 | B11: AGISTA PRIYANTONO | C11: JKT08I | D11: TELUK_GONG | E11: 8354 | F11: 7647 | G11: 707 | H11: 11795 | I11: 11226 | J11: 569 | K11: 12242 | L11: 11955 | M11: 287 | N11: 0.93 | O11: 362558 | P11: 354566 | Q11: 7992 | R11: 0.97795663 | S11: 0.91536988 | T11: 0.95175922 | U11: 0.97655612 | V11: -0.036389337 | W11: 84647 | X11: 82274 | Y11: 85838 | Z11: 83976 | AA11: 0.97196593 | AB11: 0.97830798 | AC11: -0.0063420464 | AH11: =AH10-1 -> 46286
A12: JAKARTA雅加达 | B12: AGISTA PRIYANTONO | C12: JKT43D | D12: CP_DANAUSUNTER_UTARA | E12: 9010 | F12: 8414 | G12: 596 | H12: 12239 | I12: 11583 | J12: 656 | K12: 12467 | L12: 12047 | M12: 420 | N12: 0.93 | O12: 341497 | P12: 330932 | Q12: 10565 | R12: 0.96906269 | S12: 0.93385128 | T12: 0.94640085 | U12: 0.96631106 | V12: -0.012549573 | W12: 84930 | X12: 82199 | Y12: 82048 | Z12: 80254 | AA12: 0.96784411 | AB12: 0.97813475 | AC12: -0.010290643 | AH12: =AH11-6 -> 46280
A13: JAKARTA雅加达 | B13: AGISTA PRIYANTONO | C13: JKT08C | D13: KEPULAUAN_SERIBU | E13: 2529 | F13: 2489 | G13: 40 | H13: 2844 | I13: 2832 | J13: 12 | K13: 2860 | L13: 2856 | M13: 4 | N13: 0.93 | O13: 84655 | P13: 84196 | Q13: 459 | R13: 0.99457799 | S13: 0.98418347 | T13: 0.99578059 | U13: 0.9986014 | V13: -0.011597119 | W13: 19029 | X13: 18946 | Y13: 21052 | Z13: 20978 | AA13: 0.99563824 | AB13: 0.99648489 | AC13: -0.00084665817 | AH13: 46266
A14: JAKARTA雅加达 | B14: AGISTA PRIYANTONO | C14: JKT43Q | D14: CP_ANCOL_SELATAN_1 | E14: 11274 | F14: 10941 | G14: 333 | H14: 16513 | I14: 15900 | J14: 613 | K14: 16770 | L14: 16324 | M14: 446 | N14: 0.93 | O14: 423530 | P14: 414127 | Q14: 9403 | R14: 0.9777985 | S14: 0.97046301 | T14: 0.96287773 | U14: 0.97340489 | V14: 0.0075852795 | W14: 111360 | X14: 108707 | Y14: 104416 | Z14: 102333 | AA14: 0.97617636 | AB14: 0.98005095 | AC14: -0.0038745851
A15: JAKARTA雅加达 | B15: AGISTA PRIYANTONO | C15: JKT08L | D15: KAMAL_MUARA | E15: 1786 | F15: 1687 | G15: 99 | H15: 2209 | I15: 2112 | J15: 97 | K15: 2365 | L15: 2254 | M15: 111 | N15: 0.93 | O15: 62678 | P15: 60380 | Q15: 2298 | R15: 0.96333642 | S15: 0.94456887 | T15: 0.95608873 | U15: 0.95306554 | V15: -0.011519859 | W15: 16531 | X15: 15902 | Y15: 17203 | Z15: 16650 | AA15: 0.96195028 | AB15: 0.96785444 | AC15: -0.0059041688
A16: JAKARTA雅加达 | B16: AGISTA PRIYANTONO | C16: JKT41T | D16: CP_TELUK_GONG_RAYA | E16: 6377 | F16: 6258 | G16: 119 | H16: 6177 | I16: 6021 | J16: 156 | K16: 7612 | L16: 7387 | M16: 225 | N16: 0.93 | O16: 198912 | P16: 193774 | Q16: 5138 | R16: 0.97416948 | S16: 0.98133919 | T16: 0.97474502 | U16: 0.97044141 | V16: 0.0065941659 | W16: 54116 | X16: 52991 | Y16: 51106 | Z16: 49849 | AA16: 0.97921132 | AB16: 0.97540406 | AC16: 0.0038072617
A17: JAKARTA雅加达 | B17: ANDI PRASETIYO | C17: JKT05L | D17: KOTA_TUA | E17: 0 | F17: 0 | G17: 0 | H17: 0 | I17: 0 | J17: 0 | K17: 0 | L17: 0 | M17: 0 | N17: 0.93 | O17: 0 | P17: 0 | Q17: 0 | R17: 0 | S17: 0 | T17: 0 | U17: 0 | V17: 0 | W17: 0 | X17: 0 | Y17: 0 | Z17: 0 | AA17: 0 | AB17: 0 | AC17: 0
A18: JAKARTA雅加达 | B18: ANDI PRASETIYO | C18: JKT11 | D18: TANAH_ABANG | E18: 5332 | F18: 4842 | G18: 490 | H18: 9726 | I18: 6709 | J18: 3017 | K18: 9992 | L18: 8758 | M18: 1234 | N18: 0.93 | O18: 269441 | P18: 242166 | Q18: 27275 | R18: 0.8987719 | S18: 0.90810203 | T18: 0.68980053 | U18: 0.8765012 | V18: 0.21830149 | W18: 64676 | X18: 57379 | Y18: 62830 | Z18: 56443 | AA18: 0.88717608 | AB18: 0.89834474 | AC18: -0.011168662
A19: JAKARTA雅加达 | B19: ANDI PRASETIYO | C19: JKT12 | D19: SENEN | E19: 7020 | F19: 6587 | G19: 433 | H19: 12195 | I19: 10639 | J19: 1556 | K19: 12315 | L19: 11507 | M19: 808 | N19: 0.93 | O19: 349606 | P19: 333036 | Q19: 16570 | R19: 0.95260379 | S19: 0.93831909 | T19: 0.87240672 | U19: 0.93438896 | V19: 0.065912364 | W19: 82343 | X19: 77993 | Y19: 80815 | Z19: 77061 | AA19: 0.94717219 | AB19: 0.95354823 | AC19: -0.0063760331
A20: JAKARTA雅加达 | B20: ANDI PRASETIYO | C20: JKT45B | D20: CP_MANGGA_BESAR_2 | E20: 6500 | F20: 6234 | G20: 266 | H20: 7872 | I20: 7708 | J20: 164 | K20: 8963 | L20: 8737 | M20: 226 | N20: 0.93 | O20: 197755 | P20: 192921 | Q20: 4834 | R20: 0.97555561 | S20: 0.95907692 | T20: 0.97916667 | U20: 0.97478523 | V20: -0.020089744 | W20: 54685 | X20: 53365 | Y20: 49346 | Z20: 48315 | AA20: 0.97586175 | AB20: 0.97910672 | AC20: -0.0032449622
A21: JAKARTA雅加达 | B21: ANDI PRASETIYO | C21: JKT45I | D21: CP_PINANGSIA_RAYA | E21: 1786 | F21: 1649 | G21: 137 | H21: 2987 | I21: 1699 | J21: 1288 | K21: 2874 | L21: 2660 | M21: 214 | N21: 0.93 | O21: 79569 | P21: 67896 | Q21: 11673 | R21: 0.85329714 | S21: 0.92329227 | T21: 0.56879813 | U21: 0.92553932 | V21: 0.35449415 | W21: 20012 | X21: 17199 | Y21: 19246 | Z21: 16797 | AA21: 0.85943434 | AB21: 0.87275278 | AC21: -0.01331844
A22: JAKARTA雅加达 | B22: ANDI PRASETIYO | C22: JKT45L | D22: CP_ZAINUL_ARIFIN | E22: 2023 | F22: 1989 | G22: 34 | H22: 2867 | I22: 2695 | J22: 172 | K22: 2778 | L22: 2649 | M22: 129 | N22: 0.93 | O22: 67203 | P22: 64090 | Q22: 3113 | R22: 0.95367766 | S22: 0.98319328 | T22: 0.94000698 | U22: 0.95356371 | V22: 0.043186301 | W22: 19210 | X22: 18583 | Y22: 17560 | Z22: 17072 | AA22: 0.96736075 | AB22: 0.97220957 | AC22: -0.0048488176
A23: JAKARTA雅加达 | B23: ANDI PRASETIYO | C23: JKT13K | D23: JOHAR_BARU_01 | E23: 5758 | F23: 5436 | G23: 322 | H23: 9380 | I23: 8698 | J23: 682 | K23: 9364 | L23: 8894 | M23: 470 | N23: 0.93 | O23: 250242 | P23: 240938 | Q23: 9304 | R23: 0.96281999 | S23: 0.9440778 | T23: 0.92729211 | U23: 0.94980777 | V23: 0.016785694 | W23: 61469 | X23: 58838 | Y23: 58303 | Z23: 56151 | AA23: 0.95719794 | AB23: 0.96308938 | AC23: -0.0058914407
A24: JAKARTA雅加达 | B24: ARIS YULIANTO | C24: JKT19J | D24: DC_CIPAYUNG | E24: 0 | F24: 0 | G24: 0 | H24: 0 | I24: 0 | J24: 0 | K24: 0 | L24: 0 | M24: 0 | N24: 0.93 | O24: 0 | P24: 0 | Q24: 0 | R24: 0 | S24: 0 | T24: 0 | U24: 0 | V24: 0 | W24: 0 | X24: 0 | Y24: 0 | Z24: 0 | AA24: 0 | AB24: 0 | AC24: 0
A25: JAKARTA雅加达 | B25: ARIS YULIANTO | C25: JKT19L | D25: KELAPA_DUA_01 | E25: 0 | F25: 0 | G25: 0 | H25: 0 | I25: 0 | J25: 0 | K25: 0 | L25: 0 | M25: 0 | N25: 0.93 | O25: 0 | P25: 0 | Q25: 0 | R25: 0 | S25: 0 | T25: 0 | U25: 0 | V25: 0 | W25: 0 | X25: 0 | Y25: 0 | Z25: 0 | AA25: 0 | AB25: 0 | AC25: 0
... A46: JAKARTA雅加达 | B46: DIFA HERDIANSAH MUNABARI | C46: JKT56 | D46: CP_UJUNG_MENTENG | E46: 0 | F46: 0 | G46: 0 | H46: 0 | I46: 0 | J46: 0 | K46: 0 | L46: 0 | M46: 0 | N46: 0.93 | O46: 0 | P46: 0 | Q46: 0 | R46: 0 | S46: 0 | T46: 0 | U46: 0 | V46: 0 | W46: 0 | X46: 0 | Y46: 0 | Z46: 0 | AA46: 0 | AB46: 0 | AC46: 0
A47: JAKARTA雅加达 | B47: DIFA HERDIANSAH MUNABARI | C47: #N/A | D47: CP_PISANGAN_TIMUR_2 | E47: 0 | F47: 0 | G47: 0 | H47: 0 | I47: 0 | J47: 0 | K47: 0 | L47: 0 | M47: 0 | N47: 0.93 | O47: 0 | P47: 0 | Q47: 0 | R47: 0 | S47: 0 | T47: 0 | U47: 0 | V47: 0 | W47: 0 | X47: 0 | Y47: 0 | Z47: 0 | AA47: 0 | AB47: 0 | AC47: 0
A48: JAKARTA雅加达 | B48: DIFA HERDIANSAH MUNABARI | C48: JKT56F | D48: CP_KAYU_TINGGI_1 | E48: 0 | F48: 0 | G48: 0 | H48: 0 | I48: 0 | J48: 0 | K48: 0 | L48: 0 | M48: 0 | N48: 0.93 | O48: 0 | P48: 0 | Q48: 0 | R48: 0 | S48: 0 | T48: 0 | U48: 0 | V48: 0 | W48: 0 | X48: 0 | Y48: 0 | Z48: 0 | AA48: 0 | AB48: 0 | AC48: 0
